Workbook

Sheet Trends_bulk
A1: Sample | B1: Core | C1: Depth | D1: Mean_depth | E1: Unit | F1: LLD | G1: Element | H1: Semi_total_radno | I1: Semi_total | J1: TN | K1: TOC | L1: TOC_TN
A2: RF-01 | B2: CORE-352 | C2: 0-1 | D2: 0.5 | E2: PPM | F2: 0.1 | G2: Mo | H2: 0.7 | I2: =IF(Table1[[#This Row],[Semi_total_radno]]="BLD", 0.65*Table1[[#This Row],[LLD]], Table1[[#This Row],[Semi_total_radno]]) -> 0.7 | J2: 0.2130086 | K2: 1.5581344 | L2: 7.3148899
A3: RF-02 | B3: CORE-352 | C3: 1-2 | D3: 1.5 | E3: PPM | F3: 0.1 | G3: Mo | H3: 0.7 | I3: =IF(Table1[[#This Row],[Semi_total_radno]]="BLD", 0.65*Table1[[#This Row],[LLD]], Table1[[#This Row],[Semi_total_radno]]) -> 0.7 | J3: 0.24476093 | K3: 1.8220783 | L3: 7.4443186
A4: RF-03 | B4: CORE-352 | C4: 2-3 | D4: 2.5 | E4: PPM | F4: 0.1 | G4: Mo | H4: 1.2 | I4: =IF(Table1[[#This Row],[Semi_total_radno]]="BLD", 0.65*Table1[[#This Row],[LLD]], Table1[[#This Row],[Semi_total_radno]]) -> 1.2 | J4: 0.20878421 | K4: 1.5988929 | L4: 7.6581124
A5: RF-04 | B5: CORE-352 | C5: 3-4 | D5: 3.5 | E5: PPM | F5: 0.1 | G5: Mo | H5: 3 | I5: =IF(Table1[[#This Row],[Semi_total_radno]]="BLD", 0.65*Table1[[#This Row],[LLD]], Table1[[#This Row],[Semi_total_radno]]) -> 3 | J5: 0.26063022 | K5: 1.7546206 | L5: 6.7322222
A6: RF-05 | B6: CORE-352 | C6: 4-5 | D6: 4.5 | E6: PPM | F6: 0.1 | G6: Mo | H6: 3.5 | I6: =IF(Table1[[#This Row],[Semi_total_radno]]="BLD", 0.65*Table1[[#This Row],[LLD]], Table1[[#This Row],[Semi_total_radno]]) -> 3.5 | J6: 0.2609995 | K6: 1.7825639 | L6: 6.8297599
A7: RF-06 | B7: CORE-352 | C7: 5-6 | D7: 5.5 | E7: PPM | F7: 0.1 | G7: Mo | H7: 3.6 | I7: =IF(Table1[[#This Row],[Semi_total_radno]]="BLD", 0.65*Table1[[#This Row],[LLD]], Table1[[#This Row],[Semi_total_radno]]) -> 3.6 | J7: 0.20869255 | K7: 1.6111051 | L7: 7.7199933
A8: RF-07 | B8: CORE-352 | C8: 6-7 | D8: 6.5 | E8: PPM | F8: 0.1 | G8: Mo | H8: 3.3 | I8: =IF(Table1[[#This Row],[Semi_total_radno]]="BLD", 0.65*Table1[[#This Row],[LLD]], Table1[[#This Row],[Semi_total_radno]]) -> 3.3 | J8: 0.25640079 | K8: 1.6978488 | L8: 6.6218547
A9: RF-08 | B9: CORE-352 | C9: 7-8 | D9: 7.5 | E9: PPM | F9: 0.1 | G9: Mo | H9: 3.2 | I9: =IF(Table1[[#This Row],[Semi_total_radno]]="BLD", 0.65*Table1[[#This Row],[LLD]], Table1[[#This Row],[Semi_total_radno]]) -> 3.2 | J9: 0.16514252 | K9: 1.2323353 | L9: 7.4622533
A10: RF-09 | B10: CORE-352 | C10: 8-9 | D10: 8.5 | E10: PPM | F10: 0.1 | G10: Mo | H10: 2.3 | I10: =IF(Table1[[#This Row],[Semi_total_radno]]="BLD", 0.65*Table1[[#This Row],[LLD]], Table1[[#This Row],[Semi_total_radno]]) -> 2.3 | J10: 0.004902815 | K10: 0.75896835 | L10: 154.80257
A11: RF-10 | B11: CORE-352 | C11: 9-10 | D11: 9.5 | E11: PPM | F11: 0.1 | G11: Mo | H11: 1.8 | I11: =IF(Table1[[#This Row],[Semi_total_radno]]="BLD", 0.65*Table1[[#This Row],[LLD]], Table1[[#This Row],[Semi_total_radno]]) -> 1.8 | J11: 0.0030738597 | K11: 0.47719088 | L11: 155.24159
A12: RF-11 | B12: CORE-352 | C12: 10-11 | D12: 10.5 | E12: PPM | F12: 0.1 | G12: Mo | H12: 1.6 | I12: =IF(Table1[[#This Row],[Semi_total_radno]]="BLD", 0.65*Table1[[#This Row],[LLD]], Table1[[#This Row],[Semi_total_radno]]) -> 1.6 | J12: 0.23008806 | K12: 0.85805011 | L12: 3.7292249
A13: RF-12 | B13: CORE-352 | C13: 11-12 | D13: 11.5 | E13: PPM | F13: 0.1 | G13: Mo | H13: 1.1 | I13: =IF(Table1[[#This Row],[Semi_total_radno]]="BLD", 0.65*Table1[[#This Row],[LLD]], Table1[[#This Row],[Semi_total_radno]]) -> 1.1 | J13: 0.30633134 | K13: 0.88174587 | L13: 2.8784057
... A25: RF-24 | B25: CORE-352 | C25: 23-24 | D25: 23.5 | E25: PPM | F25: 0.1 | G25: Mo | H25: 0.5 | I25: =IF(Table1[[#This Row],[Semi_total_radno]]="BLD", 0.65*Table1[[#This Row],[LLD]], Table1[[#This Row],[Semi_total_radno]]) -> 0.5 | J25: 0.2551713 | K25: 0.80598986 | L25: 3.1586227
A26: RF-25 | B26: CORE-357 | C26: 0-1 | D26: 0.5 | E26: PPM | F26: 0.1 | G26: Mo | H26: 0.6 | I26: =IF(Table1[[#This Row],[Semi_total_radno]]="BLD", 0.65*Table1[[#This Row],[LLD]], Table1[[#This Row],[Semi_total_radno]]) -> 0.6 | J26: 0.34120834 | K26: 1.5170505 | L26: =K26/J26 -> 4.446112
A27: RF-26 | B27: CORE-357 | C27: 1-2 | D27: 1.5 | E27: PPM | F27: 0.1 | G27: Mo | H27: 0.6 | I27: =IF(Table1[[#This Row],[Semi_total_radno]]="BLD", 0.65*Table1[[#This Row],[LLD]], Table1[[#This Row],[Semi_total_radno]]) -> 0.6 | J27: 0.0052734488 | K27: 0.87811798 | L27: =K27/J27 -> 166.51683
A28: RF-27 | B28: CORE-357 | C28: 2-3 | D28: 2.5 | E28: PPM | F28: 0.1 | G28: Mo | H28: 0.6 | I28: =IF(Table1[[#This Row],[Semi_total_radno]]="BLD", 0.65*Table1[[#This Row],[LLD]], Table1[[#This Row],[Semi_total_radno]]) -> 0.6 | J28: 0.25128737 | K28: 1.312072 | L28: =K28/J28 -> 5.2214006
A29: RF-28 | B29: CORE-357 | C29: 3-4 | D29: 3.5 | E29: PPM | F29: 0.1 | G29: Mo | H29: 0.7 | I29: =IF(Table1[[#This Row],[Semi_total_radno]]="BLD", 0.65*Table1[[#This Row],[LLD]], Table1[[#This Row],[Semi_total_radno]]) -> 0.7 | J29: 0.51856995 | K29: 2.0246232 | L29: =K29/J29 -> 3.9042431
A30: RF-29 | B30: CORE-357 | C30: 4-5 | D30: 4.5 | E30: PPM | F30: 0.1 | G30: Mo | H30: 0.9 | I30: =IF(Table1[[#This Row],[Semi_total_radno]]="BLD", 0.65*Table1[[#This Row],[LLD]], Table1[[#This Row],[Semi_total_radno]]) -> 0.9 | J30: 0.44535509 | K30: 1.7919422 | L30: =K30/J30 -> 4.0236258
A31: RF-30 | B31: CORE-357 | C31: 5-6 | D31: 5.5 | E31: PPM | F31: 0.1 | G31: Mo | H31: 0.7 | I31: =IF(Table1[[#This Row],[Semi_total_radno]]="BLD", 0.65*Table1[[#This Row],[LLD]], Table1[[#This Row],[Semi_total_radno]]) -> 0.7 | J31: 0.73049772 | K31: 2.5906391 | L31: =K31/J31 -> 3.5464027
A32: RF-31 | B32: CORE-357 | C32: 6-7 | D32: 6.5 | E32: PPM | F32: 0.1 | G32: Mo | H32: 0.8 | I32: =IF(Table1[[#This Row],[Semi_total_radno]]="BLD", 0.65*Table1[[#This Row],[LLD]], Table1[[#This Row],[Semi_total_radno]]) -> 0.8 | J32: 0.23559479 | K32: 1.2447417 | L32: =K32/J32 -> 5.2834006
A33: RF-32 | B33: CORE-357 | C33: 7-8 | D33: 7.5 | E33: PPM | F33: 0.1 | G33: Mo | H33: 0.8 | I33: =IF(Table1[[#This Row],[Semi_total_radno]]="BLD", 0.65*Table1[[#This Row],[LLD]], Table1[[#This Row],[Semi_total_radno]]) -> 0.8 | J33: 0.0037895394 | K33: 0.0074258852 | L33: =K33/J33 -> 1.9595746
A34: RF-33 | B34: CORE-357 | C34: 8-9 | D34: 8.5 | E34: PPM | F34: 0.1 | G34: Mo | H34: 0.9 | I34: =IF(Table1[[#This Row],[Semi_total_radno]]="BLD", 0.65*Table1[[#This Row],[LLD]], Table1[[#This Row],[Semi_total_radno]]) -> 0.9 | J34: 0.11416455 | K34: 0.98078692 | L34: =K34/J34 -> 8.5909933
A35: RF-34 | B35: CORE-357 | C35: 9-10 | D35: 9.5 | E35: PPM | F35: 0.1 | G35: Mo | H35: 0.9 | I35: =IF(Table1[[#This Row],[Semi_total_radno]]="BLD", 0.65*Table1[[#This Row],[LLD]], Table1[[#This Row],[Semi_total_radno]]) -> 0.9 | J35: 0.0025792727 | K35: 0.7224803 | L35: =K35/J35 -> 280.11008
A36: RF-35 | B36: CORE-357 | C36: 10-11 | D36: 10.5 | E36: PPM | F36: 0.1 | G36: Mo | H36: 1 | I36: =IF(Table1[[#This Row],[Semi_total_radno]]="BLD", 0.65*Table1[[#This Row],[LLD]], Table1[[#This Row],[Semi_total_radno]]) -> 1 | J36: 0.0041285236 | K36: 0.62968802 | L36: =K36/J36 -> 152.52136
A37: RF-36 | B37: CORE-346 | C37: 0-1 | D37: 0.5 | E37: PPM | F37: 0.1 | G37: Mo | H37: 0.7 | I37: =IF(Table1[[#This Row],[Semi_total_radno]]="BLD", 0.65*Table1[[#This Row],[LLD]], Table1[[#This Row],[Semi_total_radno]]) -> 0.7 | J37: 0.16807576 | K37: 1.5302047 | L37: =K37/J37 -> 9.1042557
... A43: RF-42 | B43: CORE-346 | C43: 6-7 | D43: 6.5 | E43: PPM | F43: 0.1 | G43: Mo | H43: 3.8 | I43: =IF(Table1[[#This Row],[Semi_total_radno]]="BLD", 0.65*Table1[[#This Row],[LLD]], Table1[[#This Row],[Semi_total_radno]]) -> 3.8 | J43: 0.0049335267 | K43: 1.0768021 | L43: =K43/J43 -> 218.26215
A44: RF-43 | B44: CORE-346 | C44: 7-8 | D44: 7.5 | E44: PPM | F44: 0.1 | G44: Mo | H44: 3.6 | I44: =IF(Table1[[#This Row],[Semi_total_radno]]="BLD", 0.65*Table1[[#This Row],[LLD]], Table1[[#This Row],[Semi_total_radno]]) -> 3.6
A45: RF-44 | B45: CORE-346 | C45: 8-9 | D45: 8.5 | E45: PPM | F45: 0.1 | G45: Mo | H45: 3.3 | I45: =IF(Table1[[#This Row],[Semi_total_radno]]="BLD", 0.65*Table1[[#This Row],[LLD]], Table1[[#This Row],[Semi_total_radno]]) -> 3.3 | J45: 0.0030030957 | K45: 0.83362019 | L45: =K45/J45 -> 277.58695
A46: RF-45 | B46: CORE-346 | C46: 9-10 | D46: 9.5 | E46: PPM | F46: 0.1 | G46: Mo | H46: 2.7 | I46: =IF(Table1[[#This Row],[Semi_total_radno]]="BLD", 0.65*Table1[[#This Row],[LLD]], Table1[[#This Row],[Semi_total_radno]]) -> 2.7 | J46: 0.0020532638 | K46: 0.66615409 | L46: =K46/J46 -> 324.43667
A47: RF-46 | B47: CORE-346 | C47: 10-11 | D47: 10.5 | E47: PPM | F47: 0.1 | G47: Mo | H47: 2.5 | I47: =IF(Table1[[#This Row],[Semi_total_radno]]="BLD", 0.65*Table1[[#This Row],[LLD]], Table1[[#This Row],[Semi_total_radno]]) -> 2.5 | J47: 0.0025867883 | K47: 0.0033793366 | L47: =K47/J47 -> 1.3063831
A48: RF-47 | B48: CORE-346 | C48: 11-12 | D48: 11.5 | E48: PPM | F48: 0.1 | G48: Mo | H48: 2.2 | I48: =IF(Table1[[#This Row],[Semi_total_radno]]="BLD", 0.65*Table1[[#This Row],[LLD]], Table1[[#This Row],[Semi_total_radno]]) -> 2.2 | J48: 0.00090370938 | K48: 0.34518707 | L48: =K48/J48 -> 381.9669
A49: RF-48 | B49: CORE-346 | C49: 12-13 | D49: 12.5 | E49: PPM | F49: 0.1 | G49: Mo | H49: 1.9 | I49: =IF(Table1[[#This Row],[Semi_total_radno]]="BLD", 0.65*Table1[[#This Row],[LLD]], Table1[[#This Row],[Semi_total_radno]]) -> 1.9 | J49: 0.0022553734 | K49: 0.0018333044 | L49: =K49/J49 -> 0.81286071
A50: RF-49 | B50: CORE-346 | C50: 13-14 | D50: 13.5 | E50: PPM | F50: 0.1 | G50: Mo | H50: 1.3 | I50: =IF(Table1[[#This Row],[Semi_total_radno]]="BLD", 0.65*Table1[[#This Row],[LLD]], Table1[[#This Row],[Semi_total_radno]]) -> 1.3 | J50: 0.0020753995 | K50: 0 | L50: =K50/J50 -> 0
A51: RF-50 | B51: CORE-346 | C51: 14-15 | D51: 14.5 | E51: PPM | F51: 0.1 | G51: Mo | H51: 1.1 | I51: =IF(Table1[[#This Row],[Semi_total_radno]]="BLD", 0.65*Table1[[#This Row],[LLD]], Table1[[#This Row],[Semi_total_radno]]) -> 1.1 | J51: 0.00060549 | K51: 0.0024608949 | L51: =K51/J51 -> 4.0643031
A52: RF-51 | B52: CORE-334 | C52: 0-1 | D52: 0.5 | E52: PPM | F52: 0.1 | G52: Mo | H52: 1 | I52: =IF(Table1[[#This Row],[Semi_total_radno]]="BLD", 0.65*Table1[[#This Row],[LLD]], Table1[[#This Row],[Semi_total_radno]]) -> 1 | J52: 0.2122917 | K52: 1.7695252 | L52: 8.3353478
A53: RF-52 | B53: CORE-334 | C53: 1-2 | D53: 1.5 | E53: PPM | F53: 0.1 | G53: Mo | H53: 0.5 | I53: =IF(Table1[[#This Row],[Semi_total_radno]]="BLD", 0.65*Table1[[#This Row],[LLD]], Table1[[#This Row],[Semi_total_radno]]) -> 0.5 | J53: 0.18038377 | K53: 1.537728 | L53: 8.5247577
A54: RF-53 | B54: CORE-334 | C54: 2-3 | D54: 2.5 | E54: PPM | F54: 0.1 | G54: Mo | H54: 1 | I54: =IF(Table1[[#This Row],[Semi_total_radno]]="BLD", 0.65*Table1[[#This Row],[LLD]], Table1[[#This Row],[Semi_total_radno]]) -> 1 | J54: 0.20040309 | K54: 1.67629 | L54: 8.3645916
A55: RF-54 | B55: CORE-334 | C55: 3-4 | D55: 3.5 | E55: PPM | F55: 0.1 | G55: Mo | H55: 1.6 | I55: =IF(Table1[[#This Row],[Semi_total_radno]]="BLD", 0.65*Table1[[#This Row],[LLD]], Table1[[#This Row],[Semi_total_radno]]) -> 1.6 | J55: 0.1831909 | K55: 1.5863311 | L55: 8.659443
A56: RF-55 | B56: CORE-334 | C56: 4-5 | D56: 4.5 | E56: PPM | F56: 0.1 | G56: Mo | H56: 2.8 | I56: =IF(Table1[[#This Row],[Semi_total_radno]]="BLD", 0.65*Table1[[#This Row],[LLD]], Table1[[#This Row],[Semi_total_radno]]) -> 2.8 | J56: 0.17950253 | K56: 1.4967481 | L56: 8.3383119
...

Sheet Trends_bulk (2)
A1: Sample | B1: Core | C1: Depth | D1: Mean_depth | E1: Unit | F1: LLD | G1: Element | H1: Semi_total_radno | I1: Semi_total | J1: TN | K1: TOC | L1: TOC_TN
A2: RF-01 | B2: CORE-352 | C2: 0-1 | D2: 0.5 | E2: PPM | F2: 0.1 | G2: Mo | H2: 0.7 | I2: =IF(Table18[[#This Row],[Semi_total_radno]]="BLD", 0.65*Table18[[#This Row],[LLD]], Table18[[#This Row],[Semi_total_radno]]) -> 0.7 | J2: 0.2130086 | K2: 1.5581344 | L2: 7.3148899
A3: RF-02 | B3: CORE-352 | C3: 1-2 | D3: 1.5 | E3: PPM | F3: 0.1 | G3: Mo | H3: 0.7 | I3: =IF(Table18[[#This Row],[Semi_total_radno]]="BLD", 0.65*Table18[[#This Row],[LLD]], Table18[[#This Row],[Semi_total_radno]]) -> 0.7 | J3: 0.24476093 | K3: 1.8220783 | L3: 7.4443186
A4: RF-03 | B4: CORE-352 | C4: 2-3 | D4: 2.5 | E4: PPM | F4: 0.1 | G4: Mo | H4: 1.2 | I4: =IF(Table18[[#This Row],[Semi_total_radno]]="BLD", 0.65*Table18[[#This Row],[LLD]], Table18[[#This Row],[Semi_total_radno]]) -> 1.2 | J4: 0.20878421 | K4: 1.5988929 | L4: 7.6581124
A5: RF-04 | B5: CORE-352 | C5: 3-4 | D5: 3.5 | E5: PPM | F5: 0.1 | G5: Mo | H5: 3 | I5: =IF(Table18[[#This Row],[Semi_total_radno]]="BLD", 0.65*Table18[[#This Row],[LLD]], Table18[[#This Row],[Semi_total_radno]]) -> 3 | J5: 0.26063022 | K5: 1.7546206 | L5: 6.7322222
A6: RF-05 | B6: CORE-352 | C6: 4-5 | D6: 4.5 | E6: PPM | F6: 0.1 | G6: Mo | H6: 3.5 | I6: =IF(Table18[[#This Row],[Semi_total_radno]]="BLD", 0.65*Table18[[#This Row],[LLD]], Table18[[#This Row],[Semi_total_radno]]) -> 3.5 | J6: 0.2609995 | K6: 1.7825639 | L6: 6.8297599
A7: RF-06 | B7: CORE-352 | C7: 5-6 | D7: 5.5 | E7: PPM | F7: 0.1 | G7: Mo | H7: 3.6 | I7: =IF(Table18[[#This Row],[Semi_total_radno]]="BLD", 0.65*Table18[[#This Row],[LLD]], Table18[[#This Row],[Semi_total_radno]]) -> 3.6 | J7: 0.20869255 | K7: 1.6111051 | L7: 7.7199933
A8: RF-07 | B8: CORE-352 | C8: 6-7 | D8: 6.5 | E8: PPM | F8: 0.1 | G8: Mo | H8: 3.3 | I8: =IF(Table18[[#This Row],[Semi_total_radno]]="BLD", 0.65*Table18[[#This Row],[LLD]], Table18[[#This Row],[Semi_total_radno]]) -> 3.3 | J8: 0.25640079 | K8: 1.6978488 | L8: 6.6218547
A9: RF-08 | B9: CORE-352 | C9: 7-8 | D9: 7.5 | E9: PPM | F9: 0.1 | G9: Mo | H9: 3.2 | I9: =IF(Table18[[#This Row],[Semi_total_radno]]="BLD", 0.65*Table18[[#This Row],[LLD]], Table18[[#This Row],[Semi_total_radno]]) -> 3.2 | J9: 0.16514252 | K9: 1.2323353 | L9: 7.4622533
A10: RF-09 | B10: CORE-352 | C10: 8-9 | D10: 8.5 | E10: PPM | F10: 0.1 | G10: Mo | H10: 2.3 | I10: =IF(Table18[[#This Row],[Semi_total_radno]]="BLD", 0.65*Table18[[#This Row],[LLD]], Table18[[#This Row],[Semi_total_radno]]) -> 2.3 | J10: 0.004902815 | K10: 0.75896835 | L10: 154.80257
A11: RF-10 | B11: CORE-352 | C11: 9-10 | D11: 9.5 | E11: PPM | F11: 0.1 | G11: Mo | H11: 1.8 | I11: =IF(Table18[[#This Row],[Semi_total_radno]]="BLD", 0.65*Table18[[#This Row],[LLD]], Table18[[#This Row],[Semi_total_radno]]) -> 1.8 | J11: 0.0030738597 | K11: 0.47719088 | L11: 155.24159
A12: RF-11 | B12: CORE-352 | C12: 10-11 | D12: 10.5 | E12: PPM | F12: 0.1 | G12: Mo | H12: 1.6 | I12: =IF(Table18[[#This Row],[Semi_total_radno]]="BLD", 0.65*Table18[[#This Row],[LLD]], Table18[[#This Row],[Semi_total_radno]]) -> 1.6 | J12: 0.23008806 | K12: 0.85805011 | L12: 3.7292249
A13: RF-12 | B13: CORE-352 | C13: 11-12 | D13: 11.5 | E13: PPM | F13: 0.1 | G13: Mo | H13: 1.1 | I13: =IF(Table18[[#This Row],[Semi_total_radno]]="BLD", 0.65*Table18[[#This Row],[LLD]], Table18[[#This Row],[Semi_total_radno]]) -> 1.1 | J13: 0.30633134 | K13: 0.88174587 | L13: 2.8784057
... A25: RF-24 | B25: CORE-352 | C25: 23-24 | D25: 23.5 | E25: PPM | F25: 0.1 | G25: Mo | H25: 0.5 | I25: =IF(Table18[[#This Row],[Semi_total_radno]]="BLD", 0.65*Table18[[#This Row],[LLD]], Table18[[#This Row],[Semi_total_radno]]) -> 0.5 | J25: 0.2551713 | K25: 0.80598986 | L25: 3.1586227
A26: RF-36 | B26: CORE-346 | C26: 0-1 | D26: 0.5 | E26: PPM | F26: 0.1 | G26: Mo | H26: 0.7 | I26: =IF(Table18[[#This Row],[Semi_total_radno]]="BLD", 0.65*Table18[[#This Row],[LLD]], Table18[[#This Row],[Semi_total_radno]]) -> 0.7 | J26: 0.16807576 | K26: 1.5302047 | L26: =K26/J26 -> 9.1042557
A27: RF-37 | B27: CORE-346 | C27: 1-2 | D27: 1.5 | E27: PPM | F27: 0.1 | G27: Mo | H27: 1.2 | I27: =IF(Table18[[#This Row],[Semi_total_radno]]="BLD", 0.65*Table18[[#This Row],[LLD]], Table18[[#This Row],[Semi_total_radno]]) -> 1.2 | J27: 0.16324836 | K27: 1.5245854 | L27: =K27/J27 -> 9.3390547
A28: RF-38 | B28: CORE-346 | C28: 2-3 | D28: 2.5 | E28: PPM | F28: 0.1 | G28: Mo | H28: 2.2 | I28: =IF(Table18[[#This Row],[Semi_total_radno]]="BLD", 0.65*Table18[[#This Row],[LLD]], Table18[[#This Row],[Semi_total_radno]]) -> 2.2 | J28: 0.15263675 | K28: 1.3331742 | L28: =K28/J28 -> 8.7342938
A29: RF-39 | B29: CORE-346 | C29: 3-4 | D29: 3.5 | E29: PPM | F29: 0.1 | G29: Mo | H29: 3.1 | I29: =IF(Table18[[#This Row],[Semi_total_radno]]="BLD", 0.65*Table18[[#This Row],[LLD]], Table18[[#This Row],[Semi_total_radno]]) -> 3.1 | J29: 0.16178781 | K29: 1.3450558 | L29: =K29/J29 -> 8.3137032
A30: RF-40 | B30: CORE-346 | C30: 4-5 | D30: 4.5 | E30: PPM | F30: 0.1 | G30: Mo | H30: 4.4 | I30: =IF(Table18[[#This Row],[Semi_total_radno]]="BLD", 0.65*Table18[[#This Row],[LLD]], Table18[[#This Row],[Semi_total_radno]]) -> 4.4 | J30: 0.15010448 | K30: 1.3260058 | L30: =K30/J30 -> 8.8338858
A31: RF-41 | B31: CORE-346 | C31: 5-6 | D31: 5.5 | E31: PPM | F31: 0.1 | G31: Mo | H31: 3.4 | I31: =IF(Table18[[#This Row],[Semi_total_radno]]="BLD", 0.65*Table18[[#This Row],[LLD]], Table18[[#This Row],[Semi_total_radno]]) -> 3.4 | J31: 0.14570627 | K31: 1.3029922 | L31: =K31/J31 -> 8.9425957
A32: RF-42 | B32: CORE-346 | C32: 6-7 | D32: 6.5 | E32: PPM | F32: 0.1 | G32: Mo | H32: 3.8 | I32: =IF(Table18[[#This Row],[Semi_total_radno]]="BLD", 0.65*Table18[[#This Row],[LLD]], Table18[[#This Row],[Semi_total_radno]]) -> 3.8 | J32: 0.0049335267 | K32: 1.0768021 | L32: =K32/J32 -> 218.26215
A33: RF-43 | B33: CORE-346 | C33: 7-8 | D33: 7.5 | E33: PPM | F33: 0.1 | G33: Mo | H33: 3.6 | I33: =IF(Table18[[#This Row],[Semi_total_radno]]="BLD", 0.65*Table18[[#This Row],[LLD]], Table18[[#This Row],[Semi_total_radno]]) -> 3.6
A34: RF-44 | B34: CORE-346 | C34: 8-9 | D34: 8.5 | E34: PPM | F34: 0.1 | G34: Mo | H34: 3.3 | I34: =IF(Table18[[#This Row],[Semi_total_radno]]="BLD", 0.65*Table18[[#This Row],[LLD]], Table18[[#This Row],[Semi_total_radno]]) -> 3.3 | J34: 0.0030030957 | K34: 0.83362019 | L34: =K34/J34 -> 277.58695
A35: RF-45 | B35: CORE-346 | C35: 9-10 | D35: 9.5 | E35: PPM | F35: 0.1 | G35: Mo | H35: 2.7 | I35: =IF(Table18[[#This Row],[Semi_total_radno]]="BLD", 0.65*Table18[[#This Row],[LLD]], Table18[[#This Row],[Semi_total_radno]]) -> 2.7 | J35: 0.0020532638 | K35: 0.66615409 | L35: =K35/J35 -> 324.43667
A36: RF-46 | B36: CORE-346 | C36: 10-11 | D36: 10.5 | E36: PPM | F36: 0.1 | G36: Mo | H36: 2.5 | I36: =IF(Table18[[#This Row],[Semi_total_radno]]="BLD", 0.65*Table18[[#This Row],[LLD]], Table18[[#This Row],[Semi_total_radno]]) -> 2.5 | J36: 0.0025867883 | K36: 0.0033793366 | L36: =K36/J36 -> 1.3063831
A37: RF-47 | B37: CORE-346 | C37: 11-12 | D37: 11.5 | E37: PPM | F37: 0.1 | G37: Mo | H37: 2.2 | I37: =IF(Table18[[#This Row],[Semi_total_radno]]="BLD", 0.65*Table18[[#This Row],[LLD]], Table18[[#This Row],[Semi_total_radno]]) -> 2.2 | J37: 0.00090370938 | K37: 0.34518707 | L37: =K37/J37 -> 381.9669
A38: RF-48 | B38: CORE-346 | C38: 12-13 | D38: 12.5 | E38: PPM | F38: 0.1 | G38: Mo | H38: 1.9 | I38: =IF(Table18[[#This Row],[Semi_total_radno]]="BLD", 0.65*Table18[[#This Row],[LLD]], Table18[[#This Row],[Semi_total_radno]]) -> 1.9 | J38: 0.0022553734 | K38: 0.0018333044 | L38: =K38/J38 -> 0.81286071
A39: RF-49 | B39: CORE-346 | C39: 13-14 | D39: 13.5 | E39: PPM | F39: 0.1 | G39: Mo | H39: 1.3 | I39: =IF(Table18[[#This Row],[Semi_total_radno]]="BLD", 0.65*Table18[[#This Row],[LLD]], Table18[[#This Row],[Semi_total_radno]]) -> 1.3 | J39: 0.0020753995 | K39: 0 | L39: =K39/J39 -> 0
A40: RF-50 | B40: CORE-346 | C40: 14-15 | D40: 14.5 | E40: PPM | F40: 0.1 | G40: Mo | H40: 1.1 | I40: =IF(Table18[[#This Row],[Semi_total_radno]]="BLD", 0.65*Table18[[#This Row],[LLD]], Table18[[#This Row],[Semi_total_radno]]) -> 1.1 | J40: 0.00060549 | K40: 0.0024608949 | L40: =K40/J40 -> 4.0643031
A41: RF-51 | B41: CORE-334 | C41: 0-1 | D41: 0.5 | E41: PPM | F41: 0.1 | G41: Mo | H41: 1 | I41: =IF(Table18[[#This Row],[Semi_total_radno]]="BLD", 0.65*Table18[[#This Row],[LLD]], Table18[[#This Row],[Semi_total_radno]]) -> 1 | J41: 0.2122917 | K41: 1.7695252 | L41: 8.3353478
A42: RF-52 | B42: CORE-334 | C42: 1-2 | D42: 1.5 | E42: PPM | F42: 0.1 | G42: Mo | H42: 0.5 | I42: =IF(Table18[[#This Row],[Semi_total_radno]]="BLD", 0.65*Table18[[#This Row],[LLD]], Table18[[#This Row],[Semi_total_radno]]) -> 0.5 | J42: 0.18038377 | K42: 1.537728 | L42: 8.5247577
A43: RF-53 | B43: CORE-334 | C43: 2-3 | D43: 2.5 | E43: PPM | F43: 0.1 | G43: Mo | H43: 1 | I43: =IF(Table18[[#This Row],[Semi_total_radno]]="BLD", 0.65*Table18[[#This Row],[LLD]], Table18[[#This Row],[Semi_total_radno]]) -> 1 | J43: 0.20040309 | K43: 1.67629 | L43: 8.3645916
A44: RF-54 | B44: CORE-334 | C44: 3-4 | D44: 3.5 | E44: PPM | F44: 0.1 | G44: Mo | H44: 1.6 | I44: =IF(Table18[[#This Row],[Semi_total_radno]]="BLD", 0.65*Table18[[#This Row],[LLD]], Table18[[#This Row],[Semi_total_radno]]) -> 1.6 | J44: 0.1831909 | K44: 1.5863311 | L44: 8.659443
A45: RF-55 | B45: CORE-334 | C45: 4-5 | D45: 4.5 | E45: PPM | F45: 0.1 | G45: Mo | H45: 2.8 | I45: =IF(Table18[[#This Row],[Semi_total_radno]]="BLD", 0.65*Table18[[#This Row],[LLD]], Table18[[#This Row],[Semi_total_radno]]) -> 2.8 | J45: 0.17950253 | K45: 1.4967481 | L45: 8.3383119
A46: RF-56 | B46: CORE-334 | C46: 5-6 | D46: 5.5 | E46: PPM | F46: 0.1 | G46: Mo | H46: 3.2 | I46: =IF(Table18[[#This Row],[Semi_total_radno]]="BLD", 0.65*Table18[[#This Row],[LLD]], Table18[[#This Row],[Semi_total_radno]]) -> 3.2 | J46: 0.21012133 | K46: 1.7805561 | L46: 8.4739424
A47: RF-57 | B47: CORE-334 | C47: 6-7 | D47: 6.5 | E47: PPM | F47: 0.1 | G47: Mo | H47: 3.3 | I47: =IF(Table18[[#This Row],[Semi_total_radno]]="BLD", 0.65*Table18[[#This Row],[LLD]], Table18[[#This Row],[Semi_total_radno]]) -> 3.3 | J47: 0.16531734 | K47: 1.3843391 | L47: 8.3738287
A48: RF-58 | B48: CORE-334 | C48: 7-8 | D48: 7.5 | E48: PPM | F48: 0.1 | G48: Mo | H48: 3.1 | I48: =IF(Table18[[#This Row],[Semi_total_radno]]="BLD", 0.65*Table18[[#This Row],[LLD]], Table18[[#This Row],[Semi_total_radno]]) -> 3.1 | J48: 0.15587628 | K48: 1.3395511 | L48: 8.5936815
A49: RF-59 | B49: CORE-334 | C49: 8-9 | D49: 8.5 | E49: PPM | F49: 0.1 | G49: Mo | H49: 3.4 | I49: =IF(Table18[[#This Row],[Semi_total_radno]]="BLD", 0.65*Table18[[#This Row],[LLD]], Table18[[#This Row],[Semi_total_radno]]) -> 3.4 | J49: 0.12354078 | K49: 1.0216147 | L49: 8.2694529
A50: RF-60 | B50: CORE-334 | C50: 9-10 | D50: 9.5 | E50: PPM | F50: 0.1 | G50: Mo | H50: 2.9 | I50: =IF(Table18[[#This Row],[Semi_total_radno]]="BLD", 0.65*Table18[[#This Row],[LLD]], Table18[[#This Row],[Semi_total_radno]]) -> 2.9 | J50: 0.0065454813 | K50: 0.0066507049 | L50: 1.0160758
A51: RF-61 | B51: CORE-334 | C51: 10-11 | D51: 10.5 | E51: PPM | F51: 0.1 | G51: Mo | H51: 2.3 | I51: =IF(Table18[[#This Row],[Semi_total_radno]]="BLD", 0.65*Table18[[#This Row],[LLD]], Table18[[#This Row],[Semi_total_radno]]) -> 2.3 | J51: 0.0019682962 | K51: 0.0015237624 | L51: 0.77415296
...

Sheet Semi_total_bulk
A1: Sample | B1: Mo | C1: Cu | D1: Pb | E1: Zn | F1: Ag | G1: Ni | H1: Co | I1: Mn | J1: Fe | K1: As | L1: U | M1: Th | N1: Sr | O1: Cd | P1: Sb | Q1: Bi | R1: V | S1: Ca | T1: P | U1: La | V1: Cr | W1: Mg | X1: Ba | Y1: Ti | Z1: Al | AA1: Na | AB1: K | AC1: W | AD1: Zr | AE1: Ce | AF1: Sn | AG1: Y | AH1: Nb | AI1: Ta | AJ1: Be | AK1: Sc | AL1: Li | AM1: S | AN1: Rb | AO1: Hf | AP1: In | AQ1: Re | AR1: Se | AS1: Te | AT1: Tl
A2: CAGE-22-1-HH-352-BC-A-0-1 | B2: 0.7 | C2: 150.2 | D2: 14.7 | E2: 47 | F2: 0.1 | G2: 30.9 | H2: 10 | I2: 308 | J2: 2.64 | K2: 7 | L2: 1.6 | M2: 6.1 | N2: 170 | O2: BLD | P2: 0.3 | Q2: 0.2 | R2: 64 | S2: 1.36 | T2: 0.067 | U2: 22.8 | V2: 110 | W2: 1.02 | X2: 549 | Y2: 0.3 | Z2: 5.16 | AA2: 2.868 | AB2: 1.86 | AC2: 0.6 | AD2: 51.6 | AE2: 47 | AF2: 1.4 | AG2: 15.7 | AH2: 7.2 | AI2: 0.5 | AJ2: 1 | AK2: 9 | AL2: 16.9 | AM2: 0.2 | AN2: 72.2 | AO2: 1.5 | AP2: BLD | AQ2: 0.008 | AR2: BLD | AS2: BLD | AT2: BLD
A3: CAGE-22-1-HH-352-BC-A-1-2 | B3: 0.7 | C3: 129.9 | D3: 13.9 | E3: 46 | F3: BLD | G3: 31.9 | H3: 9.6 | I3: 297 | J3: 2.63 | K3: 4 | L3: 1.8 | M3: 6 | N3: 166 | O3: BLD | P3: 0.3 | Q3: 0.2 | R3: 67 | S3: 1.38 | T3: 0.063 | U3: 23.2 | V3: 115 | W3: 1.05 | X3: 589 | Y3: 0.307 | Z3: 5.4 | AA3: 2.835 | AB3: 1.94 | AC3: 0.6 | AD3: 54.6 | AE3: 48 | AF3: 1.7 | AG3: 16.3 | AH3: 7.3 | AI3: 0.5 | AJ3: 1 | AK3: 9 | AL3: 17.7 | AM3: 0.2 | AN3: 75.1 | AO3: 1.5 | AP3: BLD | AQ3: 0.008 | AR3: BLD | AS3: BLD | AT3: BLD
A4: CAGE-22-1-HH-352-BC-A-2-3 | B4: 1.2 | C4: 145.4 | D4: 14.2 | E4: 47 | F4: BLD | G4: 33.8 | H4: 9.9 | I4: 296 | J4: 2.63 | K4: 5 | L4: 2 | M4: 6.3 | N4: 164 | O4: BLD | P4: 0.3 | Q4: 0.2 | R4: 70 | S4: 1.34 | T4: 0.056 | U4: 23.8 | V4: 119 | W4: 1.07 | X4: 622 | Y4: 0.314 | Z4: 5.43 | AA4: 2.739 | AB4: 2 | AC4: 0.5 | AD4: 53.1 | AE4: 49 | AF4: 1.5 | AG4: 16.1 | AH4: 7.2 | AI4: 0.4 | AJ4: 1 | AK4: 9 | AL4: 18.4 | AM4: 0.2 | AN4: 77.1 | AO4: 1.5 | AP4: BLD | AQ4: 0.008 | AR4: BLD | AS4: BLD | AT4: BLD
A5: CAGE-22-1-HH-352-BC-A-3-4 | B5: 3 | C5: 193.4 | D5: 14.4 | E5: 49 | F5: 0.1 | G5: 35.8 | H5: 10.2 | I5: 282 | J5: 2.67 | K5: 5 | L5: 2.5 | M5: 6.5 | N5: 154 | O5: BLD | P5: 0.3 | Q5: 0.2 | R5: 69 | S5: 1.25 | T5: 0.053 | U5: 23.7 | V5: 131 | W5: 1.08 | X5: 651 | Y5: 0.302 | Z5: 5.38 | AA5: 2.705 | AB5: 2 | AC5: 0.6 | AD5: 51.8 | AE5: 48 | AF5: 1.5 | AG5: 15.4 | AH5: 6.8 | AI5: 0.4 | AJ5: 1 | AK5: 9 | AL5: 18.8 | AM5: 0.3 | AN5: 78.1 | AO5: 1.5 | AP5: BLD | AQ5: 0.009 | AR5: BLD | AS5: BLD | AT5: BLD
A6: CAGE-22-1-HH-352-BC-A-4-5 | B6: 3.5 | C6: 215.5 | D6: 14.2 | E6: 48 | F6: 0.1 | G6: 37.1 | H6: 10.6 | I6: 285 | J6: 2.83 | K6: 6 | L6: 2.4 | M6: 6.6 | N6: 148 | O6: BLD | P6: 0.3 | Q6: 0.2 | R6: 72 | S6: 1.24 | T6: 0.055 | U6: 23.9 | V6: 157 | W6: 1.09 | X6: 693 | Y6: 0.292 | Z6: 5.49 | AA6: 2.663 | AB6: 2.1 | AC6: 0.6 | AD6: 49.7 | AE6: 49 | AF6: 1.5 | AG6: 14.6 | AH6: 6.6 | AI6: 0.4 | AJ6: 1 | AK6: 9 | AL6: 19 | AM6: 0.3 | AN6: 79.6 | AO6: 1.4 | AP6: BLD | AQ6: 0.009 | AR6: BLD | AS6: BLD | AT6: BLD
A7: CAGE-22-1-HH-352-BC-A-5-6 | B7: 3.6 | C7: 236.4 | D7: 13.9 | E7: 47 | F7: 0.1 | G7: 37.8 | H7: 10.5 | I7: 270 | J7: 2.86 | K7: 7 | L7: 2.4 | M7: 6.3 | N7: 145 | O7: BLD | P7: 0.3 | Q7: 0.2 | R7: 75 | S7: 1.2 | T7: 0.049 | U7: 23.2 | V7: 157 | W7: 1.1 | X7: 722 | Y7: 0.285 | Z7: 5.59 | AA7: 2.656 | AB7: 2.13 | AC7: 0.5 | AD7: 48.5 | AE7: 47 | AF7: 1.5 | AG7: 14.2 | AH7: 6.4 | AI7: 0.4 | AJ7: 1 | AK7: 9 | AL7: 18.8 | AM7: 0.3 | AN7: 79.4 | AO7: 1.4 | AP7: BLD | AQ7: 0.01 | AR7: BLD | AS7: BLD | AT7: BLD
A8: CAGE-22-1-HH-352-BC-A-6-7 | B8: 3.3 | C8: 292.5 | D8: 14.3 | E8: 47 | F8: 0.1 | G8: 39.3 | H8: 10.9 | I8: 265 | J8: 2.87 | K8: 8 | L8: 2.4 | M8: 6.5 | N8: 136 | O8: BLD | P8: 0.3 | Q8: 0.2 | R8: 75 | S8: 1.07 | T8: 0.048 | U8: 23.7 | V8: 176 | W8: 1.1 | X8: 787 | Y8: 0.284 | Z8: 5.76 | AA8: 2.625 | AB8: 2.18 | AC8: 0.5 | AD8: 49.1 | AE8: 48 | AF8: 1.5 | AG8: 13.9 | AH8: 6.1 | AI8: 0.4 | AJ8: 1 | AK8: 9 | AL8: 19.1 | AM8: 0.3 | AN8: 81.7 | AO8: 1.4 | AP8: BLD | AQ8: 0.013 | AR8: BLD | AS8: BLD | AT8: BLD
A9: CAGE-22-1-HH-352-BC-A-7-8 | B9: 3.2 | C9: 449.3 | D9: 13.3 | E9: 44 | F9: 0.1 | G9: 42.6 | H9: 11.4 | I9: 254 | J9: 3.02 | K9: 6 | L9: 2.3 | M9: 6.4 | N9: 125 | O9: BLD | P9: 0.3 | Q9: 0.3 | R9: 79 | S9: 0.91 | T9: 0.046 | U9: 22.8 | V9: 201 | W9: 1.08 | X9: 899 | Y9: 0.276 | Z9: 5.89 | AA9: 2.564 | AB9: 2.39 | AC9: 0.5 | AD9: 51.2 | AE9: 46 | AF9: 1.5 | AG9: 12.9 | AH9: 5.6 | AI9: 0.3 | AJ9: 1 | AK9: 9 | AL9: 18.8 | AM9: 0.3 | AN9: 84.7 | AO9: 1.5 | AP9: BLD | AQ9: 0.021 | AR9: BLD | AS9: BLD | AT9: BLD
A10: CAGE-22-1-HH-352-BC-A-8-9 | B10: 2.3 | C10: 700.4 | D10: 9.1 | E10: 36 | F10: 0.2 | G10: 46.2 | H10: 11.7 | I10: 211 | J10: 2.97 | K10: 7 | L10: 2.1 | M10: 6.2 | N10: 97 | O10: BLD | P10: 0.3 | Q10: 0.4 | R10: 79 | S10: 0.55 | T10: 0.034 | U10: 21 | V10: 277 | W10: 0.99 | X10: 1121 | Y10: 0.24 | Z10: 5.9 | AA10: 2.215 | AB10: 2.62 | AC10: 0.4 | AD10: 46.5 | AE10: 42 | AF10: 1.4 | AG10: 10 | AH10: 4.3 | AI10: 0.3 | AJ10: 1 | AK10: 8 | AL10: 16.9 | AM10: 0.2 | AN10: 86.8 | AO10: 1.3 | AP10: BLD | AQ10: 0.021 | AR10: BLD | AS10: BLD | AT10: BLD
A11: CAGE-22-1-HH-352-BC-A-9-10 | B11: 1.8 | C11: 719.8 | D11: 6.2 | E11: 32 | F11: 0.2 | G11: 50 | H11: 13 | I11: 224 | J11: 3.18 | K11: 3 | L11: 1.9 | M11: 5.9 | N11: 76 | O11: BLD | P11: 0.3 | Q11: 0.4 | R11: 82 | S11: 0.39 | T11: 0.029 | U11: 19.4 | V11: 321 | W11: 1.03 | X11: 1204 | Y11: 0.23 | Z11: 6.03 | AA11: 2.103 | AB11: 2.83 | AC11: 0.3 | AD11: 45.6 | AE11: 39 | AF11: 1.3 | AG11: 8.9 | AH11: 3.5 | AI11: 0.2 | AJ11: BLD | AK11: 9 | AL11: 16.7 | AM11: 0.2 | AN11: 88.9 | AO11: 1.3 | AP11: BLD | AQ11: 0.027 | AR11: BLD | AS11: BLD | AT11: BLD
A12: CAGE-22-1-HH-352-BC-A-10-11 | B12: 1.6 | C12: 670.9 | D12: 6.1 | E12: 30 | F12: 0.1 | G12: 50.4 | H12: 11.9 | I12: 190 | J12: 3.06 | K12: 3 | L12: 1.9 | M12: 6 | N12: 77 | O12: BLD | P12: 0.2 | Q12: 0.4 | R12: 81 | S12: 0.37 | T12: 0.028 | U12: 19.6 | V12: 307 | W12: 1 | X12: 1274 | Y12: 0.217 | Z12: 6.38 | AA12: 2.134 | AB12: 2.93 | AC12: 0.3 | AD12: 46.6 | AE12: 39 | AF12: 1.4 | AG12: 8.6 | AH12: 3.4 | AI12: 0.2 | AJ12: 1 | AK12: 8 | AL12: 16.7 | AM12: 0.2 | AN12: 92.7 | AO12: 1.3 | AP12: BLD | AQ12: 0.035 | AR12: BLD | AS12: BLD | AT12: BLD
A13: CAGE-22-1-HH-352-BC-A-11-12 | B13: 1.1 | C13: 594.7 | D13: 4.1 | E13: 24 | F13: BLD | G13: 50 | H13: 10.8 | I13: 165 | J13: 2.94 | K13: 3 | L13: 1.7 | M13: 6.1 | N13: 67 | O13: BLD | P13: 0.2 | Q13: 0.4 | R13: 80 | S13: 0.22 | T13: 0.025 | U13: 19.3 | V13: 309 | W13: 0.93 | X13: 1330 | Y13: 0.2 | Z13: 6.27 | AA13: 2.098 | AB13: 2.94 | AC13: 0.3 | AD13: 46 | AE13: 38 | AF13: 1.5 | AG13: 7.7 | AH13: 2.8 | AI13: 0.1 | AJ13: 1 | AK13: 8 | AL13: 15.5 | AM13: 0.1 | AN13: 92.3 | AO13: 1.3 | AP13: BLD | AQ13: 0.033 | AR13: BLD | AS13: BLD | AT13: BLD
A14: CAGE-22-1-HH-352-BC-A-12-13 | B14: 1.2 | C14: 558.1 | D14: 5.5 | E14: 24 | F14: BLD | G14: 51.2 | H14: 11 | I14: 164 | J14: 3.01 | K14: 2 | L14: 1.7 | M14: 5.9 | N14: 67 | O14: BLD | P14: 0.2 | Q14: 0.4 | R14: 79 | S14: 0.2 | T14: 0.025 | U14: 19 | V14: 323 | W14: 0.92 | X14: 1360 | Y14: 0.202 | Z14: 6.23 | AA14: 2.154 | AB14: 2.97 | AC14: 0.3 | AD14: 45.9 | AE14: 38 | AF14: 1.4 | AG14: 7.7 | AH14: 2.7 | AI14: 0.1 | AJ14: 1 | AK14: 8 | AL14: 15.4 | AM14: 0.1 | AN14: 93.3 | AO14: 1.3 | AP14: BLD | AQ14: 0.035 | AR14: BLD | AS14: BLD | AT14: BLD
A15: CAGE-22-1-HH-352-BC-A-13-14 | B15: 1.1 | C15: 529.2 | D15: 3.5 | E15: 25 | F15: BLD | G15: 54.5 | H15: 12.2 | I15: 181 | J15: 3.17 | K15: 2 | L15: 1.7 | M15: 6.4 | N15: 65 | O15: BLD | P15: 0.2 | Q15: 0.4 | R15: 82 | S15: 0.18 | T15: 0.025 | U15: 19.5 | V15: 343 | W15: 1.03 | X15: 1476 | Y15: 0.208 | Z15: 6.52 | AA15: 2.152 | AB15: 3.09 | AC15: 0.3 | AD15: 47.7 | AE15: 39 | AF15: 1.5 | AG15: 7.8 | AH15: 2.7 | AI15: 0.1 | AJ15: 1 | AK15: 8 | AL15: 16.5 | AM15: 0.1 | AN15: 95.4 | AO15: 1.3 | AP15: BLD | AQ15: 0.036 | AR15: BLD | AS15: BLD | AT15: BLD
A16: CAGE-22-1-HH-352-BC-A-14-15 | B16: 1.2 | C16: 651.9 | D16: 3.4 | E16: 24 | F16: 0.1 | G16: 53.9 | H16: 12 | I16: 180 | J16: 3.18 | K16: 2 | L16: 1.6 | M16: 6 | N16: 66 | O16: BLD | P16: 0.2 | Q16: 0.4 | R16: 84 | S16: 0.21 | T16: 0.025 | U16: 19.1 | V16: 331 | W16: 1.01 | X16: 1472 | Y16: 0.2 | Z16: 6.46 | AA16: 2.222 | AB16: 3.05 | AC16: 0.4 | AD16: 46.2 | AE16: 38 | AF16: 1.3 | AG16: 7.4 | AH16: 2.6 | AI16: 0.1 | AJ16: BLD | AK16: 8 | AL16: 16.3 | AM16: 0.1 | AN16: 93.3 | AO16: 1.3 | AP16: BLD | AQ16: 0.032 | AR16: BLD | AS16: BLD | AT16: BLD
A17: CAGE-22-1-HH-352-BC-A-15-16 | B17: 1.4 | C17: 638.5 | D17: 3.8 | E17: 26 | F17: 0.1 | G17: 54.2 | H17: 12.6 | I17: 186 | J17: 3.18 | K17: 1 | L17: 1.7 | M17: 6.1 | N17: 65 | O17: BLD | P17: 0.2 | Q17: 0.4 | R17: 84 | S17: 0.23 | T17: 0.025 | U17: 19.1 | V17: 339 | W17: 1.06 | X17: 1500 | Y17: 0.204 | Z17: 6.47 | AA17: 2.201 | AB17: 2.99 | AC17: 0.4 | AD17: 45.7 | AE17: 38 | AF17: 1.4 | AG17: 7.3 | AH17: 2.7 | AI17: 0.1 | AJ17: 1 | AK17: 8 | AL17: 16.7 | AM17: 0.1 | AN17: 92.7 | AO17: 1.3 | AP17: BLD | AQ17: 0.04 | AR17: BLD | AS17: BLD | AT17: BLD
A18: CAGE-22-1-HH-352-BC-A-16-17 | B18: 1.3 | C18: 747 | D18: 3.5 | E18: 25 | F18: BLD | G18: 55.4 | H18: 12.6 | I18: 187 | J18: 3.19 | K18: 2 | L18: 1.6 | M18: 6 | N18: 66 | O18: BLD | P18: 0.2 | Q18: 0.4 | R18: 83 | S18: 0.23 | T18: 0.025 | U18: 18.8 | V18: 356 | W18: 1.06 | X18: 1549 | Y18: 0.207 | Z18: 6.5 | AA18: 2.288 | AB18: 3.04 | AC18: 0.4 | AD18: 46 | AE18: 37 | AF18: 1.3 | AG18: 7.2 | AH18: 2.7 | AI18: 0.1 | AJ18: BLD | AK18: 8 | AL18: 16.9 | AM18: 0.1 | AN18: 92.2 | AO18: 1.3 | AP18: BLD | AQ18: 0.031 | AR18: BLD | AS18: BLD | AT18: BLD
A19: CAGE-22-1-HH-352-BC-A-17-18 | B19: 0.8 | C19: 815.6 | D19: 2.8 | E19: 24 | F19: 0.1 | G19: 54.8 | H19: 12.4 | I19: 190 | J19: 3.08 | K19: 1 | L19: 1.5 | M19: 5.6 | N19: 64 | O19: BLD | P19: 0.2 | Q19: 0.4 | R19: 77 | S19: 0.24 | T19: 0.024 | U19: 18.2 | V19: 331 | W19: 1.03 | X19: 1451 | Y19: 0.191 | Z19: 6.28 | AA19: 2.466 | AB19: 2.76 | AC19: 0.6 | AD19: 44.5 | AE19: 37 | AF19: 1.2 | AG19: 6.9 | AH19: 2.5 | AI19: 0.1 | AJ19: BLD | AK19: 8 | AL19: 16.2 | AM19: 0.1 | AN19: 83.2 | AO19: 1.2 | AP19: BLD | AQ19: 0.014 | AR19: BLD | AS19: BLD | AT19: BLD
A20: CAGE-22-1-HH-352-BC-A-18-19 | B20: 0.4 | C20: 1033.1 | D20: 2.4 | E20: 23 | F20: 0.1 | G20: 52.6 | H20: 12.2 | I20: 183 | J20: 2.88 | K20: 2 | L20: 1.4 | M20: 5.4 | N20: 64 | O20: BLD | P20: 0.2 | Q20: 0.4 | R20: 72 | S20: 0.21 | T20: 0.022 | U20: 19.2 | V20: 309 | W20: 0.96 | X20: 1536 | Y20: 0.186 | Z20: 6.04 | AA20: 2.521 | AB20: 2.54 | AC20: 0.5 | AD20: 45.8 | AE20: 38 | AF20: 1.1 | AG20: 6.8 | AH20: 2.3 | AI20: 0.1 | AJ20: BLD | AK20: 7 | AL20: 15.4 | AM20: BLD | AN20: 78.7 | AO20: 1.3 | AP20: BLD | AQ20: 0.009 | AR20: BLD | AS20: BLD | AT20: BLD
A21: CAGE-22-1-HH-352-BC-A-19-20 | B21: 0.6 | C21: 1195.6 | D21: 2.3 | E21: 22 | F21: 0.1 | G21: 49.3 | H21: 12 | I21: 164 | J21: 2.8 | K21: BLD | L21: 1.3 | M21: 5.1 | N21: 61 | O21: BLD | P21: 0.2 | Q21: 0.4 | R21: 70 | S21: 0.19 | T21: 0.021 | U21: 18.1 | V21: 283 | W21: 0.9 | X21: 1449 | Y21: 0.175 | Z21: 5.77 | AA21: 2.411 | AB21: 2.41 | AC21: 0.5 | AD21: 44.8 | AE21: 35 | AF21: 1.1 | AG21: 6.6 | AH21: 2.1 | AI21: 0.1 | AJ21: BLD | AK21: 7 | AL21: 14.4 | AM21: 0.2 | AN21: 73.1 | AO21: 1.3 | AP21: BLD | AQ21: 0.01 | AR21: BLD | AS21: BLD | AT21: BLD
A22: CAGE-22-1-HH-352-BC-A-20-21 | B22: 0.8 | C22: 1614.9 | D22: 2.7 | E22: 26 | F22: 0.2 | G22: 52.5 | H22: 13 | I22: 194 | J22: 3.15 | K22: 1 | L22: 1.4 | M22: 5.3 | N22: 63 | O22: BLD | P22: 0.2 | Q22: 0.6 | R22: 81 | S22: 0.27 | T22: 0.025 | U22: 18 | V22: 295 | W22: 1.03 | X22: 1211 | Y22: 0.184 | Z22: 6.15 | AA22: 2.494 | AB22: 2.6 | AC22: 0.5 | AD22: 44.5 | AE22: 35 | AF22: 1.1 | AG22: 7 | AH22: 2.3 | AI22: 0.1 | AJ22: BLD | AK22: 8 | AL22: 15.6 | AM22: 0.2 | AN22: 78.2 | AO22: 1.2 | AP22: BLD | AQ22: 0.014 | AR22: BLD | AS22: BLD | AT22: BLD
A23: CAGE-22-1-HH-352-BC-A-21-22 | B23: 0.7 | C23: 1476 | D23: 4.1 | E23: 30 | F23: 0.2 | G23: 54.7 | H23: 13.3 | I23: 202 | J23: 3.1 | K23: 2 | L23: 1.4 | M23: 5.3 | N23: 58 | O23: BLD | P23: 0.3 | Q23: 0.5 | R23: 80 | S23: 0.24 | T23: 0.025 | U23: 17.4 | V23: 293 | W23: 1.04 | X23: 1088 | Y23: 0.182 | Z23: 5.93 | AA23: 2.191 | AB23: 2.62 | AC23: 0.7 | AD23: 42.7 | AE23: 35 | AF23: 1.2 | AG23: 6.9 | AH23: 2.4 | AI23: 0.1 | AJ23: BLD | AK23: 8 | AL23: 16.2 | AM23: 0.1 | AN23: 79.7 | AO23: 1.2 | AP23: BLD | AQ23: 0.013 | AR23: BLD | AS23: BLD | AT23: BLD
A24: CAGE-22-1-HH-352-BC-A-22-23 | B24: 0.4 | C24: 838.9 | D24: 3.2 | E24: 31 | F24: 0.1 | G24: 60.9 | H24: 14.8 | I24: 255 | J24: 3.25 | K24: BLD | L24: 1.5 | M24: 5.6 | N24: 53 | O24: BLD | P24: 0.2 | Q24: 0.4 | R24: 88 | S24: 0.33 | T24: 0.027 | U24: 17.5 | V24: 312 | W24: 1.27 | X24: 945 | Y24: 0.194 | Z24: 6.33 | AA24: 2.186 | AB24: 2.66 | AC24: 0.8 | AD24: 43.1 | AE24: 35 | AF24: 1.1 | AG24: 7.6 | AH24: 2.6 | AI24: 0.2 | AJ24: BLD | AK24: 9 | AL24: 18.1 | AM24: BLD | AN24: 80.5 | AO24: 1.2 | AP24: BLD | AQ24: 0.011 | AR24: BLD | AS24: BLD | AT24: BLD
A25: CAGE-22-1-HH-352-BC-A-23-24 | B25: 0.5 | C25: 703.8 | D25: 2.9 | E25: 30 | F25: BLD | G25: 61.1 | H25: 14.8 | I25: 264 | J25: 3.36 | K25: 1 | L25: 1.5 | M25: 5.7 | N25: 56 | O25: BLD | P25: 0.2 | Q25: 0.4 | R25: 89 | S25: 0.37 | T25: 0.028 | U25: 18 | V25: 325 | W25: 1.28 | X25: 973 | Y25: 0.199 | Z25: 6.38 | AA25: 2.217 | AB25: 2.73 | AC25: 0.6 | AD25: 44.7 | AE25: 36 | AF25: 1.1 | AG25: 8 | AH25: 2.6 | AI25: 0.2 | AJ25: BLD | AK25: 9 | AL25: 18.5 | AM25: BLD | AN25: 83.7 | AO25: 1.3 | AP25: BLD | AQ25: 0.009 | AR25: BLD | AS25: BLD | AT25: BLD
A26: CAGE-22-1-HH-357-BC-0-1 | B26: 0.6 | C26: 23.2 | D26: 12.5 | E26: 35 | F26: BLD | G26: 23.4 | H26: 7.3 | I26: 324 | J26: 2.1 | K26: 1 | L26: 1.8 | M26: 7.3 | N26: 182 | O26: BLD | P26: 0.2 | Q26: 0.1 | R26: 54 | S26: 1.77 | T26: 0.062 | U26: 21.6 | V26: 67 | W26: 0.81 | X26: 379 | Y26: 0.314 | Z26: 4.63 | AA26: 2.198 | AB26: 1.46 | AC26: 0.4 | AD26: 64.1 | AE26: 45 | AF26: 1.2 | AG26: 17.7 | AH26: 7.3 | AI26: 0.5 | AJ26: 1 | AK26: 9 | AL26: 13 | AM26: 0.1 | AN26: 52.7 | AO26: 1.9 | AP26: BLD | AQ26: BLD | AR26: 1 | AS26: BLD | AT26: BLD
A27: CAGE-22-1-HH-357-BC-1-2 | B27: 0.6 | C27: 25.1 | D27: 12.1 | E27: 33 | F27: BLD | G27: 22.6 | H27: 7 | I27: 309 | J27: 1.97 | K27: 2 | L27: 1.8 | M27: 5.1 | N27: 172 | O27: BLD | P27: 0.2 | Q27: 0.1 | R27: 53 | S27: 1.73 | T27: 0.054 | U27: 23.2 | V27: 71 | W27: 0.77 | X27: 357 | Y27: 0.301 | Z27: 4.4 | AA27: 2.066 | AB27: 1.36 | AC27: 0.4 | AD27: 59.3 | AE27: 48 | AF27: 1.2 | AG27: 17.1 | AH27: 7 | AI27: 0.5 | AJ27: BLD | AK27: 8 | AL27: 12.6 | AM27: 0.1 | AN27: 50.7 | AO27: 1.7 | AP27: BLD | AQ27: BLD | AR27: BLD | AS27: BLD | AT27: BLD
A28: CAGE-22-1-HH-357-BC-2-3 | B28: 0.6 | C28: 25.4 | D28: 12.6 | E28: 34 | F28: BLD | G28: 22.9 | H28: 7.3 | I28: 314 | J28: 2.05 | K28: BLD | L28: 1.8 | M28: 5.4 | N28: 183 | O28: BLD | P28: 0.2 | Q28: 0.1 | R28: 54 | S28: 1.83 | T28: 0.058 | U28: 23.4 | V28: 68 | W28: 0.79 | X28: 373 | Y28: 0.319 | Z28: 4.66 | AA28: 2.232 | AB28: 1.44 | AC28: 0.4 | AD28: 69.4 | AE28: 48 | AF28: 1.2 | AG28: 17.9 | AH28: 7.7 | AI28: 0.5 | AJ28: 1 | AK28: 9 | AL28: 13 | AM28: 0.1 | AN28: 52.7 | AO28: 2 | AP28: BLD | AQ28: BLD | AR28: BLD | AS28: BLD | AT28: BLD
A29: CAGE-22-1-HH-357-BC-3-4 | B29: 0.7 | C29: 24.1 | D29: 12.8 | E29: 35 | F29: BLD | G29: 23.5 | H29: 7.4 | I29: 325 | J29: 2.05 | K29: 2 | L29: 1.8 | M29: 5.1 | N29: 187 | O29: BLD | P29: 0.2 | Q29: 0.1 | R29: 54 | S29: 1.88 | T29: 0.058 | U29: 22.6 | V29: 70 | W29: 0.8 | X29: 370 | Y29: 0.319 | Z29: 4.71 | AA29: 2.28 | AB29: 1.42 | AC29: 0.4 | AD29: 64.7 | AE29: 47 | AF29: 1.3 | AG29: 18.2 | AH29: 7.8 | AI29: 0.5 | AJ29: 1 | AK29: 9 | AL29: 12.6 | AM29: 0.1 | AN29: 51.9 | AO29: 1.8 | AP29: BLD | AQ29: BLD | AR29: BLD | AS29: BLD | AT29: BLD
A30: CAGE-22-1-HH-357-BC-4-5 | B30: 0.9 | C30: 25.9 | D30: 13.1 | E30: 34 | F30: BLD | G30: 23.2 | H30: 7.2 | I30: 324 | J30: 2.06 | K30: 2 | L30: 1.8 | M30: 5.6 | N30: 183 | O30: BLD | P30: 0.2 | Q30: 0.1 | R30: 53 | S30: 1.77 | T30: 0.055 | U30: 23.3 | V30: 71 | W30: 0.8 | X30: 378 | Y30: 0.314 | Z30: 4.57 | AA30: 2.16 | AB30: 1.43 | AC30: 0.4 | AD30: 66.1 | AE30: 48 | AF30: 1.2 | AG30: 18.1 | AH30: 7.6 | AI30: 0.5 | AJ30: 2 | AK30: 9 | AL30: 12.6 | AM30: 0.1 | AN30: 52.6 | AO30: 2 | AP30: BLD | AQ30: BLD | AR30: BLD | AS30: BLD | AT30: BLD
A31: CAGE-22-1-HH-357-BC-5-6 | B31: 0.7 | C31: 25.4 | D31: 12.3 | E31: 31 | F31: BLD | G31: 21.4 | H31: 6.8 | I31: 322 | J31: 1.94 | K31: 1 | L31: 1.6 | M31: 5 | N31: 177 | O31: BLD | P31: 0.2 | Q31: BLD | R31: 50 | S31: 1.68 | T31: 0.058 | U31: 22.5 | V31: 61 | W31: 0.73 | X31: 350 | Y31: 0.302 | Z31: 4.46 | AA31: 2.089 | AB31: 1.34 | AC31: 0.4 | AD31: 57 | AE31: 46 | AF31: 1.1 | AG31: 16.9 | AH31: 7.2 | AI31: 0.5 | AJ31: 1 | AK31: 8 | AL31: 11.3 | AM31: 0.1 | AN31: 48.9 | AO31: 1.6 | AP31: BLD | AQ31: BLD | AR31: BLD | AS31: BLD | AT31: BLD
A32: CAGE-22-1-HH-357-BC-6-7 | B32: 0.8 | C32: 26.7 | D32: 12.6 | E32: 34 | F32: BLD | G32: 22.6 | H32: 7.3 | I32: 322 | J32: 2.04 | K32: 1 | L32: 1.9 | M32: 5.4 | N32: 183 | O32: BLD | P32: 0.3 | Q32: 0.1 | R32: 53 | S32: 1.94 | T32: 0.054 | U32: 22.5 | V32: 68 | W32: 0.78 | X32: 367 | Y32: 0.315 | Z32: 4.66 | AA32: 2.107 | AB32: 1.41 | AC32: 0.4 | AD32: 66.3 | AE32: 47 | AF32: 1.2 | AG32: 18.5 | AH32: 7.8 | AI32: 0.5 | AJ32: 1 | AK32: 9 | AL32: 12.4 | AM32: 0.1 | AN32: 52.1 | AO32: 1.9 | AP32: BLD | AQ32: BLD | AR32: 1 | AS32: BLD | AT32: BLD
A33: CAGE-22-1-HH-357-BC-7-8 | B33: 0.8 | C33: 27.8 | D33: 12.1 | E33: 30 | F33: BLD | G33: 21.1 | H33: 6.6 | I33: 298 | J33: 1.9 | K33: 3 | L33: 1.8 | M33: 5.4 | N33: 195 | O33: BLD | P33: 0.2 | Q33: 0.1 | R33: 48 | S33: 1.89 | T33: 0.054 | U33: 23.8 | V33: 63 | W33: 0.71 | X33: 354 | Y33: 0.308 | Z33: 4.44 | AA33: 2.064 | AB33: 1.35 | AC33: 0.4 | AD33: 64.2 | AE33: 49 | AF33: 1.1 | AG33: 17.2 | AH33: 7.4 | AI33: 0.5 | AJ33: 1 | AK33: 8 | AL33: 11.1 | AM33: 0.1 | AN33: 48.6 | AO33: 1.9 | AP33: BLD | AQ33: BLD | AR33: BLD | AS33: BLD | AT33: BLD
A34: CAGE-22-1-HH-357-BC-8-9 | B34: 0.9 | C34: 23.7 | D34: 12.2 | E34: 32 | F34: BLD | G34: 22.1 | H34: 7.1 | I34: 322 | J34: 2.01 | K34: 3 | L34: 1.8 | M34: 4.9 | N34: 178 | O34: BLD | P34: 0.2 | Q34: BLD | R34: 51 | S34: 1.68 | T34: 0.051 | U34: 21.6 | V34: 62 | W34: 0.76 | X34: 357 | Y34: 0.306 | Z34: 4.62 | AA34: 2.15 | AB34: 1.39 | AC34: 0.4 | AD34: 61.3 | AE34: 45 | AF34: 1.1 | AG34: 17.6 | AH34: 7.2 | AI34: 0.5 | AJ34: 1 | AK34: 9 | AL34: 11.9 | AM34: 0.1 | AN34: 51 | AO34: 1.8 | AP34: BLD | AQ34: BLD | AR34: 1 | AS34: BLD | AT34: BLD
A35: CAGE-22-1-HH-357-BC-9-10 | B35: 0.9 | C35: 19 | D35: 11.3 | E35: 31 | F35: BLD | G35: 22 | H35: 6.9 | I35: 310 | J35: 1.95 | K35: 2 | L35: 1.9 | M35: 5.1 | N35: 175 | O35: BLD | P35: 0.3 | Q35: BLD | R35: 50 | S35: 1.68 | T35: 0.05 | U35: 22.8 | V35: 57 | W35: 0.76 | X35: 346 | Y35: 0.301 | Z35: 4.44 | AA35: 2.058 | AB35: 1.35 | AC35: 0.4 | AD35: 55.8 | AE35: 47 | AF35: 1.1 | AG35: 17.1 | AH35: 7.3 | AI35: 0.5 | AJ35: 1 | AK35: 8 | AL35: 11.8 | AM35: 0.1 | AN35: 49.4 | AO35: 1.5 | AP35: BLD | AQ35: BLD | AR35: 1 | AS35: BLD | AT35: BLD
A36: CAGE-22-1-HH-357-BC-10-11 | B36: 1 | C36: 17.4 | D36: 11.3 | E36: 30 | F36: BLD | G36: 21.7 | H36: 6.8 | I36: 302 | J36: 1.93 | K36: 3 | L36: 1.9 | M36: 4.7 | N36: 184 | O36: BLD | P36: 0.2 | Q36: BLD | R36: 50 | S36: 2.05 | T36: 0.048 | U36: 20.8 | V36: 63 | W36: 0.72 | X36: 343 | Y36: 0.294 | Z36: 4.42 | AA36: 2.071 | AB36: 1.32 | AC36: 0.4 | AD36: 61.2 | AE36: 44 | AF36: 1 | AG36: 16.5 | AH36: 6.9 | AI36: 0.5 | AJ36: 1 | AK36: 8 | AL36: 11.5 | AM36: 0.2 | AN36: 49 | AO36: 1.7 | AP36: BLD | AQ36: 0.006 | AR36: BLD | AS36: BLD | AT36: BLD
A37: CAGE-22-1-HH-346-BC-A-0-1 | B37: 0.7 | C37: 131 | D37: 11.3 | E37: 42 | F37: BLD | G37: 32.4 | H37: 9.7 | I37: 273 | J37: 2.49 | K37: 4 | L37: 1.6 | M37: 5.6 | N37: 145 | O37: BLD | P37: 0.3 | Q37: 0.1 | R37: 61 | S37: 1.03 | T37: 0.06 | U37: 22.3 | V37: 129 | W37: 0.97 | X37: 542 | Y37: 0.289 | Z37: 5.21 | AA37: 2.748 | AB37: 1.82 | AC37: 0.5 | AD37: 52.1 | AE37: 45 | AF37: 1.3 | AG37: 14.9 | AH37: 6.6 | AI37: 0.4 | AJ37: 1 | AK37: 8 | AL37: 16.6 | AM37: 0.2 | AN37: 70.6 | AO37: 1.5 | AP37: BLD | AQ37: 0.016 | AR37: BLD | AS37: BLD | AT37: BLD
A38: CAGE-22-1-HH-346-BC-A-1-2 | B38: 1.2 | C38: 143.8 | D38: 11.5 | E38: 44 | F38: 0.1 | G38: 32.3 | H38: 9.7 | I38: 267 | J38: 2.5 | K38: 5 | L38: 2 | M38: 6.1 | N38: 143 | O38: BLD | P38: 0.3 | Q38: 0.2 | R38: 65 | S38: 0.99 | T38: 0.049 | U38: 23.1 | V38: 138 | W38: 0.98 | X38: 568 | Y38: 0.276 | Z38: 4.99 | AA38: 2.605 | AB38: 1.82 | AC38: 0.4 | AD38: 52.3 | AE38: 46 | AF38: 1.3 | AG38: 14.5 | AH38: 6.5 | AI38: 0.4 | AJ38: 1 | AK38: 8 | AL38: 16.6 | AM38: 0.2 | AN38: 74 | AO38: 1.4 | AP38: BLD | AQ38: 0.015 | AR38: BLD | AS38: BLD | AT38: BLD
A39: CAGE-22-1-HH-346-BC-A-2-3 | B39: 2.2 | C39: 157.5 | D39: 11.4 | E39: 42 | F39: 0.1 | G39: 32.9 | H39: 9.8 | I39: 273 | J39: 2.46 | K39: 5 | L39: 2.3 | M39: 5.9 | N39: 141 | O39: BLD | P39: 0.3 | Q39: 0.2 | R39: 64 | S39: 1.01 | T39: 0.047 | U39: 22.1 | V39: 146 | W39: 0.95 | X39: 593 | Y39: 0.27 | Z39: 5.08 | AA39: 2.527 | AB39: 1.87 | AC39: 0.4 | AD39: 50.3 | AE39: 44 | AF39: 1.3 | AG39: 14.5 | AH39: 6.4 | AI39: 0.4 | AJ39: 1 | AK39: 8 | AL39: 16.6 | AM39: 0.2 | AN39: 74.2 | AO39: 1.4 | AP39: BLD | AQ39: 0.022 | AR39: 1 | AS39: BLD | AT39: BLD
A40: CAGE-22-1-HH-346-BC-A-3-4 | B40: 3.1 | C40: 167.7 | D40: 11.7 | E40: 44 | F40: 0.1 | G40: 33.7 | H40: 9.9 | I40: 253 | J40: 2.49 | K40: 6 | L40: 2.7 | M40: 5.9 | N40: 147 | O40: BLD | P40: 0.3 | Q40: 0.2 | R40: 65 | S40: 1.06 | T40: 0.075 | U40: 23.7 | V40: 152 | W40: 0.95 | X40: 614 | Y40: 0.28 | Z40: 5.14 | AA40: 2.488 | AB40: 1.87 | AC40: 0.4 | AD40: 53.1 | AE40: 47 | AF40: 1.4 | AG40: 15.1 | AH40: 6.7 | AI40: 0.4 | AJ40: 1 | AK40: 8 | AL40: 16.6 | AM40: 0.2 | AN40: 75.1 | AO40: 1.5 | AP40: BLD | AQ40: 0.02 | AR40: 1 | AS40: BLD | AT40: BLD
...

Sheet Semi_total_bulk (2)
A1: Sample | B1: Mo | C1: Cu | D1: Pb | E1: Zn | F1: Ag | G1: Ni | H1: Co | I1: Mn | J1: Fe | K1: As | L1: U | M1: Th | N1: Sr | O1: Cd | P1: Sb | Q1: Bi | R1: V | S1: Ca | T1: P | U1: La | V1: Cr | W1: Mg | X1: Ba | Y1: Ti | Z1: Al | AA1: Na | AB1: K | AC1: W | AD1: Zr | AE1: Ce | AF1: Sn | AG1: Y | AH1: Nb | AI1: Ta | AJ1: Sc | AK1: Li | AL1: S | AM1: Rb | AN1: Hf | AO1: Be
A2: CAGE-22-1-HH-352-BC-A-0-1 | B2: 0.7 | C2: 150.2 | D2: 14.7 | E2: 47 | F2: =IF(Semi_total_bulk!F2="BLD", 0.65*0.1, Semi_total_bulk!F2) -> 0.1 | G2: 30.9 | H2: 10 | I2: 308 | J2: =Semi_total_bulk!J2*10000 -> 26400 | K2: =IF(Semi_total_bulk!K2="BLD", 0.65*1, Semi_total_bulk!K2) -> 7 | L2: 1.6 | M2: 6.1 | N2: 170 | O2: =IF(Semi_total_bulk!O2="BLD", 0.65*0.1, Semi_total_bulk!O2) -> 0.065 | P2: 0.3 | Q2: =IF(Semi_total_bulk!Q2="BLD", 0.65*0.1, Semi_total_bulk!Q2) -> 0.2 | R2: 64 | S2: =Semi_total_bulk!S2*10000 -> 13600 | T2: =Semi_total_bulk!T2*10000 -> 670 | U2: 22.8 | V2: 110 | W2: =Semi_total_bulk!W2*10000 -> 10200 | X2: 549 | Y2: =Semi_total_bulk!Y2*10000 -> 3000 | Z2: =Semi_total_bulk!Z2*10000 -> 51600 | AA2: =Semi_total_bulk!AA2*10000 -> 28680 | AB2: =Semi_total_bulk!AB2*10000 -> 18600 | AC2: 0.6 | AD2: 51.6 | AE2: 47 | AF2: 1.4 | AG2: 15.7 | AH2: 7.2 | AI2: 0.5 | AJ2: 9 | AK2: 16.9 | AL2: =IF(Semi_total_bulk!AM2="BLD",0.65*0.1,Semi_total_bulk!AM2)*10000 -> 2000 | AM2: 72.2 | AN2: 1.5 | AO2: =IF(Semi_total_bulk!AJ2="BLD", 0.65*0.1, Semi_total_bulk!AJ2) -> 1
A3: CAGE-22-1-HH-352-BC-A-1-2 | B3: 0.7 | C3: 129.9 | D3: 13.9 | E3: 46 | F3: =IF(Semi_total_bulk!F3="BLD", 0.65*0.1, Semi_total_bulk!F3) -> 0.065 | G3: 31.9 | H3: 9.6 | I3: 297 | J3: =Semi_total_bulk!J3*10000 -> 26300 | K3: =IF(Semi_total_bulk!K3="BLD", 0.65*1, Semi_total_bulk!K3) -> 4 | L3: 1.8 | M3: 6 | N3: 166 | O3: =IF(Semi_total_bulk!O3="BLD", 0.65*0.1, Semi_total_bulk!O3) -> 0.065 | P3: 0.3 | Q3: =IF(Semi_total_bulk!Q3="BLD", 0.65*0.1, Semi_total_bulk!Q3) -> 0.2 | R3: 67 | S3: =Semi_total_bulk!S3*10000 -> 13800 | T3: =Semi_total_bulk!T3*10000 -> 630 | U3: 23.2 | V3: 115 | W3: =Semi_total_bulk!W3*10000 -> 10500 | X3: 589 | Y3: =Semi_total_bulk!Y3*10000 -> 3070 | Z3: =Semi_total_bulk!Z3*10000 -> 54000 | AA3: =Semi_total_bulk!AA3*10000 -> 28350 | AB3: =Semi_total_bulk!AB3*10000 -> 19400 | AC3: 0.6 | AD3: 54.6 | AE3: 48 | AF3: 1.7 | AG3: 16.3 | AH3: 7.3 | AI3: 0.5 | AJ3: 9 | AK3: 17.7 | AL3: =IF(Semi_total_bulk!AM3="BLD",0.65*0.1,Semi_total_bulk!AM3)*10000 -> 2000 | AM3: 75.1 | AN3: 1.5 | AO3: =IF(Semi_total_bulk!AJ3="BLD", 0.65*0.1, Semi_total_bulk!AJ3) -> 1
A4: CAGE-22-1-HH-352-BC-A-2-3 | B4: 1.2 | C4: 145.4 | D4: 14.2 | E4: 47 | F4: =IF(Semi_total_bulk!F4="BLD", 0.65*0.1, Semi_total_bulk!F4) -> 0.065 | G4: 33.8 | H4: 9.9 | I4: 296 | J4: =Semi_total_bulk!J4*10000 -> 26300 | K4: =IF(Semi_total_bulk!K4="BLD", 0.65*1, Semi_total_bulk!K4) -> 5 | L4: 2 | M4: 6.3 | N4: 164 | O4: =IF(Semi_total_bulk!O4="BLD", 0.65*0.1, Semi_total_bulk!O4) -> 0.065 | P4: 0.3 | Q4: =IF(Semi_total_bulk!Q4="BLD", 0.65*0.1, Semi_total_bulk!Q4) -> 0.2 | R4: 70 | S4: =Semi_total_bulk!S4*10000 -> 13400 | T4: =Semi_total_bulk!T4*10000 -> 560 | U4: 23.8 | V4: 119 | W4: =Semi_total_bulk!W4*10000 -> 10700 | X4: 622 | Y4: =Semi_total_bulk!Y4*10000 -> 3140 | Z4: =Semi_total_bulk!Z4*10000 -> 54300 | AA4: =Semi_total_bulk!AA4*10000 -> 27390 | AB4: =Semi_total_bulk!AB4*10000 -> 20000 | AC4: 0.5 | AD4: 53.1 | AE4: 49 | AF4: 1.5 | AG4: 16.1 | AH4: 7.2 | AI4: 0.4 | AJ4: 9 | AK4: 18.4 | AL4: =IF(Semi_total_bulk!AM4="BLD",0.65*0.1,Semi_total_bulk!AM4)*10000 -> 2000 | AM4: 77.1 | AN4: 1.5 | AO4: =IF(Semi_total_bulk!AJ4="BLD", 0.65*0.1, Semi_total_bulk!AJ4) -> 1
A5: CAGE-22-1-HH-352-BC-A-3-4 | B5: 3 | C5: 193.4 | D5: 14.4 | E5: 49 | F5: =IF(Semi_total_bulk!F5="BLD", 0.65*0.1, Semi_total_bulk!F5) -> 0.1 | G5: 35.8 | H5: 10.2 | I5: 282 | J5: =Semi_total_bulk!J5*10000 -> 26700 | K5: =IF(Semi_total_bulk!K5="BLD", 0.65*1, Semi_total_bulk!K5) -> 5 | L5: 2.5 | M5: 6.5 | N5: 154 | O5: =IF(Semi_total_bulk!O5="BLD", 0.65*0.1, Semi_total_bulk!O5) -> 0.065 | P5: 0.3 | Q5: =IF(Semi_total_bulk!Q5="BLD", 0.65*0.1, Semi_total_bulk!Q5) -> 0.2 | R5: 69 | S5: =Semi_total_bulk!S5*10000 -> 12500 | T5: =Semi_total_bulk!T5*10000 -> 530 | U5: 23.7 | V5: 131 | W5: =Semi_total_bulk!W5*10000 -> 10800 | X5: 651 | Y5: =Semi_total_bulk!Y5*10000 -> 3020 | Z5: =Semi_total_bulk!Z5*10000 -> 53800 | AA5: =Semi_total_bulk!AA5*10000 -> 27050 | AB5: =Semi_total_bulk!AB5*10000 -> 20000 | AC5: 0.6 | AD5: 51.8 | AE5: 48 | AF5: 1.5 | AG5: 15.4 | AH5: 6.8 | AI5: 0.4 | AJ5: 9 | AK5: 18.8 | AL5: =IF(Semi_total_bulk!AM5="BLD",0.65*0.1,Semi_total_bulk!AM5)*10000 -> 3000 | AM5: 78.1 | AN5: 1.5 | AO5: =IF(Semi_total_bulk!AJ5="BLD", 0.65*0.1, Semi_total_bulk!AJ5) -> 1
A6: CAGE-22-1-HH-352-BC-A-4-5 | B6: 3.5 | C6: 215.5 | D6: 14.2 | E6: 48 | F6: =IF(Semi_total_bulk!F6="BLD", 0.65*0.1, Semi_total_bulk!F6) -> 0.1 | G6: 37.1 | H6: 10.6 | I6: 285 | J6: =Semi_total_bulk!J6*10000 -> 28300 | K6: =IF(Semi_total_bulk!K6="BLD", 0.65*1, Semi_total_bulk!K6) -> 6 | L6: 2.4 | M6: 6.6 | N6: 148 | O6: =IF(Semi_total_bulk!O6="BLD", 0.65*0.1, Semi_total_bulk!O6) -> 0.065 | P6: 0.3 | Q6: =IF(Semi_total_bulk!Q6="BLD", 0.65*0.1, Semi_total_bulk!Q6) -> 0.2 | R6: 72 | S6: =Semi_total_bulk!S6*10000 -> 12400 | T6: =Semi_total_bulk!T6*10000 -> 550 | U6: 23.9 | V6: 157 | W6: =Semi_total_bulk!W6*10000 -> 10900 | X6: 693 | Y6: =Semi_total_bulk!Y6*10000 -> 2920 | Z6: =Semi_total_bulk!Z6*10000 -> 54900 | AA6: =Semi_total_bulk!AA6*10000 -> 26630 | AB6: =Semi_total_bulk!AB6*10000 -> 21000 | AC6: 0.6 | AD6: 49.7 | AE6: 49 | AF6: 1.5 | AG6: 14.6 | AH6: 6.6 | AI6: 0.4 | AJ6: 9 | AK6: 19 | AL6: =IF(Semi_total_bulk!AM6="BLD",0.65*0.1,Semi_total_bulk!AM6)*10000 -> 3000 | AM6: 79.6 | AN6: 1.4 | AO6: =IF(Semi_total_bulk!AJ6="BLD", 0.65*0.1, Semi_total_bulk!AJ6) -> 1
A7: CAGE-22-1-HH-352-BC-A-5-6 | B7: 3.6 | C7: 236.4 | D7: 13.9 | E7: 47 | F7: =IF(Semi_total_bulk!F7="BLD", 0.65*0.1, Semi_total_bulk!F7) -> 0.1 | G7: 37.8 | H7: 10.5 | I7: 270 | J7: =Semi_total_bulk!J7*10000 -> 28600 | K7: =IF(Semi_total_bulk!K7="BLD", 0.65*1, Semi_total_bulk!K7) -> 7 | L7: 2.4 | M7: 6.3 | N7: 145 | O7: =IF(Semi_total_bulk!O7="BLD", 0.65*0.1, Semi_total_bulk!O7) -> 0.065 | P7: 0.3 | Q7: =IF(Semi_total_bulk!Q7="BLD", 0.65*0.1, Semi_total_bulk!Q7) -> 0.2 | R7: 75 | S7: =Semi_total_bulk!S7*10000 -> 12000 | T7: =Semi_total_bulk!T7*10000 -> 490 | U7: 23.2 | V7: 157 | W7: =Semi_total_bulk!W7*10000 -> 11000 | X7: 722 | Y7: =Semi_total_bulk!Y7*10000 -> 2850 | Z7: =Semi_total_bulk!Z7*10000 -> 55900 | AA7: =Semi_total_bulk!AA7*10000 -> 26560 | AB7: =Semi_total_bulk!AB7*10000 -> 21300 | AC7: 0.5 | AD7: 48.5 | AE7: 47 | AF7: 1.5 | AG7: 14.2 | AH7: 6.4 | AI7: 0.4 | AJ7: 9 | AK7: 18.8 | AL7: =IF(Semi_total_bulk!AM7="BLD",0.65*0.1,Semi_total_bulk!AM7)*10000 -> 3000 | AM7: 79.4 | AN7: 1.4 | AO7: =IF(Semi_total_bulk!AJ7="BLD", 0.65*0.1, Semi_total_bulk!AJ7) -> 1
A8: CAGE-22-1-HH-352-BC-A-6-7 | B8: 3.3 | C8: 292.5 | D8: 14.3 | E8: 47 | F8: =IF(Semi_total_bulk!F8="BLD", 0.65*0.1, Semi_total_bulk!F8) -> 0.1 | G8: 39.3 | H8: 10.9 | I8: 265 | J8: =Semi_total_bulk!J8*10000 -> 28700 | K8: =IF(Semi_total_bulk!K8="BLD", 0.65*1, Semi_total_bulk!K8) -> 8 | L8: 2.4 | M8: 6.5 | N8: 136 | O8: =IF(Semi_total_bulk!O8="BLD", 0.65*0.1, Semi_total_bulk!O8) -> 0.065 | P8: 0.3 | Q8: =IF(Semi_total_bulk!Q8="BLD", 0.65*0.1, Semi_total_bulk!Q8) -> 0.2 | R8: 75 | S8: =Semi_total_bulk!S8*10000 -> 10700 | T8: =Semi_total_bulk!T8*10000 -> 480 | U8: 23.7 | V8: 176 | W8: =Semi_total_bulk!W8*10000 -> 11000 | X8: 787 | Y8: =Semi_total_bulk!Y8*10000 -> 2840 | Z8: =Semi_total_bulk!Z8*10000 -> 57600 | AA8: =Semi_total_bulk!AA8*10000 -> 26250 | AB8: =Semi_total_bulk!AB8*10000 -> 21800 | AC8: 0.5 | AD8: 49.1 | AE8: 48 | AF8: 1.5 | AG8: 13.9 | AH8: 6.1 | AI8: 0.4 | AJ8: 9 | AK8: 19.1 | AL8: =IF(Semi_total_bulk!AM8="BLD",0.65*0.1,Semi_total_bulk!AM8)*10000 -> 3000 | AM8: 81.7 | AN8: 1.4 | AO8: =IF(Semi_total_bulk!AJ8="BLD", 0.65*0.1, Semi_total_bulk!AJ8) -> 1
A9: CAGE-22-1-HH-352-BC-A-7-8 | B9: 3.2 | C9: 449.3 | D9: 13.3 | E9: 44 | F9: =IF(Semi_total_bulk!F9="BLD", 0.65*0.1, Semi_total_bulk!F9) -> 0.1 | G9: 42.6 | H9: 11.4 | I9: 254 | J9: =Semi_total_bulk!J9*10000 -> 30200 | K9: =IF(Semi_total_bulk!K9="BLD", 0.65*1, Semi_total_bulk!K9) -> 6 | L9: 2.3 | M9: 6.4 | N9: 125 | O9: =IF(Semi_total_bulk!O9="BLD", 0.65*0.1, Semi_total_bulk!O9) -> 0.065 | P9: 0.3 | Q9: =IF(Semi_total_bulk!Q9="BLD", 0.65*0.1, Semi_total_bulk!Q9) -> 0.3 | R9: 79 | S9: =Semi_total_bulk!S9*10000 -> 9100 | T9: =Semi_total_bulk!T9*10000 -> 460 | U9: 22.8 | V9: 201 | W9: =Semi_total_bulk!W9*10000 -> 10800 | X9: 899 | Y9: =Semi_total_bulk!Y9*10000 -> 2760 | Z9: =Semi_total_bulk!Z9*10000 -> 58900 | AA9: =Semi_total_bulk!AA9*10000 -> 25640 | AB9: =Semi_total_bulk!AB9*10000 -> 23900 | AC9: 0.5 | AD9: 51.2 | AE9: 46 | AF9: 1.5 | AG9: 12.9 | AH9: 5.6 | AI9: 0.3 | AJ9: 9 | AK9: 18.8 | AL9: =IF(Semi_total_bulk!AM9="BLD",0.65*0.1,Semi_total_bulk!AM9)*10000 -> 3000 | AM9: 84.7 | AN9: 1.5 | AO9: =IF(Semi_total_bulk!AJ9="BLD", 0.65*0.1, Semi_total_bulk!AJ9) -> 1
A10: CAGE-22-1-HH-352-BC-A-8-9 | B10: 2.3 | C10: 700.4 | D10: 9.1 | E10: 36 | F10: =IF(Semi_total_bulk!F10="BLD", 0.65*0.1, Semi_total_bulk!F10) -> 0.2 | G10: 46.2 | H10: 11.7 | I10: 211 | J10: =Semi_total_bulk!J10*10000 -> 29700 | K10: =IF(Semi_total_bulk!K10="BLD", 0.65*1, Semi_total_bulk!K10) -> 7 | L10: 2.1 | M10: 6.2 | N10: 97 | O10: =IF(Semi_total_bulk!O10="BLD", 0.65*0.1, Semi_total_bulk!O10) -> 0.065 | P10: 0.3 | Q10: =IF(Semi_total_bulk!Q10="BLD", 0.65*0.1, Semi_total_bulk!Q10) -> 0.4 | R10: 79 | S10: =Semi_total_bulk!S10*10000 -> 5500 | T10: =Semi_total_bulk!T10*10000 -> 340 | U10: 21 | V10: 277 | W10: =Semi_total_bulk!W10*10000 -> 9900 | X10: 1121 | Y10: =Semi_total_bulk!Y10*10000 -> 2400 | Z10: =Semi_total_bulk!Z10*10000 -> 59000 | AA10: =Semi_total_bulk!AA10*10000 -> 22150 | AB10: =Semi_total_bulk!AB10*10000 -> 26200 | AC10: 0.4 | AD10: 46.5 | AE10: 42 | AF10: 1.4 | AG10: 10 | AH10: 4.3 | AI10: 0.3 | AJ10: 8 | AK10: 16.9 | AL10: =IF(Semi_total_bulk!AM10="BLD",0.65*0.1,Semi_total_bulk!AM10)*10000 -> 2000 | AM10: 86.8 | AN10: 1.3 | AO10: =IF(Semi_total_bulk!AJ10="BLD", 0.65*0.1, Semi_total_bulk!AJ10) -> 1
A11: CAGE-22-1-HH-352-BC-A-9-10 | B11: 1.8 | C11: 719.8 | D11: 6.2 | E11: 32 | F11: =IF(Semi_total_bulk!F11="BLD", 0.65*0.1, Semi_total_bulk!F11) -> 0.2 | G11: 50 | H11: 13 | I11: 224 | J11: =Semi_total_bulk!J11*10000 -> 31800 | K11: =IF(Semi_total_bulk!K11="BLD", 0.65*1, Semi_total_bulk!K11) -> 3 | L11: 1.9 | M11: 5.9 | N11: 76 | O11: =IF(Semi_total_bulk!O11="BLD", 0.65*0.1, Semi_total_bulk!O11) -> 0.065 | P11: 0.3 | Q11: =IF(Semi_total_bulk!Q11="BLD", 0.65*0.1, Semi_total_bulk!Q11) -> 0.4 | R11: 82 | S11: =Semi_total_bulk!S11*10000 -> 3900 | T11: =Semi_total_bulk!T11*10000 -> 290 | U11: 19.4 | V11: 321 | W11: =Semi_total_bulk!W11*10000 -> 10300 | X11: 1204 | Y11: =Semi_total_bulk!Y11*10000 -> 2300 | Z11: =Semi_total_bulk!Z11*10000 -> 60300 | AA11: =Semi_total_bulk!AA11*10000 -> 21030 | AB11: =Semi_total_bulk!AB11*10000 -> 28300 | AC11: 0.3 | AD11: 45.6 | AE11: 39 | AF11: 1.3 | AG11: 8.9 | AH11: 3.5 | AI11: 0.2 | AJ11: 9 | AK11: 16.7 | AL11: =IF(Semi_total_bulk!AM11="BLD",0.65*0.1,Semi_total_bulk!AM11)*10000 -> 2000 | AM11: 88.9 | AN11: 1.3 | AO11: =IF(Semi_total_bulk!AJ11="BLD", 0.65*0.1, Semi_total_bulk!AJ11) -> 0.065
A12: CAGE-22-1-HH-352-BC-A-10-11 | B12: 1.6 | C12: 670.9 | D12: 6.1 | E12: 30 | F12: =IF(Semi_total_bulk!F12="BLD", 0.65*0.1, Semi_total_bulk!F12) -> 0.1 | G12: 50.4 | H12: 11.9 | I12: 190 | J12: =Semi_total_bulk!J12*10000 -> 30600 | K12: =IF(Semi_total_bulk!K12="BLD", 0.65*1, Semi_total_bulk!K12) -> 3 | L12: 1.9 | M12: 6 | N12: 77 | O12: =IF(Semi_total_bulk!O12="BLD", 0.65*0.1, Semi_total_bulk!O12) -> 0.065 | P12: 0.2 | Q12: =IF(Semi_total_bulk!Q12="BLD", 0.65*0.1, Semi_total_bulk!Q12) -> 0.4 | R12: 81 | S12: =Semi_total_bulk!S12*10000 -> 3700 | T12: =Semi_total_bulk!T12*10000 -> 280 | U12: 19.6 | V12: 307 | W12: =Semi_total_bulk!W12*10000 -> 10000 | X12: 1274 | Y12: =Semi_total_bulk!Y12*10000 -> 2170 | Z12: =Semi_total_bulk!Z12*10000 -> 63800 | AA12: =Semi_total_bulk!AA12*10000 -> 21340 | AB12: =Semi_total_bulk!AB12*10000 -> 29300 | AC12: 0.3 | AD12: 46.6 | AE12: 39 | AF12: 1.4 | AG12: 8.6 | AH12: 3.4 | AI12: 0.2 | AJ12: 8 | AK12: 16.7 | AL12: =IF(Semi_total_bulk!AM12="BLD",0.65*0.1,Semi_total_bulk!AM12)*10000 -> 2000 | AM12: 92.7 | AN12: 1.3 | AO12: =IF(Semi_total_bulk!AJ12="BLD", 0.65*0.1, Semi_total_bulk!AJ12) -> 1
A13: CAGE-22-1-HH-352-BC-A-11-12 | B13: 1.1 | C13: 594.7 | D13: 4.1 | E13: 24 | F13: =IF(Semi_total_bulk!F13="BLD", 0.65*0.1, Semi_total_bulk!F13) -> 0.065 | G13: 50 | H13: 10.8 | I13: 165 | J13: =Semi_total_bulk!J13*10000 -> 29400 | K13: =IF(Semi_total_bulk!K13="BLD", 0.65*1, Semi_total_bulk!K13) -> 3 | L13: 1.7 | M13: 6.1 | N13: 67 | O13: =IF(Semi_total_bulk!O13="BLD", 0.65*0.1, Semi_total_bulk!O13) -> 0.065 | P13: 0.2 | Q13: =IF(Semi_total_bulk!Q13="BLD", 0.65*0.1, Semi_total_bulk!Q13) -> 0.4 | R13: 80 | S13: =Semi_total_bulk!S13*10000 -> 2200 | T13: =Semi_total_bulk!T13*10000 -> 250 | U13: 19.3 | V13: 309 | W13: =Semi_total_bulk!W13*10000 -> 9300 | X13: 1330 | Y13: =Semi_total_bulk!Y13*10000 -> 2000 | Z13: =Semi_total_bulk!Z13*10000 -> 62700 | AA13: =Semi_total_bulk!AA13*10000 -> 20980 | AB13: =Semi_total_bulk!AB13*10000 -> 29400 | AC13: 0.3 | AD13: 46 | AE13: 38 | AF13: 1.5 | AG13: 7.7 | AH13: 2.8 | AI13: 0.1 | AJ13: 8 | AK13: 15.5 | AL13: =IF(Semi_total_bulk!AM13="BLD",0.65*0.1,Semi_total_bulk!AM13)*10000 -> 1000 | AM13: 92.3 | AN13: 1.3 | AO13: =IF(Semi_total_bulk!AJ13="BLD", 0.65*0.1, Semi_total_bulk!AJ13) -> 1
... A92: CAGE-22-1-HH-334-MC-B-40-40,5 | B92: 1.1 | C92: 16 | D92: 10.2 | E92: 27 | F92: =IF(Semi_total_bulk!F92="BLD", 0.65*0.1, Semi_total_bulk!F92) -> 0.065 | G92: 21.3 | H92: 7.1 | I92: 269 | J92: =Semi_total_bulk!J92*10000 -> 19100 | K92: =IF(Semi_total_bulk!K92="BLD", 0.65*1, Semi_total_bulk!K92) -> 3 | L92: 1.9 | M92: 5 | N92: 170 | O92: =IF(Semi_total_bulk!O92="BLD", 0.65*0.1, Semi_total_bulk!O92) -> 0.065 | P92: 0.2 | Q92: =IF(Semi_total_bulk!Q92="BLD", 0.65*0.1, Semi_total_bulk!Q92) -> 0.065 | R92: 54 | S92: =Semi_total_bulk!S92*10000 -> 12500 | T92: =Semi_total_bulk!T92*10000 -> 440 | U92: 23 | V92: 58 | W92: =Semi_total_bulk!W92*10000 -> 6800 | X92: 379 | Y92: =Semi_total_bulk!Y92*10000 -> 3130 | Z92: =Semi_total_bulk!Z92*10000 -> 45200 | AA92: =Semi_total_bulk!AA92*10000 -> 19470 | AB92: =Semi_total_bulk!AB92*10000 -> 14400 | AC92: 0.4 | AD92: 56.5 | AE92: 45 | AF92: 1.1 | AG92: 16.7 | AH92: 7.4 | AI92: 0.5 | AJ92: 8 | AK92: 12.6 | AL92: =IF(Semi_total_bulk!AM92="BLD",0.65*0.1,Semi_total_bulk!AM92)*10000 -> 2000 | AM92: 52.2 | AN92: 1.6 | AO92: =IF(Semi_total_bulk!AJ92="BLD", 0.65*0.1, Semi_total_bulk!AJ92) -> 1

Sheet PCA_TAIL_NE
A1: Sample | B1: Type.of.sediment | C1: O2.zone | D1: Mo | E1: Cu | F1: Pb | G1: Zn | H1: Ag | I1: Ni | J1: Co | K1: Mn | L1: As | M1: Sr | N1: Sb | O1: Bi | P1: Ca | Q1: Cr | R1: Al | S1: K | T1: Sc | U1: TOC | V1: TN | W1: TOC_TN | X1: CORE name | Y1: Sample ID
A2: 0-1 | B2: sediment | C2: Fe-Mn reduction zone | D2: 0.7 | E2: 150.2 | F2: 14.7 | G2: 47 | H2: =IF(Semi_total_bulk!F2="BLD", 0.65*0.1, Semi_total_bulk!F2) -> 0.1 | I2: 30.9 | J2: 10 | K2: 308 | L2: =IF(Semi_total_bulk!K2="BLD", 0.65*1, Semi_total_bulk!K2) -> 7 | M2: 170 | N2: 0.3 | O2: =IF(Semi_total_bulk!Q2="BLD", 0.65*0.1, Semi_total_bulk!Q2) -> 0.2 | P2: =Semi_total_bulk!S2*10000 -> 13600 | Q2: 110 | R2: =Semi_total_bulk!Z2*10000 -> 51600 | S2: =Semi_total_bulk!AB2*10000 -> 18600 | T2: 9 | U2: 0.2130086 | V2: 1.5581344 | W2: 7.3148899 | X2: HH-352 | Y2: CAGE-22-1-HH-352-BC-A-0-1
