Workbook

Sheet REZULTATI
A1: izraženo u μg/L
B2: Al | C2: As | D2: Ba | E2: Be | F2: Ca | G2: Cd | H2: Co | I2: Cr | J2: Cu | K2: Fe | L2: Ga | M2: Ge | N2: K | O2: Li | P2: Mg | Q2: Mn | R2: Mo | S2: Ni | T2: Nb | U2: Pb | V2: Rb | W2: Sb | X2: Sc | Y2: Se | Z2: Sn | AA2: Sr | AB2: Ti | AC2: Th | AD2: U | AE2: V | AF2: W | AG2: Y | AH2: Zn | AJ2: La | AK2: Ce | AL2: Pr | AM2: Nd | AN2: Sm | AO2: Eu | AP2: Gd | AQ2: Tb | AR2: Dy | AS2: Ho | AT2: Er | AU2: Tm | AV2: Yb | AW2: Lu
A3: Blank_1_100x | B3: 0.411 | C3: <LOD | D3: 0.019 | E3: <LOD | F3: <LOD | G3: <LOD | H3: <LOD | I3: <LOD | J3: 0.013 | K3: 0.363 | L3: <0.000 | M3: 0.008 | N3: 81.388 | O3: <LOD | P3: 0.64 | Q3: 0.011 | R3: <LOD | S3: 0.032 | T3: <0.000 | U3: 0.01 | V3: 0.004 | W3: <LOD | X3: <LOD | Y3: <LOD | Z3: 0.009 | AA3: 0.008 | AB3: 0.019 | AC3: 0 | AD3: <LOD | AE3: <LOD | AF3: 0.001 | AG3: <LOD | AH3: 0.131 | AJ3: <0.000 | AK3: <0.000 | AL3: 0 | AM3: 0.001 | AN3: 0 | AO3: 0 | AP3: 0 | AQ3: 0 | AR3: 0 | AS3: 0 | AT3: 0 | AU3: 0 | AV3: 0 | AW3: 0
A4: J001_1_100x | B4: 1.219 | C4: 0.101 | D4: 0.101 | E4: <LOD | F4: <LOD | G4: <LOD | H4: 0.004 | I4: <LOD | J4: 0.04 | K4: 1.359 | L4: 0 | M4: <0.000 | N4: 65.435 | O4: <LOD | P4: 4.908 | Q4: 1.118 | R4: 0.014 | S4: 0.046 | T4: <0.000 | U4: 0.007 | V4: 0.007 | W4: <LOD | X4: <LOD | Y4: 0.014 | Z4: 0.008 | AA4: 0.038 | AB4: 0.009 | AC4: 0 | AD4: 0.007 | AE4: 0.057 | AF4: 0.001 | AG4: 0.005 | AH4: 0.201 | AJ4: <0.000 | AK4: 0 | AL4: 0.001 | AM4: 0.004 | AN4: 0.002 | AO4: 0 | AP4: 0.001 | AQ4: 0 | AR4: 0.001 | AS4: 0 | AT4: 0 | AU4: 0 | AV4: 0 | AW4: 0
A5: J002_1_100x | B5: 0.563 | C5: 0.008 | D5: 0.074 | E5: <LOD | F5: <LOD | G5: <LOD | H5: <LOD | I5: <LOD | J5: 1.224 | K5: 2.349 | L5: <0.000 | M5: <0.000 | N5: 70.416 | O5: <LOD | P5: 6.63 | Q5: 0.096 | R5: 0.136 | S5: 0.031 | T5: <0.000 | U5: 0.009 | V5: 0.007 | W5: <LOD | X5: <LOD | Y5: 0.005 | Z5: 0.009 | AA5: 0.026 | AB5: 0.009 | AC5: 0 | AD5: <LOD | AE5: <LOD | AF5: 0.001 | AG5: 0.001 | AH5: 1.754 | AJ5: <0.000 | AK5: <0.000 | AL5: 0 | AM5: 0 | AN5: 0 | AO5: 0 | AP5: 0 | AQ5: 0 | AR5: 0 | AS5: 0 | AT5: 0 | AU5: 0 | AV5: 0 | AW5: 0
A6: J003_1_100x | B6: <LOD | C6: 0.031 | D6: 0.04 | E6: <LOD | F6: <LOD | G6: <LOD | H6: <LOD | I6: <LOD | J6: 0.035 | K6: 0.256 | L6: <0.000 | M6: <0.000 | N6: 64.535 | O6: <LOD | P6: 3.083 | Q6: 0.241 | R6: 0.004 | S6: 0.027 | T6: <0.000 | U6: 0.006 | V6: 0.006 | W6: <LOD | X6: <LOD | Y6: 0.005 | Z6: 0.006 | AA6: 0.019 | AB6: <LOD | AC6: 0 | AD6: 0.003 | AE6: 0.023 | AF6: 0.001 | AG6: 0.001 | AH6: 0.029 | AJ6: <0.000 | AK6: <0.000 | AL6: 0 | AM6: 0.001 | AN6: 0 | AO6: 0 | AP6: 0 | AQ6: 0 | AR6: 0 | AS6: 0 | AT6: 0 | AU6: 0 | AV6: 0 | AW6: 0
A7: J007_1_100x | B7: 0.283 | C7: 0.084 | D7: 0.11 | E7: <LOD | F7: <LOD | G7: 0.001 | H7: 0.002 | I7: <LOD | J7: 0.108 | K7: 0.533 | L7: 0 | M7: 0 | N7: 63.488 | O7: <LOD | P7: 4.883 | Q7: 0.809 | R7: 0.009 | S7: 0.034 | T7: 0 | U7: 0.012 | V7: 0.007 | W7: <LOD | X7: <LOD | Y7: 0.017 | Z7: 0.005 | AA7: 0.046 | AB7: 0.019 | AC7: 0 | AD7: 0.003 | AE7: 0.041 | AF7: 0.001 | AG7: 0.002 | AH7: <LOD | AJ7: <0.000 | AK7: <0.000 | AL7: 0 | AM7: 0.001 | AN7: 0 | AO7: 0 | AP7: 0 | AQ7: 0 | AR7: 0 | AS7: 0 | AT7: 0 | AU7: 0 | AV7: 0 | AW7: 0
A8: J010_1_100x | B8: <LOD | C8: 0.019 | D8: 0.04 | E8: <LOD | F8: <LOD | G8: <LOD | H8: <LOD | I8: <LOD | J8: 0.001 | K8: 0.337 | L8: <0.000 | M8: <0.000 | N8: 15.45 | O8: <LOD | P8: 1.32 | Q8: 0.475 | R8: 0.003 | S8: 0.008 | T8: <0.000 | U8: 0.002 | V8: 0.003 | W8: <LOD | X8: <LOD | Y8: 0.006 | Z8: 0.001 | AA8: 0.016 | AB8: <LOD | AC8: 0 | AD8: 0.001 | AE8: 0.058 | AF8: 0 | AG8: 0.006 | AH8: <LOD | AJ8: <0.000 | AK8: 0.003 | AL8: 0.001 | AM8: 0.004 | AN8: 0.001 | AO8: 0 | AP8: 0.001 | AQ8: 0 | AR8: 0.001 | AS8: 0 | AT8: 0 | AU8: 0 | AV8: 0 | AW8: 0
A9: J016a_1_100x | B9: 0.402 | C9: 0.016 | D9: 0.139 | E9: <LOD | F9: <LOD | G9: <LOD | H9: <LOD | I9: <LOD | J9: 0.115 | K9: 0.391 | L9: 0 | M9: <0.000 | N9: 67.701 | O9: <LOD | P9: 8.213 | Q9: 0.139 | R9: 0.013 | S9: 0.029 | T9: <0.000 | U9: 0.006 | V9: 0.006 | W9: <LOD | X9: <LOD | Y9: 0.007 | Z9: 0.01 | AA9: 0.083 | AB9: 0.01 | AC9: 0 | AD9: 0.001 | AE9: 0.001 | AF9: 0.001 | AG9: 0.002 | AH9: <LOD | AJ9: <0.000 | AK9: <0.000 | AL9: 0 | AM9: 0.001 | AN9: 0.001 | AO9: 0 | AP9: 0 | AQ9: 0 | AR9: 0 | AS9: 0 | AT9: 0 | AU9: 0 | AV9: 0 | AW9: 0
A10: J016b_1_100x | B10: 0.657 | C10: 0.025 | D10: 0.242 | E10: <LOD | F10: <LOD | G10: <LOD | H10: <LOD | I10: <LOD | J10: 0.143 | K10: 0.559 | L10: 0 | M10: 0.002 | N10: 67.638 | O10: <LOD | P10: 9.679 | Q10: 0.153 | R10: 0.017 | S10: 0.043 | T10: <0.000 | U10: 0.01 | V10: 0.005 | W10: <LOD | X10: <LOD | Y10: 0.01 | Z10: 0.009 | AA10: 0.105 | AB10: 0.027 | AC10: 0 | AD10: 0.001 | AE10: 0.001 | AF10: 0.001 | AG10: 0.003 | AH10: 0.827 | AJ10: <0.000 | AK10: <0.000 | AL10: 0 | AM10: 0.002 | AN10: 0.001 | AO10: 0 | AP10: 0 | AQ10: 0 | AR10: 0 | AS10: 0 | AT10: 0 | AU10: 0 | AV10: 0 | AW10: 0
A11: J016c_1_100x | B11: 0.289 | C11: 0.017 | D11: 0.206 | E11: <LOD | F11: <LOD | G11: <LOD | H11: <LOD | I11: <LOD | J11: 0.126 | K11: 1.331 | L11: 0 | M11: <0.000 | N11: 66.56 | O11: <LOD | P11: 8.493 | Q11: 0.126 | R11: 0.014 | S11: 0.029 | T11: <0.000 | U11: 0.006 | V11: 0.006 | W11: <LOD | X11: <LOD | Y11: 0.008 | Z11: 0.004 | AA11: 0.091 | AB11: 0.003 | AC11: 0 | AD11: 0.001 | AE11: <LOD | AF11: 0.001 | AG11: 0.002 | AH11: <LOD | AJ11: <0.000 | AK11: <0.000 | AL11: 0 | AM11: 0.001 | AN11: 0.001 | AO11: 0 | AP11: 0 | AQ11: 0 | AR11: 0.001 | AS11: 0 | AT11: 0 | AU11: 0 | AV11: 0 | AW11: 0
A12: J018_1_100x | B12: 0.253 | C12: 0.004 | D12: 0.017 | E12: <LOD | F12: <LOD | G12: <LOD | H12: <LOD | I12: <LOD | J12: 0.033 | K12: 0.24 | L12: <0.000 | M12: 0.001 | N12: 62.584 | O12: <LOD | P12: 0.691 | Q12: 0.019 | R12: <LOD | S12: 0.019 | T12: <0.000 | U12: 0.008 | V12: 0.004 | W12: <LOD | X12: <LOD | Y12: <LOD | Z12: 0.005 | AA12: 0.011 | AB12: 0.002 | AC12: 0 | AD12: <LOD | AE12: <LOD | AF12: 0 | AG12: <LOD | AH12: <LOD | AJ12: <0.000 | AK12: <0.000 | AL12: 0 | AM12: 0 | AN12: 0 | AO12: 0 | AP12: 0 | AQ12: 0 | AR12: 0 | AS12: 0 | AT12: 0 | AU12: 0 | AV12: 0 | AW12: 0
A13: J019_1_100x | B13: <LOD | C13: 0.001 | D13: 0.023 | E13: <LOD | F13: <LOD | G13: <LOD | H13: <LOD | I13: <LOD | J13: 0.006 | K13: 0.287 | L13: <0.000 | M13: 0.001 | N13: 63.644 | O13: <LOD | P13: 0.607 | Q13: 0.143 | R13: <LOD | S13: 0.019 | T13: <0.000 | U13: 0.006 | V13: 0.004 | W13: <LOD | X13: <LOD | Y13: 0.001 | Z13: 0.003 | AA13: 0.009 | AB13: <LOD | AC13: 0 | AD13: <LOD | AE13: <LOD | AF13: 0 | AG13: <LOD | AH13: <LOD | AJ13: <0.000 | AK13: <0.000 | AL13: 0 | AM13: 0 | AN13: 0 | AO13: 0 | AP13: 0 | AQ13: 0 | AR13: 0 | AS13: 0 | AT13: 0 | AU13: 0 | AV13: 0 | AW13: 0
A14: J024_1_100x | B14: 0.166 | C14: 0.077 | D14: 0.069 | E14: <LOD | F14: <LOD | G14: <LOD | H14: 0.002 | I14: <LOD | J14: 0.085 | K14: 0.372 | L14: 0 | M14: 0 | N14: 66.918 | O14: <LOD | P14: 3.794 | Q14: 1.486 | R14: 0.009 | S14: 0.036 | T14: <0.000 | U14: 0.006 | V14: 0.009 | W14: 0.001 | X14: <LOD | Y14: 0.019 | Z14: 0.005 | AA14: 0.03 | AB14: <LOD | AC14: 0 | AD14: 0.001 | AE14: 0.164 | AF14: 0.001 | AG14: 0.001 | AH14: 0.015 | AJ14: <0.000 | AK14: <0.000 | AL14: 0 | AM14: 0.001 | AN14: 0 | AO14: 0 | AP14: 0 | AQ14: 0 | AR14: 0 | AS14: 0 | AT14: 0 | AU14: 0 | AV14: 0 | AW14: 0
A15: J028_1_100x | B15: 0.721 | C15: 0.021 | D15: 0.117 | E15: <LOD | F15: <LOD | G15: <LOD | H15: <LOD | I15: 0.068 | J15: 0.026 | K15: 0.399 | L15: 0 | M15: <0.000 | N15: 62.474 | O15: <LOD | P15: 4.156 | Q15: 0.928 | R15: 0.007 | S15: 0.024 | T15: <0.000 | U15: 0.006 | V15: 0.005 | W15: <LOD | X15: <LOD | Y15: 0.007 | Z15: 0.005 | AA15: 0.055 | AB15: <LOD | AC15: 0 | AD15: 0.001 | AE15: 0.031 | AF15: 0.006 | AG15: 0.001 | AH15: <LOD | AJ15: <0.000 | AK15: <0.000 | AL15: 0 | AM15: 0.001 | AN15: 0 | AO15: 0 | AP15: 0 | AQ15: 0 | AR15: 0 | AS15: 0 | AT15: 0 | AU15: 0 | AV15: 0 | AW15: 0
A16: J033_1_100x | B16: 0.055 | C16: 0.077 | D16: 0.1 | E16: <LOD | F16: <LOD | G16: 0.001 | H16: 0.003 | I16: 0.043 | J16: 0.085 | K16: 0.471 | L16: 0 | M16: 0 | N16: 65.53 | O16: <LOD | P16: 3.418 | Q16: 1.723 | R16: 0.014 | S16: 0.039 | T16: <0.000 | U16: 0.007 | V16: 0.009 | W16: 0.001 | X16: <LOD | Y16: 0.023 | Z16: 0.004 | AA16: 0.033 | AB16: 0.01 | AC16: 0 | AD16: 0.002 | AE16: 0.236 | AF16: 0.001 | AG16: 0.001 | AH16: 0.007 | AJ16: <0.000 | AK16: <0.000 | AL16: 0 | AM16: 0.001 | AN16: 0 | AO16: 0 | AP16: 0 | AQ16: 0 | AR16: 0 | AS16: 0 | AT16: 0 | AU16: 0 | AV16: 0 | AW16: 0
A17: J039_1_100x | B17: 0.843 | C17: 0.011 | D17: 0.182 | E17: <LOD | F17: <LOD | G17: <LOD | H17: 0.001 | I17: <LOD | J17: 0.302 | K17: 0.456 | L17: 0 | M17: <0.000 | N17: 64.51 | O17: <LOD | P17: 4.296 | Q17: 1.104 | R17: 0.005 | S17: 0.039 | T17: <0.000 | U17: 0.008 | V17: 0.006 | W17: <LOD | X17: <LOD | Y17: 0.015 | Z17: 0.007 | AA17: 0.049 | AB17: <LOD | AC17: 0 | AD17: 0.001 | AE17: 0.063 | AF17: 0.002 | AG17: 0.002 | AH17: 0.22 | AJ17: <0.000 | AK17: <0.000 | AL17: 0 | AM17: 0.001 | AN17: 0 | AO17: 0 | AP17: 0 | AQ17: 0 | AR17: 0 | AS17: 0 | AT17: 0 | AU17: 0 | AV17: 0 | AW17: 0
A18: J041_1_100x | B18: 0.334 | C18: 0.012 | D18: 0.219 | E18: <LOD | F18: <LOD | G18: <LOD | H18: 0.002 | I18: <LOD | J18: 0.274 | K18: 0.592 | L18: <0.000 | M18: <0.000 | N18: 66.169 | O18: <LOD | P18: 8.253 | Q18: 1.999 | R18: 0.021 | S18: 0.042 | T18: <0.000 | U18: 0.006 | V18: 0.009 | W18: <LOD | X18: <LOD | Y18: 0.016 | Z18: 0.002 | AA18: 0.096 | AB18: <LOD | AC18: 0 | AD18: 0.002 | AE18: 0.003 | AF18: 0.002 | AG18: 0.003 | AH18: <LOD | AJ18: <0.000 | AK18: <0.000 | AL18: 0 | AM18: 0.002 | AN18: 0 | AO18: 0 | AP18: 0.001 | AQ18: 0 | AR18: 0 | AS18: 0 | AT18: 0 | AU18: 0 | AV18: 0 | AW18: 0
A19: J043_1_100x | B19: 1.634 | C19: 0.008 | D19: 0.058 | E19: <LOD | F19: <LOD | G19: <LOD | H19: <LOD | I19: 0.008 | J19: 0.066 | K19: 0.361 | L19: 0 | M19: <0.000 | N19: 65.192 | O19: <LOD | P19: 2.366 | Q19: 0.079 | R19: 0.002 | S19: 0.038 | T19: <0.000 | U19: 0.017 | V19: 0.004 | W19: <LOD | X19: <LOD | Y19: 0.002 | Z19: 0.008 | AA19: 0.029 | AB19: 0.1 | AC19: 0 | AD19: 0.003 | AE19: 0.005 | AF19: 0.001 | AG19: 0.002 | AH19: 0.868 | AJ19: <0.000 | AK19: <0.000 | AL19: 0.001 | AM19: 0.002 | AN19: 0 | AO19: 0 | AP19: 0 | AQ19: 0 | AR19: 0 | AS19: 0 | AT19: 0 | AU19: 0 | AV19: 0 | AW19: 0
A21: Blank_2_100x | B21: 1.539 | C21: 0.004 | D21: 0.057 | E21: <LOD | F21: <LOD | G21: <LOD | H21: <LOD | I21: 0.005 | J21: 0.253 | K21: 1.161 | L21: 0 | M21: <0.000 | N21: 32.203 | O21: <LOD | P21: 1.111 | Q21: 0.026 | R21: 0.001 | S21: 0.135 | T21: <0.000 | U21: 0.166 | V21: 0.004 | W21: <LOD | X21: 0.006 | Y21: <LOD | Z21: 0.011 | AA21: 0.011 | AB21: 0.134 | AC21: 0 | AD21: <LOD | AE21: <LOD | AF21: 0 | AG21: <LOD | AH21: 1.918 | AJ21: <0.000 | AK21: <0.000 | AL21: 0 | AM21: 0 | AN21: 0 | AO21: 0 | AP21: 0 | AQ21: 0 | AR21: 0 | AS21: 0 | AT21: 0 | AU21: 0 | AV21: 0 | AW21: 0
A22: J001_2_100x | B22: 17.837 | C22: 0.376 | D22: 37.817 | E22: 0.016 | F22: 430.831 | G22: 0.016 | H22: 0.297 | I22: 0.042 | J22: 0.605 | K22: 69.38 | L22: 0.003 | M22: 0.007 | N22: 49.783 | O22: <LOD | P22: 107.653 | Q22: 63.83 | R22: 0.005 | S22: 0.54 | T22: <0.000 | U22: 0.411 | V22: 0.071 | W22: <LOD | X22: 0.006 | Y22: 0.019 | Z22: 0.017 | AA22: 1.923 | AB22: 0.22 | AC22: 0.003 | AD22: 1.033 | AE22: 0.063 | AF22: 0.001 | AG22: 0.158 | AH22: 3.214 | AJ22: 0.033 | AK22: 0.097 | AL22: 0.024 | AM22: 0.128 | AN22: 0.033 | AO22: 0.02 | AP22: 0.031 | AQ22: 0.006 | AR22: 0.026 | AS22: 0.005 | AT22: 0.013 | AU22: 0.001 | AV22: 0.008 | AW22: 0.001
A23: J002_2_100x | B23: 15.531 | C23: 0.036 | D23: 29.192 | E23: 0.006 | F23: 606.024 | G23: 0.023 | H23: 0.046 | I23: 0.065 | J23: 1689.476 | K23: 74.437 | L23: 0.002 | M23: 0.004 | N23: 32.677 | O23: 0.006 | P23: 139.046 | Q23: 50.248 | R23: 0.014 | S23: 0.252 | T23: 0 | U23: 0.307 | V23: 0.029 | W23: 0.002 | X23: 0.048 | Y23: 0.017 | Z23: 0.018 | AA23: 0.808 | AB23: 0.009 | AC23: 0.008 | AD23: 0.14 | AE23: <LOD | AF23: 0.001 | AG23: 0.511 | AH23: 1.916 | AJ23: 0.049 | AK23: 0.068 | AL23: 0.024 | AM23: 0.115 | AN23: 0.046 | AO23: 0.027 | AP23: 0.056 | AQ23: 0.013 | AR23: 0.083 | AS23: 0.016 | AT23: 0.04 | AU23: 0.005 | AV23: 0.029 | AW23: 0.004
A24: J003_2_100x | B24: 9.777 | C24: 0.061 | D24: 27.768 | E24: 0.01 | F24: 388.946 | G24: 0.008 | H24: 0.089 | I24: 0.016 | J24: 0.632 | K24: 1.196 | L24: 0.001 | M24: <0.000 | N24: 35.318 | O24: <LOD | P24: 88.273 | Q24: 22.236 | R24: <LOD | S24: 0.309 | T24: <0.000 | U24: 0.143 | V24: 0.087 | W24: <LOD | X24: 0.008 | Y24: 0.003 | Z24: 0.008 | AA24: 1.145 | AB24: 0.002 | AC24: 0.002 | AD24: 0.596 | AE24: 0.007 | AF24: 0.001 | AG24: 0.075 | AH24: 0.429 | AJ24: <0.000 | AK24: 0.036 | AL24: 0.008 | AM24: 0.04 | AN24: 0.014 | AO24: 0.011 | AP24: 0.013 | AQ24: 0.002 | AR24: 0.012 | AS24: 0.002 | AT24: 0.005 | AU24: 0.001 | AV24: 0.003 | AW24: 0.001
A25: J007_2_100x | B25: 8.108 | C25: 0.164 | D25: 37.302 | E25: 0.009 | F25: 489.238 | G25: 0.031 | H25: 0.212 | I25: 0.042 | J25: 1.351 | K25: 2.701 | L25: 0.001 | M25: <0.000 | N25: 41.703 | O25: 0.001 | P25: 112.623 | Q25: 59.326 | R25: <LOD | S25: 0.538 | T25: <0.000 | U25: 0.447 | V25: 0.107 | W25: <LOD | X25: 0.007 | Y25: 0.012 | Z25: 0.009 | AA25: 2.185 | AB25: 0.02 | AC25: 0.002 | AD25: 0.615 | AE25: 0.013 | AF25: 0.001 | AG25: 0.067 | AH25: 1.552 | AJ25: <0.000 | AK25: 0.042 | AL25: 0.01 | AM25: 0.052 | AN25: 0.014 | AO25: 0.014 | AP25: 0.014 | AQ25: 0.002 | AR25: 0.012 | AS25: 0.002 | AT25: 0.005 | AU25: 0.001 | AV25: 0.003 | AW25: 0
A26: J0010_2_100x | B26: 7.935 | C26: 0.061 | D26: 12.688 | E26: 0.004 | F26: 300.463 | G26: 0.013 | H26: 0.125 | I26: 0.021 | J26: 0.456 | K26: 4.028 | L26: 0.001 | M26: <0.000 | N26: 38.438 | O26: <LOD | P26: 50.149 | Q26: 36.804 | R26: 0.001 | S26: 0.251 | T26: <0.000 | U26: 0.325 | V26: 0.044 | W26: <LOD | X26: 0.004 | Y26: 0.008 | Z26: 0.009 | AA26: 0.964 | AB26: 0.072 | AC26: 0.002 | AD26: 0.211 | AE26: 0.034 | AF26: 0 | AG26: 0.03 | AH26: 0.659 | AJ26: <0.000 | AK26: 0.02 | AL26: 0.004 | AM26: 0.023 | AN26: 0.006 | AO26: 0.005 | AP26: 0.006 | AQ26: 0.001 | AR26: 0.006 | AS26: 0.001 | AT26: 0.002 | AU26: 0 | AV26: 0.002 | AW26: 0
A27: J0016a_2_100x | B27: 23.075 | C27: 0.056 | D27: 103.167 | E27: 0.015 | F27: 2213.549 | G27: 0.046 | H27: 0.03 | I27: 0.039 | J27: 1.326 | K27: 3.298 | L27: 0.006 | M27: 0.006 | N27: 43.021 | O27: 0.023 | P27: 303.574 | Q27: 239.259 | R27: 0.001 | S27: 0.639 | T27: <0.000 | U27: 0.023 | V27: 0.014 | W27: <LOD | X27: 0.021 | Y27: 0.019 | Z27: 0.015 | AA27: 8.036 | AB27: 0.012 | AC27: 0.005 | AD27: 0.64 | AE27: 0.004 | AF27: 0.001 | AG27: 0.392 | AH27: 4.68 | AJ27: 0.211 | AK27: 0.218 | AL27: 0.053 | AM27: 0.247 | AN27: 0.066 | AO27: 0.047 | AP27: 0.064 | AQ27: 0.011 | AR27: 0.055 | AS27: 0.01 | AT27: 0.022 | AU27: 0.002 | AV27: 0.015 | AW27: 0.002
A28: J0016b_2_100x | B28: 16.113 | C28: 0.071 | D28: 96.446 | E28: 0.011 | F28: 2167.765 | G28: 0.041 | H28: 0.036 | I28: 0.021 | J28: 1.422 | K28: 2.3 | L28: 0.005 | M28: 0.004 | N28: 42.802 | O28: 0.018 | P28: 288.968 | Q28: 162.717 | R28: <LOD | S28: 0.456 | T28: <0.000 | U28: 0.023 | V28: 0.017 | W28: <LOD | X28: 0.019 | Y28: 0.014 | Z28: 0.01 | AA28: 8.087 | AB28: <LOD | AC28: 0.004 | AD28: 0.513 | AE28: 0.003 | AF28: 0.001 | AG28: 0.347 | AH28: 3.161 | AJ28: 0.186 | AK28: 0.193 | AL28: 0.047 | AM28: 0.221 | AN28: 0.063 | AO28: 0.042 | AP28: 0.059 | AQ28: 0.009 | AR28: 0.049 | AS28: 0.009 | AT28: 0.021 | AU28: 0.003 | AV28: 0.015 | AW28: 0.002
A29: J016c_2_100x | B29: 13.242 | C29: 0.069 | D29: 99.969 | E29: 0.009 | F29: 2192.937 | G29: 0.039 | H29: 0.029 | I29: 0.028 | J29: 1.333 | K29: 1.973 | L29: 0.002 | M29: <0.000 | N29: 28.903 | O29: 0.009 | P29: 254.515 | Q29: 151.997 | R29: <LOD | S29: 0.455 | T29: <0.000 | U29: 0.027 | V29: 0.018 | W29: <LOD | X29: 0.014 | Y29: 0.015 | Z29: 0.011 | AA29: 7.964 | AB29: <LOD | AC29: 0.005 | AD29: 0.006 | AE29: 0.003 | AF29: 0.002 | AG29: 0.358 | AH29: 3.306 | AJ29: 0.193 | AK29: 0.202 | AL29: 0.05 | AM29: 0.234 | AN29: 0.065 | AO29: 0.039 | AP29: 0.061 | AQ29: 0.01 | AR29: 0.051 | AS29: 7.2 | AT29: 0.021 | AU29: 0.002 | AV29: 0.013 | AW29: 0.002
A30: J018_2_100x | B30: 18.138 | C30: 0.021 | D30: 4.236 | E30: 0.004 | F30: 443.06 | G30: 0.008 | H30: 0.024 | I30: 0.047 | J30: 2.98 | K30: 23.294 | L30: 0.002 | M30: <0.000 | N30: 20.392 | O30: <LOD | P30: 31.063 | Q30: 8.13 | R30: 0.003 | S30: 0.117 | T30: 0 | U30: 0.168 | V30: 0.021 | W30: <LOD | X30: 0.02 | Y30: 0.002 | Z30: 0.014 | AA30: 0.463 | AB30: 0.281 | AC30: 0.005 | AD30: 0.006 | AE30: 0.019 | AF30: 0.001 | AG30: 0.074 | AH30: 0.981 | AJ30: 0.017 | AK30: 0.06 | AL30: 0.012 | AM30: 0.05 | AN30: 0.013 | AO30: 0.005 | AP30: 0.011 | AQ30: 0.002 | AR30: 0.012 | AS30: 11.5 | AT30: 0.007 | AU30: 0.001 | AV30: 0.004 | AW30: 0.001
A31: J019_2_100x | B31: 4.947 | C31: 0.007 | D31: 4.305 | E31: 0.002 | F31: 52.163 | G31: 0.002 | H31: 0.009 | I31: 0.019 | J31: 0.395 | K31: 3.437 | L31: 0.002 | M31: <0.000 | N31: 19.381 | O31: <LOD | P31: 6.335 | Q31: 6.463 | R31: <LOD | S31: 0.03 | T31: 0 | U31: 0.179 | V31: 0.016 | W31: <LOD | X31: <LOD | Y31: 0.001 | Z31: 0.016 | AA31: 0.131 | AB31: 0.016 | AC31: 0.008 | AD31: 0.008 | AE31: 0.002 | AF31: 0 | AG31: 0.035 | AH31: 0.393 | AJ31: <0.000 | AK31: 0.109 | AL31: 0.007 | AM31: 0.027 | AN31: 0.006 | AO31: 0.002 | AP31: 0.006 | AQ31: 0.001 | AR31: 0.006 | AS31: 10.1 | AT31: 0.003 | AU31: 0 | AV31: 0.002 | AW31: 0
A32: J024_2_100x | B32: 13.687 | C32: 0.285 | D32: 17.599 | E32: 0.005 | F32: 436.191 | G32: 0.102 | H32: 0.27 | I32: 0.068 | J32: 1.678 | K32: 3.157 | L32: 0.002 | M32: <0.000 | N32: 32.84 | O32: <LOD | P32: 47.973 | Q32: 97.414 | R32: <LOD | S32: 0.876 | T32: <0.000 | U32: 0.561 | V32: 0.059 | W32: 0.006 | X32: 0.011 | Y32: 0.018 | Z32: 0.012 | AA32: 0.821 | AB32: 0.048 | AC32: 0.007 | AD32: 0.007 | AE32: 0.053 | AF32: 0.001 | AG32: 0.11 | AH32: 2.035 | AJ32: 0.028 | AK32: 0.124 | AL32: 0.016 | AM32: 0.079 | AN32: 0.021 | AO32: 0.009 | AP32: 0.02 | AQ32: 0.004 | AR32: 0.021 | AS32: 9 | AT32: 0.01 | AU32: 0.001 | AV32: 0.007 | AW32: 0.001
A33: J028_2_100x | B33: 11.468 | C33: 0.075 | D33: 26.366 | E33: 0.003 | F33: 359.588 | G33: 0.014 | H33: 0.094 | I33: 0.045 | J33: 0.607 | K33: 1.944 | L33: 0.002 | M33: <0.000 | N33: 23.037 | O33: <LOD | P33: 54.534 | Q33: 62.026 | R33: <LOD | S33: 0.225 | T33: 0 | U33: 0.299 | V33: 0.025 | W33: <LOD | X33: 0.002 | Y33: 0.008 | Z33: 0.01 | AA33: 1.639 | AB33: 0.015 | AC33: 0.009 | AD33: 0.008 | AE33: 0.01 | AF33: 0.001 | AG33: 0.09 | AH33: 1.14 | AJ33: 0.016 | AK33: 0.128 | AL33: 0.012 | AM33: 0.056 | AN33: 0.015 | AO33: 0.009 | AP33: 0.015 | AQ33: 0.003 | AR33: 0.017 | AS33: 16.7 | AT33: 0.008 | AU33: 0.001 | AV33: 0.006 | AW33: 0.001
A34: J033_2_100x | B34: 11.747 | C34: 0.207 | D34: 17.285 | E34: 0.003 | F34: 468.932 | G34: 0.115 | H34: 0.269 | I34: 0.069 | J34: 2.719 | K34: 3.84 | L34: 0.002 | M34: <0.000 | N34: 31.925 | O34: <LOD | P34: 41.865 | Q34: 104.569 | R34: 0.001 | S34: 0.959 | T34: <0.000 | U34: 0.489 | V34: 0.052 | W34: 0.006 | X34: 0.007 | Y34: 0.022 | Z34: 0.009 | AA34: 0.938 | AB34: 0.038 | AC34: 0.006 | AD34: 0.006 | AE34: 0.061 | AF34: 0.001 | AG34: 0.085 | AH34: 2.022 | AJ34: 0.017 | AK34: 0.094 | AL34: 0.012 | AM34: 0.06 | AN34: 0.02 | AO34: 0.008 | AP34: 0.017 | AQ34: 0.003 | AR34: 0.016 | AS34: 4.3 | AT34: 0.008 | AU34: 0.001 | AV34: 0.005 | AW34: 0.001
A35: J039_2_100x | B35: 17.379 | C35: 0.059 | D35: 27.974 | E35: 0.004 | F35: 843.267 | G35: 0.056 | H35: 0.361 | I35: 0.057 | J35: 21.57 | K35: 3.823 | L35: 0.003 | M35: <0.000 | N35: 23.755 | O35: <LOD | P35: 61.998 | Q35: 106.049 | R35: <LOD | S35: 0.719 | T35: 0 | U35: 0.176 | V35: 0.043 | W35: <LOD | X35: 0.014 | Y35: 0.018 | Z35: 0.006 | AA35: 1.9 | AB35: 0.076 | AC35: 0.012 | AD35: 0.013 | AE35: 0.035 | AF35: 0.002 | AG35: 0.147 | AH35: 2.467 | AJ35: 0.055 | AK35: 0.206 | AL35: 0.021 | AM35: 0.094 | AN35: 0.023 | AO35: 0.013 | AP35: 0.021 | AQ35: 0.004 | AR35: 0.023 | AS35: 7.7 | AT35: 0.013 | AU35: 0.002 | AV35: 0.011 | AW35: 0.002
A36: J041_2_100x | B36: 25.073 | C36: 0.055 | D36: 61.554 | E36: 0.008 | F36: 1931.105 | G36: 0.078 | H36: 0.336 | I36: 0.067 | J36: 4.843 | K36: 12.244 | L36: 0.004 | M36: <0.000 | N36: 28.742 | O36: 0.001 | P36: 154.443 | Q36: 246.964 | R36: 0.002 | S36: 1.317 | T36: 0 | U36: 0.039 | V36: 0.044 | W36: <LOD | X36: 0.013 | Y36: 0.022 | Z36: 0.011 | AA36: 5.684 | AB36: 0.071 | AC36: 0.01 | AD36: 0.01 | AE36: 0.01 | AF36: 0.002 | AG36: 0.18 | AH36: 6.272 | AJ36: 0.077 | AK36: 0.112 | AL36: 0.025 | AM36: 0.11 | AN36: 0.029 | AO36: 0.019 | AP36: 0.026 | AQ36: 0.005 | AR36: 0.028 | AS36: 1.8 | AT36: 0.014 | AU36: 0.002 | AV36: 0.011 | AW36: 0.002
A37: J043_2_100x | B37: 16.815 | C37: 0.027 | D37: 20.404 | E37: 0.008 | F37: 1182.27 | G37: 0.005 | H37: 0.035 | I37: 0.049 | J37: 1.542 | K37: 0.739 | L37: 0.005 | M37: <0.000 | N37: 21.285 | O37: <LOD | P37: 71.972 | Q37: 12.468 | R37: 0.001 | S37: 0.117 | T37: <0.000 | U37: 0.076 | V37: 0.021 | W37: <LOD | X37: 0.007 | Y37: 0.006 | Z37: 0.01 | AA37: 2.873 | AB37: <LOD | AC37: 0.008 | AD37: 0.008 | AE37: 0.003 | AF37: 0.001 | AG37: 0.111 | AH37: 0.468 | AJ37: 0.135 | AK37: 0.024 | AL37: 0.034 | AM37: 0.135 | AN37: 0.028 | AO37: 0.01 | AP37: 0.021 | AQ37: 0.003 | AR37: 0.017 | AS37: 10.9 | AT37: 0.008 | AU37: 0.001 | AV37: 0.006 | AW37: 0.001
A39: Blank_3_100x | B39: 0.217 | C39: 0.003 | D39: 0.029 | E39: <LOD | F39: <LOD | G39: 0.001 | H39: <LOD | I39: <LOD | J39: 0.345 | K39: 0.244 | L39: 0 | M39: <0.000 | N39: 24.922 | O39: <LOD | P39: 5.164 | Q39: 0.034 | R39: <LOD | S39: 0.012 | T39: 0 | U39: 0.01 | V39: 0.004 | W39: <LOD | X39: <LOD | Y39: 0.002 | Z39: 0.011 | AA39: 0.041 | AB39: <LOD | AC39: 0.002 | AD39: 0.002 | AE39: <LOD | AF39: 0 | AG39: <LOD | AH39: 0.396 | AJ39: <0.000 | AK39: <0.000 | AL39: 0 | AM39: 0 | AN39: <0.000 | AO39: 0 | AP39: 0 | AQ39: 0 | AR39: 0 | AS39: 21.6 | AT39: 0 | AU39: 0 | AV39: 0 | AW39: 0
A40: J001_3_100x | B40: 318.701 | C40: 4.962 | D40: 11.583 | E40: 0.037 | F40: 41.131 | G40: 0.007 | H40: 0.339 | I40: 0.557 | J40: 2.548 | K40: 1006.763 | L40: 0.063 | M40: 0.014 | N40: 21.574 | O40: <LOD | P40: 10.245 | Q40: 25.444 | R40: 0.108 | S40: 0.544 | T40: 0.016 | U40: 0.774 | V40: 0.015 | W40: 0.012 | X40: 0.204 | Y40: 0.054 | Z40: 0.019 | AA40: 0.385 | AB40: 6.71 | AC40: 0.252 | AD40: 0.257 | AE40: 1.171 | AF40: 0.018 | AG40: 1.384 | AH40: 1.816 | AJ40: 0.305 | AK40: 0.681 | AL40: 0.148 | AM40: 0.686 | AN40: 0.198 | AO40: 0.054 | AP40: 0.164 | AQ40: 0.038 | AR40: 0.225 | AS40: 1.4 | AT40: 0.136 | AU40: 0.017 | AV40: 0.112 | AW40: 0.017
A41: J002_3_100x | B41: 140.159 | C41: 6.157 | D41: 33.958 | E41: 0.024 | F41: 456.659 | G41: 0.021 | H41: 2.11 | I41: 0.412 | J41: 572.384 | K41: 3866.575 | L41: 0.072 | M41: 0.106 | N41: 17.936 | O41: 0.034 | P41: 981.73 | Q41: 1347.308 | R41: 6.635 | S41: 1.132 | T41: 0.01 | U41: 1.056 | V41: 0.02 | W41: 0.178 | X41: 0.452 | Y41: 0.306 | Z41: 0.066 | AA41: 0.387 | AB41: 4.442 | AC41: 0.129 | AD41: 0.132 | AE41: 1.036 | AF41: 0.015 | AG41: 1.235 | AH41: 3.604 | AJ41: 0.107 | AK41: 0.306 | AL41: 0.039 | AM41: 0.169 | AN41: 0.062 | AO41: 0.032 | AP41: 0.078 | AQ41: 0.025 | AR41: 0.186 | AS41: 2.8 | AT41: 0.114 | AU41: 0.017 | AV41: 0.111 | AW41: 0.016
A42: J003_3_100x | B42: 201.439 | C42: 1.471 | D42: 6.391 | E42: 0.03 | F42: 63.851 | G42: 0.003 | H42: 0.124 | I42: 0.337 | J42: 6.92 | K42: 285.512 | L42: 0.038 | M42: 0.002 | N42: 19.913 | O42: 0.003 | P42: 12.878 | Q42: 19.522 | R42: 0.088 | S42: 0.449 | T42: 0.008 | U42: 0.267 | V42: 0.012 | W42: 0.008 | X42: 0.107 | Y42: 0.016 | Z42: 0.013 | AA42: 0.214 | AB42: 3.362 | AC42: 0.167 | AD42: 0.171 | AE42: 0.306 | AF42: 0.015 | AG42: 1.197 | AH42: 1.139 | AJ42: 0.22 | AK42: 0.468 | AL42: 0.093 | AM42: 0.444 | AN42: 0.138 | AO42: 0.039 | AP42: 0.125 | AQ42: 0.032 | AR42: 0.191 | AS42: 2.6 | AT42: 0.112 | AU42: 0.015 | AV42: 0.092 | AW42: 0.014
...

Sheet Podaci
A1: izraženo u μg/L
B2: Al | C2: As | D2: Ba | E2: Be | F2: Ca | G2: Cd | H2: Co | I2: Cr | J2: Cu | K2: Fe | L2: Ga | M2: Ge | N2: K | O2: Li | P2: Mg | Q2: Mn | R2: Mo | S2: Ni | T2: Nb | U2: Pb | V2: Rb | W2: Sb | X2: Sc | Y2: Se | Z2: Sn | AA2: Sr | AB2: Ti | AC2: Th | AD2: U | AE2: V | AF2: W | AG2: Y | AH2: Zn | AI2: La | AJ2: Ce | AK2: Pr | AL2: Nd | AM2: Sm | AN2: Eu | AO2: Gd | AP2: Tb | AQ2: Dy | AR2: Ho | AS2: Er | AT2: Tm | AU2: Yb | AV2: Lu | AX2: m (g)
A3: Blank_1_100x | B3: 0.411 | C3: <LOD | D3: 0.019 | E3: <LOD | F3: <LOD | G3: <LOD | H3: <LOD | I3: <LOD | J3: 0.013 | K3: 0.363 | L3: 0 | M3: 0.008 | N3: 81.388 | O3: <LOD | P3: 0.64 | Q3: 0.011 | R3: <LOD | S3: 0.032 | T3: 0 | U3: 0.01 | V3: 0.004 | W3: <LOD | X3: <LOD | Y3: <LOD | Z3: 0.009 | AA3: 0.008 | AB3: 0.019 | AC3: 0 | AD3: <LOD | AE3: <LOD | AF3: 0.001 | AG3: <LOD | AH3: 0.131 | AI3: 0 | AJ3: 0 | AK3: 0 | AL3: 0.001 | AM3: 0 | AN3: 0 | AO3: 0 | AP3: 0 | AQ3: 0 | AR3: 0 | AS3: 0 | AT3: 0 | AU3: 0 | AV3: 0 | AX3: 1
A4: J001_1_100x | B4: 1.219 | C4: 0.101 | D4: 0.101 | E4: <LOD | F4: <LOD | G4: <LOD | H4: 0.004 | I4: <LOD | J4: 0.04 | K4: 1.359 | L4: 0 | M4: 0 | N4: 65.435 | O4: <LOD | P4: 4.908 | Q4: 1.118 | R4: 0.014 | S4: 0.046 | T4: 0 | U4: 0.007 | V4: 0.007 | W4: <LOD | X4: <LOD | Y4: 0.014 | Z4: 0.008 | AA4: 0.038 | AB4: 0.009 | AC4: 0 | AD4: 0.007 | AE4: 0.057 | AF4: 0.001 | AG4: 0.005 | AH4: 0.201 | AI4: 0 | AJ4: 0 | AK4: 0.001 | AL4: 0.004 | AM4: 0.002 | AN4: 0 | AO4: 0.001 | AP4: 0 | AQ4: 0.001 | AR4: 0 | AS4: 0 | AT4: 0 | AU4: 0 | AV4: 0 | AX4: 0.5009
A5: J002_1_100x | B5: 0.563 | C5: 0.008 | D5: 0.074 | E5: <LOD | F5: <LOD | G5: <LOD | H5: <LOD | I5: <LOD | J5: 1.224 | K5: 2.349 | L5: 0 | M5: 0 | N5: 70.416 | O5: <LOD | P5: 6.63 | Q5: 0.096 | R5: 0.136 | S5: 0.031 | T5: 0 | U5: 0.009 | V5: 0.007 | W5: <LOD | X5: <LOD | Y5: 0.005 | Z5: 0.009 | AA5: 0.026 | AB5: 0.009 | AC5: 0 | AD5: <LOD | AE5: <LOD | AF5: 0.001 | AG5: 0.001 | AH5: 1.754 | AI5: 0 | AJ5: 0 | AK5: 0 | AL5: 0 | AM5: 0 | AN5: 0 | AO5: 0 | AP5: 0 | AQ5: 0 | AR5: 0 | AS5: 0 | AT5: 0 | AU5: 0 | AV5: 0 | AX5: 0.5197
A6: J003_1_100x | B6: <LOD | C6: 0.031 | D6: 0.04 | E6: <LOD | F6: <LOD | G6: <LOD | H6: <LOD | I6: <LOD | J6: 0.035 | K6: 0.256 | L6: 0 | M6: 0 | N6: 64.535 | O6: <LOD | P6: 3.083 | Q6: 0.241 | R6: 0.004 | S6: 0.027 | T6: 0 | U6: 0.006 | V6: 0.006 | W6: <LOD | X6: <LOD | Y6: 0.005 | Z6: 0.006 | AA6: 0.019 | AB6: <LOD | AC6: 0 | AD6: 0.003 | AE6: 0.023 | AF6: 0.001 | AG6: 0.001 | AH6: 0.029 | AI6: 0 | AJ6: 0 | AK6: 0 | AL6: 0.001 | AM6: 0 | AN6: 0 | AO6: 0 | AP6: 0 | AQ6: 0 | AR6: 0 | AS6: 0 | AT6: 0 | AU6: 0 | AV6: 0 | AX6: 0.5248
A7: J007_1_100x | B7: 0.283 | C7: 0.084 | D7: 0.11 | E7: <LOD | F7: <LOD | G7: 0.001 | H7: 0.002 | I7: <LOD | J7: 0.108 | K7: 0.533 | L7: 0 | M7: 0 | N7: 63.488 | O7: <LOD | P7: 4.883 | Q7: 0.809 | R7: 0.009 | S7: 0.034 | T7: 0 | U7: 0.012 | V7: 0.007 | W7: <LOD | X7: <LOD | Y7: 0.017 | Z7: 0.005 | AA7: 0.046 | AB7: 0.019 | AC7: 0 | AD7: 0.003 | AE7: 0.041 | AF7: 0.001 | AG7: 0.002 | AH7: <LOD | AI7: 0 | AJ7: 0 | AK7: 0 | AL7: 0.001 | AM7: 0 | AN7: 0 | AO7: 0 | AP7: 0 | AQ7: 0 | AR7: 0 | AS7: 0 | AT7: 0 | AU7: 0 | AV7: 0 | AX7: 0.5017
A8: J010_1_100x | B8: <LOD | C8: 0.019 | D8: 0.04 | E8: <LOD | F8: <LOD | G8: <LOD | H8: <LOD | I8: <LOD | J8: 0.001 | K8: 0.337 | L8: 0 | M8: 0 | N8: 15.45 | O8: <LOD | P8: 1.32 | Q8: 0.475 | R8: 0.003 | S8: 0.008 | T8: 0 | U8: 0.002 | V8: 0.003 | W8: <LOD | X8: <LOD | Y8: 0.006 | Z8: 0.001 | AA8: 0.016 | AB8: <LOD | AC8: 0 | AD8: 0.001 | AE8: 0.058 | AF8: 0 | AG8: 0.006 | AH8: <LOD | AI8: 0 | AJ8: 0.003 | AK8: 0.001 | AL8: 0.004 | AM8: 0.001 | AN8: 0 | AO8: 0.001 | AP8: 0 | AQ8: 0.001 | AR8: 0 | AS8: 0 | AT8: 0 | AU8: 0 | AV8: 0 | AX8: 0.51
A9: J016a_1_100x | B9: 0.402 | C9: 0.016 | D9: 0.139 | E9: <LOD | F9: <LOD | G9: <LOD | H9: <LOD | I9: <LOD | J9: 0.115 | K9: 0.391 | L9: 0 | M9: 0 | N9: 67.701 | O9: <LOD | P9: 8.213 | Q9: 0.139 | R9: 0.013 | S9: 0.029 | T9: 0 | U9: 0.006 | V9: 0.006 | W9: <LOD | X9: <LOD | Y9: 0.007 | Z9: 0.01 | AA9: 0.083 | AB9: 0.01 | AC9: 0 | AD9: 0.001 | AE9: 0.001 | AF9: 0.001 | AG9: 0.002 | AH9: <LOD | AI9: 0 | AJ9: 0 | AK9: 0 | AL9: 0.001 | AM9: 0.001 | AN9: 0 | AO9: 0 | AP9: 0 | AQ9: 0 | AR9: 0 | AS9: 0 | AT9: 0 | AU9: 0 | AV9: 0 | AX9: 0.5047
A10: J016b_1_100x | B10: 0.657 | C10: 0.025 | D10: 0.242 | E10: <LOD | F10: <LOD | G10: <LOD | H10: <LOD | I10: <LOD | J10: 0.143 | K10: 0.559 | L10: 0 | M10: 0.002 | N10: 67.638 | O10: <LOD | P10: 9.679 | Q10: 0.153 | R10: 0.017 | S10: 0.043 | T10: 0 | U10: 0.01 | V10: 0.005 | W10: <LOD | X10: <LOD | Y10: 0.01 | Z10: 0.009 | AA10: 0.105 | AB10: 0.027 | AC10: 0 | AD10: 0.001 | AE10: 0.001 | AF10: 0.001 | AG10: 0.003 | AH10: 0.827 | AI10: 0 | AJ10: 0 | AK10: 0 | AL10: 0.002 | AM10: 0.001 | AN10: 0 | AO10: 0 | AP10: 0 | AQ10: 0 | AR10: 0 | AS10: 0 | AT10: 0 | AU10: 0 | AV10: 0 | AX10: 0.5016
A11: J016c_1_100x | B11: 0.289 | C11: 0.017 | D11: 0.206 | E11: <LOD | F11: <LOD | G11: <LOD | H11: <LOD | I11: <LOD | J11: 0.126 | K11: 1.331 | L11: 0 | M11: 0 | N11: 66.56 | O11: <LOD | P11: 8.493 | Q11: 0.126 | R11: 0.014 | S11: 0.029 | T11: 0 | U11: 0.006 | V11: 0.006 | W11: <LOD | X11: <LOD | Y11: 0.008 | Z11: 0.004 | AA11: 0.091 | AB11: 0.003 | AC11: 0 | AD11: 0.001 | AE11: <LOD | AF11: 0.001 | AG11: 0.002 | AH11: <LOD | AI11: 0 | AJ11: 0 | AK11: 0 | AL11: 0.001 | AM11: 0.001 | AN11: 0 | AO11: 0 | AP11: 0 | AQ11: 0.001 | AR11: 0 | AS11: 0 | AT11: 0 | AU11: 0 | AV11: 0 | AX11: 0.513
A12: J018_1_100x | B12: 0.253 | C12: 0.004 | D12: 0.017 | E12: <LOD | F12: <LOD | G12: <LOD | H12: <LOD | I12: <LOD | J12: 0.033 | K12: 0.24 | L12: 0 | M12: 0.001 | N12: 62.584 | O12: <LOD | P12: 0.691 | Q12: 0.019 | R12: <LOD | S12: 0.019 | T12: 0 | U12: 0.008 | V12: 0.004 | W12: <LOD | X12: <LOD | Y12: <LOD | Z12: 0.005 | AA12: 0.011 | AB12: 0.002 | AC12: 0 | AD12: <LOD | AE12: <LOD | AF12: 0 | AG12: <LOD | AH12: <LOD | AI12: 0 | AJ12: 0 | AK12: 0 | AL12: 0 | AM12: 0 | AN12: 0 | AO12: 0 | AP12: 0 | AQ12: 0 | AR12: 0 | AS12: 0 | AT12: 0 | AU12: 0 | AV12: 0 | AX12: 0.5201
A13: J019_1_100x | B13: <LOD | C13: 0.001 | D13: 0.023 | E13: <LOD | F13: <LOD | G13: <LOD | H13: <LOD | I13: <LOD | J13: 0.006 | K13: 0.287 | L13: 0 | M13: 0.001 | N13: 63.644 | O13: <LOD | P13: 0.607 | Q13: 0.143 | R13: <LOD | S13: 0.019 | T13: 0 | U13: 0.006 | V13: 0.004 | W13: <LOD | X13: <LOD | Y13: 0.001 | Z13: 0.003 | AA13: 0.009 | AB13: <LOD | AC13: 0 | AD13: <LOD | AE13: <LOD | AF13: 0 | AG13: <LOD | AH13: <LOD | AI13: 0 | AJ13: 0 | AK13: 0 | AL13: 0 | AM13: 0 | AN13: 0 | AO13: 0 | AP13: 0 | AQ13: 0 | AR13: 0 | AS13: 0 | AT13: 0 | AU13: 0 | AV13: 0 | AX13: 0.5287
A14: J024_1_100x | B14: 0.166 | C14: 0.077 | D14: 0.069 | E14: <LOD | F14: <LOD | G14: <LOD | H14: 0.002 | I14: <LOD | J14: 0.085 | K14: 0.372 | L14: 0 | M14: 0 | N14: 66.918 | O14: <LOD | P14: 3.794 | Q14: 1.486 | R14: 0.009 | S14: 0.036 | T14: 0 | U14: 0.006 | V14: 0.009 | W14: 0.001 | X14: <LOD | Y14: 0.019 | Z14: 0.005 | AA14: 0.03 | AB14: <LOD | AC14: 0 | AD14: 0.001 | AE14: 0.164 | AF14: 0.001 | AG14: 0.001 | AH14: 0.015 | AI14: 0 | AJ14: 0 | AK14: 0 | AL14: 0.001 | AM14: 0 | AN14: 0 | AO14: 0 | AP14: 0 | AQ14: 0 | AR14: 0 | AS14: 0 | AT14: 0 | AU14: 0 | AV14: 0 | AX14: 0.5213
A15: J028_1_100x | B15: 0.721 | C15: 0.021 | D15: 0.117 | E15: <LOD | F15: <LOD | G15: <LOD | H15: <LOD | I15: 0.068 | J15: 0.026 | K15: 0.399 | L15: 0 | M15: 0 | N15: 62.474 | O15: <LOD | P15: 4.156 | Q15: 0.928 | R15: 0.007 | S15: 0.024 | T15: 0 | U15: 0.006 | V15: 0.005 | W15: <LOD | X15: <LOD | Y15: 0.007 | Z15: 0.005 | AA15: 0.055 | AB15: <LOD | AC15: 0 | AD15: 0.001 | AE15: 0.031 | AF15: 0.006 | AG15: 0.001 | AH15: <LOD | AI15: 0 | AJ15: 0 | AK15: 0 | AL15: 0.001 | AM15: 0 | AN15: 0 | AO15: 0 | AP15: 0 | AQ15: 0 | AR15: 0 | AS15: 0 | AT15: 0 | AU15: 0 | AV15: 0 | AX15: 0.5119
A16: J033_1_100x | B16: 0.055 | C16: 0.077 | D16: 0.1 | E16: <LOD | F16: <LOD | G16: 0.001 | H16: 0.003 | I16: 0.043 | J16: 0.085 | K16: 0.471 | L16: 0 | M16: 0 | N16: 65.53 | O16: <LOD | P16: 3.418 | Q16: 1.723 | R16: 0.014 | S16: 0.039 | T16: 0 | U16: 0.007 | V16: 0.009 | W16: 0.001 | X16: <LOD | Y16: 0.023 | Z16: 0.004 | AA16: 0.033 | AB16: 0.01 | AC16: 0 | AD16: 0.002 | AE16: 0.236 | AF16: 0.001 | AG16: 0.001 | AH16: 0.007 | AI16: 0 | AJ16: 0 | AK16: 0 | AL16: 0.001 | AM16: 0 | AN16: 0 | AO16: 0 | AP16: 0 | AQ16: 0 | AR16: 0 | AS16: 0 | AT16: 0 | AU16: 0 | AV16: 0 | AX16: 0.5326
A17: J039_1_100x | B17: 0.843 | C17: 0.011 | D17: 0.182 | E17: <LOD | F17: <LOD | G17: <LOD | H17: 0.001 | I17: <LOD | J17: 0.302 | K17: 0.456 | L17: 0 | M17: 0 | N17: 64.51 | O17: <LOD | P17: 4.296 | Q17: 1.104 | R17: 0.005 | S17: 0.039 | T17: 0 | U17: 0.008 | V17: 0.006 | W17: <LOD | X17: <LOD | Y17: 0.015 | Z17: 0.007 | AA17: 0.049 | AB17: <LOD | AC17: 0 | AD17: 0.001 | AE17: 0.063 | AF17: 0.002 | AG17: 0.002 | AH17: 0.22 | AI17: 0 | AJ17: 0 | AK17: 0 | AL17: 0.001 | AM17: 0 | AN17: 0 | AO17: 0 | AP17: 0 | AQ17: 0 | AR17: 0 | AS17: 0 | AT17: 0 | AU17: 0 | AV17: 0 | AX17: 0.5147
A18: J041_1_100x | B18: 0.334 | C18: 0.012 | D18: 0.219 | E18: <LOD | F18: <LOD | G18: <LOD | H18: 0.002 | I18: <LOD | J18: 0.274 | K18: 0.592 | L18: 0 | M18: 0 | N18: 66.169 | O18: <LOD | P18: 8.253 | Q18: 1.999 | R18: 0.021 | S18: 0.042 | T18: 0 | U18: 0.006 | V18: 0.009 | W18: <LOD | X18: <LOD | Y18: 0.016 | Z18: 0.002 | AA18: 0.096 | AB18: <LOD | AC18: 0 | AD18: 0.002 | AE18: 0.003 | AF18: 0.002 | AG18: 0.003 | AH18: <LOD | AI18: 0 | AJ18: 0 | AK18: 0 | AL18: 0.002 | AM18: 0 | AN18: 0 | AO18: 0.001 | AP18: 0 | AQ18: 0 | AR18: 0 | AS18: 0 | AT18: 0 | AU18: 0 | AV18: 0 | AX18: 0.5234
A19: J043_1_100x | B19: 1.634 | C19: 0.008 | D19: 0.058 | E19: <LOD | F19: <LOD | G19: <LOD | H19: <LOD | I19: 0.008 | J19: 0.066 | K19: 0.361 | L19: 0 | M19: 0 | N19: 65.192 | O19: <LOD | P19: 2.366 | Q19: 0.079 | R19: 0.002 | S19: 0.038 | T19: 0 | U19: 0.017 | V19: 0.004 | W19: <LOD | X19: <LOD | Y19: 0.002 | Z19: 0.008 | AA19: 0.029 | AB19: 0.1 | AC19: 0 | AD19: 0.003 | AE19: 0.005 | AF19: 0.001 | AG19: 0.002 | AH19: 0.868 | AI19: 0 | AJ19: 0 | AK19: 0.001 | AL19: 0.002 | AM19: 0 | AN19: 0 | AO19: 0 | AP19: 0 | AQ19: 0 | AR19: 0 | AS19: 0 | AT19: 0 | AU19: 0 | AV19: 0 | AX19: 0.5373
A21: Blank_2_100x | B21: 1.539 | C21: 0.004 | D21: 0.057 | E21: <LOD | F21: <LOD | G21: <LOD | H21: <LOD | I21: 0.005 | J21: 0.253 | K21: 1.161 | L21: 0 | M21: 0 | N21: 32.203 | O21: <LOD | P21: 1.111 | Q21: 0.026 | R21: 0.001 | S21: 0.135 | T21: 0 | U21: 0.166 | V21: 0.004 | W21: <LOD | X21: 0.006 | Y21: <LOD | Z21: 0.011 | AA21: 0.011 | AB21: 0.134 | AC21: 0 | AD21: <LOD | AE21: <LOD | AF21: 0 | AG21: <LOD | AH21: 1.918 | AI21: 0 | AJ21: 0 | AK21: 0 | AL21: 0 | AM21: 0 | AN21: 0 | AO21: 0 | AP21: 0 | AQ21: 0 | AR21: 0 | AS21: 0 | AT21: 0 | AU21: 0 | AV21: 0 | AX21: 1
A22: J001_2_100x | B22: 17.837 | C22: 0.376 | D22: 37.817 | E22: 0.016 | F22: 430.831 | G22: 0.016 | H22: 0.297 | I22: 0.042 | J22: 0.605 | K22: 69.38 | L22: 0.003 | M22: 0.007 | N22: 49.783 | O22: <LOD | P22: 107.653 | Q22: 63.83 | R22: 0.005 | S22: 0.54 | T22: 0 | U22: 0.411 | V22: 0.071 | W22: <LOD | X22: 0.006 | Y22: 0.019 | Z22: 0.017 | AA22: 1.923 | AB22: 0.22 | AC22: 0.003 | AD22: 1.033 | AE22: 0.063 | AF22: 0.001 | AG22: 0.158 | AH22: 3.214 | AI22: 0.033 | AJ22: 0.097 | AK22: 0.024 | AL22: 0.128 | AM22: 0.033 | AN22: 0.02 | AO22: 0.031 | AP22: 0.006 | AQ22: 0.026 | AR22: 0.005 | AS22: 0.013 | AT22: 0.001 | AU22: 0.008 | AV22: 0.001 | AX22: 0.5009
A23: J002_2_100x | B23: 15.531 | C23: 0.036 | D23: 29.192 | E23: 0.006 | F23: 606.024 | G23: 0.023 | H23: 0.046 | I23: 0.065 | J23: 1689.476 | K23: 74.437 | L23: 0.002 | M23: 0.004 | N23: 32.677 | O23: 0.006 | P23: 139.046 | Q23: 50.248 | R23: 0.014 | S23: 0.252 | T23: 0 | U23: 0.307 | V23: 0.029 | W23: 0.002 | X23: 0.048 | Y23: 0.017 | Z23: 0.018 | AA23: 0.808 | AB23: 0.009 | AC23: 0.008 | AD23: 0.14 | AE23: <LOD | AF23: 0.001 | AG23: 0.511 | AH23: 1.916 | AI23: 0.049 | AJ23: 0.068 | AK23: 0.024 | AL23: 0.115 | AM23: 0.046 | AN23: 0.027 | AO23: 0.056 | AP23: 0.013 | AQ23: 0.083 | AR23: 0.016 | AS23: 0.04 | AT23: 0.005 | AU23: 0.029 | AV23: 0.004 | AX23: 0.5197
A24: J003_2_100x | B24: 9.777 | C24: 0.061 | D24: 27.768 | E24: 0.01 | F24: 388.946 | G24: 0.008 | H24: 0.089 | I24: 0.016 | J24: 0.632 | K24: 1.196 | L24: 0.001 | M24: 0 | N24: 35.318 | O24: <LOD | P24: 88.273 | Q24: 22.236 | R24: <LOD | S24: 0.309 | T24: 0 | U24: 0.143 | V24: 0.087 | W24: <LOD | X24: 0.008 | Y24: 0.003 | Z24: 0.008 | AA24: 1.145 | AB24: 0.002 | AC24: 0.002 | AD24: 0.596 | AE24: 0.007 | AF24: 0.001 | AG24: 0.075 | AH24: 0.429 | AI24: 0 | AJ24: 0.036 | AK24: 0.008 | AL24: 0.04 | AM24: 0.014 | AN24: 0.011 | AO24: 0.013 | AP24: 0.002 | AQ24: 0.012 | AR24: 0.002 | AS24: 0.005 | AT24: 0.001 | AU24: 0.003 | AV24: 0.001 | AX24: 0.5248
A25: J007_2_100x | B25: 8.108 | C25: 0.164 | D25: 37.302 | E25: 0.009 | F25: 489.238 | G25: 0.031 | H25: 0.212 | I25: 0.042 | J25: 1.351 | K25: 2.701 | L25: 0.001 | M25: 0 | N25: 41.703 | O25: 0.001 | P25: 112.623 | Q25: 59.326 | R25: <LOD | S25: 0.538 | T25: 0 | U25: 0.447 | V25: 0.107 | W25: <LOD | X25: 0.007 | Y25: 0.012 | Z25: 0.009 | AA25: 2.185 | AB25: 0.02 | AC25: 0.002 | AD25: 0.615 | AE25: 0.013 | AF25: 0.001 | AG25: 0.067 | AH25: 1.552 | AI25: 0 | AJ25: 0.042 | AK25: 0.01 | AL25: 0.052 | AM25: 0.014 | AN25: 0.014 | AO25: 0.014 | AP25: 0.002 | AQ25: 0.012 | AR25: 0.002 | AS25: 0.005 | AT25: 0.001 | AU25: 0.003 | AV25: 0 | AX25: 0.5017
A26: J0010_2_100x | B26: 7.935 | C26: 0.061 | D26: 12.688 | E26: 0.004 | F26: 300.463 | G26: 0.013 | H26: 0.125 | I26: 0.021 | J26: 0.456 | K26: 4.028 | L26: 0.001 | M26: 0 | N26: 38.438 | O26: <LOD | P26: 50.149 | Q26: 36.804 | R26: 0.001 | S26: 0.251 | T26: 0 | U26: 0.325 | V26: 0.044 | W26: <LOD | X26: 0.004 | Y26: 0.008 | Z26: 0.009 | AA26: 0.964 | AB26: 0.072 | AC26: 0.002 | AD26: 0.211 | AE26: 0.034 | AF26: 0 | AG26: 0.03 | AH26: 0.659 | AI26: 0 | AJ26: 0.02 | AK26: 0.004 | AL26: 0.023 | AM26: 0.006 | AN26: 0.005 | AO26: 0.006 | AP26: 0.001 | AQ26: 0.006 | AR26: 0.001 | AS26: 0.002 | AT26: 0 | AU26: 0.002 | AV26: 0 | AX26: 0.51
A27: J0016a_2_100x | B27: 23.075 | C27: 0.056 | D27: 103.167 | E27: 0.015 | F27: 2213.549 | G27: 0.046 | H27: 0.03 | I27: 0.039 | J27: 1.326 | K27: 3.298 | L27: 0.006 | M27: 0.006 | N27: 43.021 | O27: 0.023 | P27: 303.574 | Q27: 239.259 | R27: 0.001 | S27: 0.639 | T27: 0 | U27: 0.023 | V27: 0.014 | W27: <LOD | X27: 0.021 | Y27: 0.019 | Z27: 0.015 | AA27: 8.036 | AB27: 0.012 | AC27: 0.005 | AD27: 0.64 | AE27: 0.004 | AF27: 0.001 | AG27: 0.392 | AH27: 4.68 | AI27: 0.211 | AJ27: 0.218 | AK27: 0.053 | AL27: 0.247 | AM27: 0.066 | AN27: 0.047 | AO27: 0.064 | AP27: 0.011 | AQ27: 0.055 | AR27: 0.01 | AS27: 0.022 | AT27: 0.002 | AU27: 0.015 | AV27: 0.002 | AX27: 0.5047
A28: J0016b_2_100x | B28: 16.113 | C28: 0.071 | D28: 96.446 | E28: 0.011 | F28: 2167.765 | G28: 0.041 | H28: 0.036 | I28: 0.021 | J28: 1.422 | K28: 2.3 | L28: 0.005 | M28: 0.004 | N28: 42.802 | O28: 0.018 | P28: 288.968 | Q28: 162.717 | R28: <LOD | S28: 0.456 | T28: 0 | U28: 0.023 | V28: 0.017 | W28: <LOD | X28: 0.019 | Y28: 0.014 | Z28: 0.01 | AA28: 8.087 | AB28: <LOD | AC28: 0.004 | AD28: 0.513 | AE28: 0.003 | AF28: 0.001 | AG28: 0.347 | AH28: 3.161 | AI28: 0.186 | AJ28: 0.193 | AK28: 0.047 | AL28: 0.221 | AM28: 0.063 | AN28: 0.042 | AO28: 0.059 | AP28: 0.009 | AQ28: 0.049 | AR28: 0.009 | AS28: 0.021 | AT28: 0.003 | AU28: 0.015 | AV28: 0.002 | AX28: 0.5016
A29: J016c_2_100x | B29: 13.242 | C29: 0.069 | D29: 99.969 | E29: 0.009 | F29: 2192.937 | G29: 0.039 | H29: 0.029 | I29: 0.028 | J29: 1.333 | K29: 1.973 | L29: 0.002 | M29: 0 | N29: 28.903 | O29: 0.009 | P29: 254.515 | Q29: 151.997 | R29: <LOD | S29: 0.455 | T29: 0 | U29: 0.027 | V29: 0.018 | W29: <LOD | X29: 0.014 | Y29: 0.015 | Z29: 0.011 | AA29: 7.964 | AB29: <LOD | AC29: 0.005 | AD29: 0.006 | AE29: 0.003 | AF29: 0.002 | AG29: 0.358 | AH29: 3.306 | AI29: 0.193 | AJ29: 0.202 | AK29: 0.05 | AL29: 0.234 | AM29: 0.065 | AN29: 0.039 | AO29: 0.061 | AP29: 0.01 | AQ29: 0.051 | AR29: 7.2 | AS29: 0.021 | AT29: 0.002 | AU29: 0.013 | AV29: 0.002 | AX29: 0.513
A30: J018_2_100x | B30: 18.138 | C30: 0.021 | D30: 4.236 | E30: 0.004 | F30: 443.06 | G30: 0.008 | H30: 0.024 | I30: 0.047 | J30: 2.98 | K30: 23.294 | L30: 0.002 | M30: 0 | N30: 20.392 | O30: <LOD | P30: 31.063 | Q30: 8.13 | R30: 0.003 | S30: 0.117 | T30: 0 | U30: 0.168 | V30: 0.021 | W30: <LOD | X30: 0.02 | Y30: 0.002 | Z30: 0.014 | AA30: 0.463 | AB30: 0.281 | AC30: 0.005 | AD30: 0.006 | AE30: 0.019 | AF30: 0.001 | AG30: 0.074 | AH30: 0.981 | AI30: 0.017 | AJ30: 0.06 | AK30: 0.012 | AL30: 0.05 | AM30: 0.013 | AN30: 0.005 | AO30: 0.011 | AP30: 0.002 | AQ30: 0.012 | AR30: 11.5 | AS30: 0.007 | AT30: 0.001 | AU30: 0.004 | AV30: 0.001 | AX30: 0.5201
A31: J019_2_100x | B31: 4.947 | C31: 0.007 | D31: 4.305 | E31: 0.002 | F31: 52.163 | G31: 0.002 | H31: 0.009 | I31: 0.019 | J31: 0.395 | K31: 3.437 | L31: 0.002 | M31: 0 | N31: 19.381 | O31: <LOD | P31: 6.335 | Q31: 6.463 | R31: <LOD | S31: 0.03 | T31: 0 | U31: 0.179 | V31: 0.016 | W31: <LOD | X31: <LOD | Y31: 0.001 | Z31: 0.016 | AA31: 0.131 | AB31: 0.016 | AC31: 0.008 | AD31: 0.008 | AE31: 0.002 | AF31: 0 | AG31: 0.035 | AH31: 0.393 | AI31: 0 | AJ31: 0.109 | AK31: 0.007 | AL31: 0.027 | AM31: 0.006 | AN31: 0.002 | AO31: 0.006 | AP31: 0.001 | AQ31: 0.006 | AR31: 10.1 | AS31: 0.003 | AT31: 0 | AU31: 0.002 | AV31: 0 | AX31: 0.5287
A32: J024_2_100x | B32: 13.687 | C32: 0.285 | D32: 17.599 | E32: 0.005 | F32: 436.191 | G32: 0.102 | H32: 0.27 | I32: 0.068 | J32: 1.678 | K32: 3.157 | L32: 0.002 | M32: 0 | N32: 32.84 | O32: <LOD | P32: 47.973 | Q32: 97.414 | R32: <LOD | S32: 0.876 | T32: 0 | U32: 0.561 | V32: 0.059 | W32: 0.006 | X32: 0.011 | Y32: 0.018 | Z32: 0.012 | AA32: 0.821 | AB32: 0.048 | AC32: 0.007 | AD32: 0.007 | AE32: 0.053 | AF32: 0.001 | AG32: 0.11 | AH32: 2.035 | AI32: 0.028 | AJ32: 0.124 | AK32: 0.016 | AL32: 0.079 | AM32: 0.021 | AN32: 0.009 | AO32: 0.02 | AP32: 0.004 | AQ32: 0.021 | AR32: 9 | AS32: 0.01 | AT32: 0.001 | AU32: 0.007 | AV32: 0.001 | AX32: 0.5213
A33: J028_2_100x | B33: 11.468 | C33: 0.075 | D33: 26.366 | E33: 0.003 | F33: 359.588 | G33: 0.014 | H33: 0.094 | I33: 0.045 | J33: 0.607 | K33: 1.944 | L33: 0.002 | M33: 0 | N33: 23.037 | O33: <LOD | P33: 54.534 | Q33: 62.026 | R33: <LOD | S33: 0.225 | T33: 0 | U33: 0.299 | V33: 0.025 | W33: <LOD | X33: 0.002 | Y33: 0.008 | Z33: 0.01 | AA33: 1.639 | AB33: 0.015 | AC33: 0.009 | AD33: 0.008 | AE33: 0.01 | AF33: 0.001 | AG33: 0.09 | AH33: 1.14 | AI33: 0.016 | AJ33: 0.128 | AK33: 0.012 | AL33: 0.056 | AM33: 0.015 | AN33: 0.009 | AO33: 0.015 | AP33: 0.003 | AQ33: 0.017 | AR33: 16.7 | AS33: 0.008 | AT33: 0.001 | AU33: 0.006 | AV33: 0.001 | AX33: 0.5119
A34: J033_2_100x | B34: 11.747 | C34: 0.207 | D34: 17.285 | E34: 0.003 | F34: 468.932 | G34: 0.115 | H34: 0.269 | I34: 0.069 | J34: 2.719 | K34: 3.84 | L34: 0.002 | M34: 0 | N34: 31.925 | O34: <LOD | P34: 41.865 | Q34: 104.569 | R34: 0.001 | S34: 0.959 | T34: 0 | U34: 0.489 | V34: 0.052 | W34: 0.006 | X34: 0.007 | Y34: 0.022 | Z34: 0.009 | AA34: 0.938 | AB34: 0.038 | AC34: 0.006 | AD34: 0.006 | AE34: 0.061 | AF34: 0.001 | AG34: 0.085 | AH34: 2.022 | AI34: 0.017 | AJ34: 0.094 | AK34: 0.012 | AL34: 0.06 | AM34: 0.02 | AN34: 0.008 | AO34: 0.017 | AP34: 0.003 | AQ34: 0.016 | AR34: 4.3 | AS34: 0.008 | AT34: 0.001 | AU34: 0.005 | AV34: 0.001 | AX34: 0.5326
A35: J039_2_100x | B35: 17.379 | C35: 0.059 | D35: 27.974 | E35: 0.004 | F35: 843.267 | G35: 0.056 | H35: 0.361 | I35: 0.057 | J35: 21.57 | K35: 3.823 | L35: 0.003 | M35: 0 | N35: 23.755 | O35: <LOD | P35: 61.998 | Q35: 106.049 | R35: <LOD | S35: 0.719 | T35: 0 | U35: 0.176 | V35: 0.043 | W35: <LOD | X35: 0.014 | Y35: 0.018 | Z35: 0.006 | AA35: 1.9 | AB35: 0.076 | AC35: 0.012 | AD35: 0.013 | AE35: 0.035 | AF35: 0.002 | AG35: 0.147 | AH35: 2.467 | AI35: 0.055 | AJ35: 0.206 | AK35: 0.021 | AL35: 0.094 | AM35: 0.023 | AN35: 0.013 | AO35: 0.021 | AP35: 0.004 | AQ35: 0.023 | AR35: 7.7 | AS35: 0.013 | AT35: 0.002 | AU35: 0.011 | AV35: 0.002 | AX35: 0.5147
A36: J041_2_100x | B36: 25.073 | C36: 0.055 | D36: 61.554 | E36: 0.008 | F36: 1931.105 | G36: 0.078 | H36: 0.336 | I36: 0.067 | J36: 4.843 | K36: 12.244 | L36: 0.004 | M36: 0 | N36: 28.742 | O36: 0.001 | P36: 154.443 | Q36: 246.964 | R36: 0.002 | S36: 1.317 | T36: 0 | U36: 0.039 | V36: 0.044 | W36: <LOD | X36: 0.013 | Y36: 0.022 | Z36: 0.011 | AA36: 5.684 | AB36: 0.071 | AC36: 0.01 | AD36: 0.01 | AE36: 0.01 | AF36: 0.002 | AG36: 0.18 | AH36: 6.272 | AI36: 0.077 | AJ36: 0.112 | AK36: 0.025 | AL36: 0.11 | AM36: 0.029 | AN36: 0.019 | AO36: 0.026 | AP36: 0.005 | AQ36: 0.028 | AR36: 1.8 | AS36: 0.014 | AT36: 0.002 | AU36: 0.011 | AV36: 0.002 | AX36: 0.5234
A37: J043_2_100x | B37: 16.815 | C37: 0.027 | D37: 20.404 | E37: 0.008 | F37: 1182.27 | G37: 0.005 | H37: 0.035 | I37: 0.049 | J37: 1.542 | K37: 0.739 | L37: 0.005 | M37: 0 | N37: 21.285 | O37: <LOD | P37: 71.972 | Q37: 12.468 | R37: 0.001 | S37: 0.117 | T37: 0 | U37: 0.076 | V37: 0.021 | W37: <LOD | X37: 0.007 | Y37: 0.006 | Z37: 0.01 | AA37: 2.873 | AB37: <LOD | AC37: 0.008 | AD37: 0.008 | AE37: 0.003 | AF37: 0.001 | AG37: 0.111 | AH37: 0.468 | AI37: 0.135 | AJ37: 0.024 | AK37: 0.034 | AL37: 0.135 | AM37: 0.028 | AN37: 0.01 | AO37: 0.021 | AP37: 0.003 | AQ37: 0.017 | AR37: 10.9 | AS37: 0.008 | AT37: 0.001 | AU37: 0.006 | AV37: 0.001 | AX37: 0.5373
A39: Blank_3_100x | B39: 0.217 | C39: 0.003 | D39: 0.029 | E39: <LOD | F39: <LOD | G39: 0.001 | H39: <LOD | I39: <LOD | J39: 0.345 | K39: 0.244 | L39: 0 | M39: 0 | N39: 24.922 | O39: <LOD | P39: 5.164 | Q39: 0.034 | R39: <LOD | S39: 0.012 | T39: 0 | U39: 0.01 | V39: 0.004 | W39: <LOD | X39: <LOD | Y39: 0.002 | Z39: 0.011 | AA39: 0.041 | AB39: <LOD | AC39: 0.002 | AD39: 0.002 | AE39: <LOD | AF39: 0 | AG39: <LOD | AH39: 0.396 | AI39: 0 | AJ39: 0 | AK39: 0 | AL39: 0 | AM39: 0 | AN39: 0 | AO39: 0 | AP39: 0 | AQ39: 0 | AR39: 21.6 | AS39: 0 | AT39: 0 | AU39: 0 | AV39: 0 | AX39: 1
A40: J001_3_100x | B40: 318.701 | C40: 4.962 | D40: 11.583 | E40: 0.037 | F40: 41.131 | G40: 0.007 | H40: 0.339 | I40: 0.557 | J40: 2.548 | K40: 1006.763 | L40: 0.063 | M40: 0.014 | N40: 21.574 | O40: <LOD | P40: 10.245 | Q40: 25.444 | R40: 0.108 | S40: 0.544 | T40: 0.016 | U40: 0.774 | V40: 0.015 | W40: 0.012 | X40: 0.204 | Y40: 0.054 | Z40: 0.019 | AA40: 0.385 | AB40: 6.71 | AC40: 0.252 | AD40: 0.257 | AE40: 1.171 | AF40: 0.018 | AG40: 1.384 | AH40: 1.816 | AI40: 0.305 | AJ40: 0.681 | AK40: 0.148 | AL40: 0.686 | AM40: 0.198 | AN40: 0.054 | AO40: 0.164 | AP40: 0.038 | AQ40: 0.225 | AR40: 1.4 | AS40: 0.136 | AT40: 0.017 | AU40: 0.112 | AV40: 0.017 | AX40: 0.5009
A41: J002_3_100x | B41: 140.159 | C41: 6.157 | D41: 33.958 | E41: 0.024 | F41: 456.659 | G41: 0.021 | H41: 2.11 | I41: 0.412 | J41: 572.384 | K41: 3866.575 | L41: 0.072 | M41: 0.106 | N41: 17.936 | O41: 0.034 | P41: 981.73 | Q41: 1347.308 | R41: 6.635 | S41: 1.132 | T41: 0.01 | U41: 1.056 | V41: 0.02 | W41: 0.178 | X41: 0.452 | Y41: 0.306 | Z41: 0.066 | AA41: 0.387 | AB41: 4.442 | AC41: 0.129 | AD41: 0.132 | AE41: 1.036 | AF41: 0.015 | AG41: 1.235 | AH41: 3.604 | AI41: 0.107 | AJ41: 0.306 | AK41: 0.039 | AL41: 0.169 | AM41: 0.062 | AN41: 0.032 | AO41: 0.078 | AP41: 0.025 | AQ41: 0.186 | AR41: 2.8 | AS41: 0.114 | AT41: 0.017 | AU41: 0.111 | AV41: 0.016 | AX41: 0.5197
A42: J003_3_100x | B42: 201.439 | C42: 1.471 | D42: 6.391 | E42: 0.03 | F42: 63.851 | G42: 0.003 | H42: 0.124 | I42: 0.337 | J42: 6.92 | K42: 285.512 | L42: 0.038 | M42: 0.002 | N42: 19.913 | O42: 0.003 | P42: 12.878 | Q42: 19.522 | R42: 0.088 | S42: 0.449 | T42: 0.008 | U42: 0.267 | V42: 0.012 | W42: 0.008 | X42: 0.107 | Y42: 0.016 | Z42: 0.013 | AA42: 0.214 | AB42: 3.362 | AC42: 0.167 | AD42: 0.171 | AE42: 0.306 | AF42: 0.015 | AG42: 1.197 | AH42: 1.139 | AI42: 0.22 | AJ42: 0.468 | AK42: 0.093 | AL42: 0.444 | AM42: 0.138 | AN42: 0.039 | AO42: 0.125 | AP42: 0.032 | AQ42: 0.191 | AR42: 2.6 | AS42: 0.112 | AT42: 0.015 | AU42: 0.092 | AV42: 0.014 | AX42: 0.5248
...

Sheet Umanjeno za Blankove
A1: izraženo u mg/kg i umanjeno za blankove
B2: Al | C2: As | D2: Ba | E2: Be | F2: Ca | G2: Cd | H2: Co | I2: Cr | J2: Cu | K2: Fe | L2: Ga | M2: Ge | N2: K | O2: Li | P2: Mg | Q2: Mn | R2: Mo | S2: Ni | T2: Nb | U2: Pb | V2: Rb | W2: Sb | X2: Sc | Y2: Se | Z2: Sn | AA2: Sr | AB2: Ti | AC2: Th | AD2: U | AE2: V | AF2: W | AG2: Y | AH2: Zn | AI2: La | AJ2: Ce | AK2: Pr | AL2: Nd | AM2: Sm | AN2: Eu | AO2: Gd | AP2: Tb | AQ2: Dy | AR2: Ho | AS2: Er | AT2: Tm | AU2: Yb | AV2: Lu
A3: J001_1_100x | B3: =IF(OR(Podaci!B$3="<LOD", Podaci!B4="<LOD"), Podaci!B4,(Podaci!B4-Podaci!B$3)) -> 0.808 | C3: =IF(OR(Podaci!C$3="<LOD", Podaci!C4="<LOD"), Podaci!C4,(Podaci!C4-Podaci!C$3)) -> 0.101 | D3: =IF(OR(Podaci!D$3="<LOD", Podaci!D4="<LOD"), Podaci!D4,(Podaci!D4-Podaci!D$3)) -> 0.082 | E3: =IF(OR(Podaci!E$3="<LOD", Podaci!E4="<LOD"), Podaci!E4,(Podaci!E4-Podaci!E$3)) -> <LOD | F3: =IF(OR(Podaci!F$3="<LOD", Podaci!F4="<LOD"), Podaci!F4,(Podaci!F4-Podaci!F$3)) -> <LOD | G3: =IF(OR(Podaci!G$3="<LOD", Podaci!G4="<LOD"), Podaci!G4,(Podaci!G4-Podaci!G$3)) -> <LOD | H3: =IF(OR(Podaci!H$3="<LOD", Podaci!H4="<LOD"), Podaci!H4,(Podaci!H4-Podaci!H$3)) -> 0.004 | I3: =IF(OR(Podaci!I$3="<LOD", Podaci!I4="<LOD"), Podaci!I4,(Podaci!I4-Podaci!I$3)) -> <LOD | ... AV3: =IF(OR(Podaci!AV$3="<LOD", Podaci!AV4="<LOD"), Podaci!AV4,(Podaci!AV4-Podaci!AV$3)) -> 0
A4: J002_1_100x | B4: =IF(OR(Podaci!B$3="<LOD", Podaci!B5="<LOD"), Podaci!B5,(Podaci!B5-Podaci!B$3)) -> 0.152 | C4: =IF(OR(Podaci!C$3="<LOD", Podaci!C5="<LOD"), Podaci!C5,(Podaci!C5-Podaci!C$3)) -> 0.008 | D4: =IF(OR(Podaci!D$3="<LOD", Podaci!D5="<LOD"), Podaci!D5,(Podaci!D5-Podaci!D$3)) -> 0.055 | E4: =IF(OR(Podaci!E$3="<LOD", Podaci!E5="<LOD"), Podaci!E5,(Podaci!E5-Podaci!E$3)) -> <LOD | F4: =IF(OR(Podaci!F$3="<LOD", Podaci!F5="<LOD"), Podaci!F5,(Podaci!F5-Podaci!F$3)) -> <LOD | G4: =IF(OR(Podaci!G$3="<LOD", Podaci!G5="<LOD"), Podaci!G5,(Podaci!G5-Podaci!G$3)) -> <LOD | H4: =IF(OR(Podaci!H$3="<LOD", Podaci!H5="<LOD"), Podaci!H5,(Podaci!H5-Podaci!H$3)) -> <LOD | I4: =IF(OR(Podaci!I$3="<LOD", Podaci!I5="<LOD"), Podaci!I5,(Podaci!I5-Podaci!I$3)) -> <LOD | ... AV4: =IF(OR(Podaci!AV$3="<LOD", Podaci!AV5="<LOD"), Podaci!AV5,(Podaci!AV5-Podaci!AV$3)) -> 0
A5: J003_1_100x | B5: =IF(OR(Podaci!B$3="<LOD", Podaci!B6="<LOD"), Podaci!B6,(Podaci!B6-Podaci!B$3)) -> <LOD | C5: =IF(OR(Podaci!C$3="<LOD", Podaci!C6="<LOD"), Podaci!C6,(Podaci!C6-Podaci!C$3)) -> 0.031 | D5: =IF(OR(Podaci!D$3="<LOD", Podaci!D6="<LOD"), Podaci!D6,(Podaci!D6-Podaci!D$3)) -> 0.021 | E5: =IF(OR(Podaci!E$3="<LOD", Podaci!E6="<LOD"), Podaci!E6,(Podaci!E6-Podaci!E$3)) -> <LOD | F5: =IF(OR(Podaci!F$3="<LOD", Podaci!F6="<LOD"), Podaci!F6,(Podaci!F6-Podaci!F$3)) -> <LOD | G5: =IF(OR(Podaci!G$3="<LOD", Podaci!G6="<LOD"), Podaci!G6,(Podaci!G6-Podaci!G$3)) -> <LOD | H5: =IF(OR(Podaci!H$3="<LOD", Podaci!H6="<LOD"), Podaci!H6,(Podaci!H6-Podaci!H$3)) -> <LOD | I5: =IF(OR(Podaci!I$3="<LOD", Podaci!I6="<LOD"), Podaci!I6,(Podaci!I6-Podaci!I$3)) -> <LOD | ... AV5: =IF(OR(Podaci!AV$3="<LOD", Podaci!AV6="<LOD"), Podaci!AV6,(Podaci!AV6-Podaci!AV$3)) -> 0
A6: J007_1_100x | B6: =IF(OR(Podaci!B$3="<LOD", Podaci!B7="<LOD"), Podaci!B7,(Podaci!B7-Podaci!B$3)) -> -0.128 | C6: =IF(OR(Podaci!C$3="<LOD", Podaci!C7="<LOD"), Podaci!C7,(Podaci!C7-Podaci!C$3)) -> 0.084 | D6: =IF(OR(Podaci!D$3="<LOD", Podaci!D7="<LOD"), Podaci!D7,(Podaci!D7-Podaci!D$3)) -> 0.091 | E6: =IF(OR(Podaci!E$3="<LOD", Podaci!E7="<LOD"), Podaci!E7,(Podaci!E7-Podaci!E$3)) -> <LOD | F6: =IF(OR(Podaci!F$3="<LOD", Podaci!F7="<LOD"), Podaci!F7,(Podaci!F7-Podaci!F$3)) -> <LOD | G6: =IF(OR(Podaci!G$3="<LOD", Podaci!G7="<LOD"), Podaci!G7,(Podaci!G7-Podaci!G$3)) -> 0.001 | H6: =IF(OR(Podaci!H$3="<LOD", Podaci!H7="<LOD"), Podaci!H7,(Podaci!H7-Podaci!H$3)) -> 0.002 | I6: =IF(OR(Podaci!I$3="<LOD", Podaci!I7="<LOD"), Podaci!I7,(Podaci!I7-Podaci!I$3)) -> <LOD | ... AV6: =IF(OR(Podaci!AV$3="<LOD", Podaci!AV7="<LOD"), Podaci!AV7,(Podaci!AV7-Podaci!AV$3)) -> 0
A7: J010_1_100x | B7: =IF(OR(Podaci!B$3="<LOD", Podaci!B8="<LOD"), Podaci!B8,(Podaci!B8-Podaci!B$3)) -> <LOD | C7: =IF(OR(Podaci!C$3="<LOD", Podaci!C8="<LOD"), Podaci!C8,(Podaci!C8-Podaci!C$3)) -> 0.019 | D7: =IF(OR(Podaci!D$3="<LOD", Podaci!D8="<LOD"), Podaci!D8,(Podaci!D8-Podaci!D$3)) -> 0.021 | E7: =IF(OR(Podaci!E$3="<LOD", Podaci!E8="<LOD"), Podaci!E8,(Podaci!E8-Podaci!E$3)) -> <LOD | F7: =IF(OR(Podaci!F$3="<LOD", Podaci!F8="<LOD"), Podaci!F8,(Podaci!F8-Podaci!F$3)) -> <LOD | G7: =IF(OR(Podaci!G$3="<LOD", Podaci!G8="<LOD"), Podaci!G8,(Podaci!G8-Podaci!G$3)) -> <LOD | H7: =IF(OR(Podaci!H$3="<LOD", Podaci!H8="<LOD"), Podaci!H8,(Podaci!H8-Podaci!H$3)) -> <LOD | I7: =IF(OR(Podaci!I$3="<LOD", Podaci!I8="<LOD"), Podaci!I8,(Podaci!I8-Podaci!I$3)) -> <LOD | ... AV7: =IF(OR(Podaci!AV$3="<LOD", Podaci!AV8="<LOD"), Podaci!AV8,(Podaci!AV8-Podaci!AV$3)) -> 0
A8: J016a_1_100x | B8: =IF(OR(Podaci!B$3="<LOD", Podaci!B9="<LOD"), Podaci!B9,(Podaci!B9-Podaci!B$3)) -> -0.009 | C8: =IF(OR(Podaci!C$3="<LOD", Podaci!C9="<LOD"), Podaci!C9,(Podaci!C9-Podaci!C$3)) -> 0.016 | D8: =IF(OR(Podaci!D$3="<LOD", Podaci!D9="<LOD"), Podaci!D9,(Podaci!D9-Podaci!D$3)) -> 0.12 | E8: =IF(OR(Podaci!E$3="<LOD", Podaci!E9="<LOD"), Podaci!E9,(Podaci!E9-Podaci!E$3)) -> <LOD | F8: =IF(OR(Podaci!F$3="<LOD", Podaci!F9="<LOD"), Podaci!F9,(Podaci!F9-Podaci!F$3)) -> <LOD | G8: =IF(OR(Podaci!G$3="<LOD", Podaci!G9="<LOD"), Podaci!G9,(Podaci!G9-Podaci!G$3)) -> <LOD | H8: =IF(OR(Podaci!H$3="<LOD", Podaci!H9="<LOD"), Podaci!H9,(Podaci!H9-Podaci!H$3)) -> <LOD | I8: =IF(OR(Podaci!I$3="<LOD", Podaci!I9="<LOD"), Podaci!I9,(Podaci!I9-Podaci!I$3)) -> <LOD | ... AV8: =IF(OR(Podaci!AV$3="<LOD", Podaci!AV9="<LOD"), Podaci!AV9,(Podaci!AV9-Podaci!AV$3)) -> 0
A9: J016b_1_100x | B9: =IF(OR(Podaci!B$3="<LOD", Podaci!B10="<LOD"), Podaci!B10,(Podaci!B10-Podaci!B$3)) -> 0.246 | C9: =IF(OR(Podaci!C$3="<LOD", Podaci!C10="<LOD"), Podaci!C10,(Podaci!C10-Podaci!C$3)) -> 0.025 | D9: =IF(OR(Podaci!D$3="<LOD", Podaci!D10="<LOD"), Podaci!D10,(Podaci!D10-Podaci!D$3)) -> 0.223 | E9: =IF(OR(Podaci!E$3="<LOD", Podaci!E10="<LOD"), Podaci!E10,(Podaci!E10-Podaci!E$3)) -> <LOD | F9: =IF(OR(Podaci!F$3="<LOD", Podaci!F10="<LOD"), Podaci!F10,(Podaci!F10-Podaci!F$3)) -> <LOD | G9: =IF(OR(Podaci!G$3="<LOD", Podaci!G10="<LOD"), Podaci!G10,(Podaci!G10-Podaci!G$3)) -> <LOD | H9: =IF(OR(Podaci!H$3="<LOD", Podaci!H10="<LOD"), Podaci!H10,(Podaci!H10-Podaci!H$3)) -> <LOD | I9: =IF(OR(Podaci!I$3="<LOD", Podaci!I10="<LOD"), Podaci!I10,(Podaci!I10-Podaci!I$3)) -> <LOD | ... AV9: =IF(OR(Podaci!AV$3="<LOD", Podaci!AV10="<LOD"), Podaci!AV10,(Podaci!AV10-Podaci!AV$3)) -> 0
A10: J016c_1_100x | B10: =IF(OR(Podaci!B$3="<LOD", Podaci!B11="<LOD"), Podaci!B11,(Podaci!B11-Podaci!B$3)) -> -0.122 | C10: =IF(OR(Podaci!C$3="<LOD", Podaci!C11="<LOD"), Podaci!C11,(Podaci!C11-Podaci!C$3)) -> 0.017 | D10: =IF(OR(Podaci!D$3="<LOD", Podaci!D11="<LOD"), Podaci!D11,(Podaci!D11-Podaci!D$3)) -> 0.187 | E10: =IF(OR(Podaci!E$3="<LOD", Podaci!E11="<LOD"), Podaci!E11,(Podaci!E11-Podaci!E$3)) -> <LOD | F10: =IF(OR(Podaci!F$3="<LOD", Podaci!F11="<LOD"), Podaci!F11,(Podaci!F11-Podaci!F$3)) -> <LOD | G10: =IF(OR(Podaci!G$3="<LOD", Podaci!G11="<LOD"), Podaci!G11,(Podaci!G11-Podaci!G$3)) -> <LOD | H10: =IF(OR(Podaci!H$3="<LOD", Podaci!H11="<LOD"), Podaci!H11,(Podaci!H11-Podaci!H$3)) -> <LOD | I10: =IF(OR(Podaci!I$3="<LOD", Podaci!I11="<LOD"), Podaci!I11,(Podaci!I11-Podaci!I$3)) -> <LOD | ... AV10: =IF(OR(Podaci!AV$3="<LOD", Podaci!AV11="<LOD"), Podaci!AV11,(Podaci!AV11-Podaci!AV$3)) -> 0
A11: J018_1_100x | B11: =IF(OR(Podaci!B$3="<LOD", Podaci!B12="<LOD"), Podaci!B12,(Podaci!B12-Podaci!B$3)) -> -0.158 | C11: =IF(OR(Podaci!C$3="<LOD", Podaci!C12="<LOD"), Podaci!C12,(Podaci!C12-Podaci!C$3)) -> 0.004 | D11: =IF(OR(Podaci!D$3="<LOD", Podaci!D12="<LOD"), Podaci!D12,(Podaci!D12-Podaci!D$3)) -> -0.002 | E11: =IF(OR(Podaci!E$3="<LOD", Podaci!E12="<LOD"), Podaci!E12,(Podaci!E12-Podaci!E$3)) -> <LOD | F11: =IF(OR(Podaci!F$3="<LOD", Podaci!F12="<LOD"), Podaci!F12,(Podaci!F12-Podaci!F$3)) -> <LOD | G11: =IF(OR(Podaci!G$3="<LOD", Podaci!G12="<LOD"), Podaci!G12,(Podaci!G12-Podaci!G$3)) -> <LOD | H11: =IF(OR(Podaci!H$3="<LOD", Podaci!H12="<LOD"), Podaci!H12,(Podaci!H12-Podaci!H$3)) -> <LOD | I11: =IF(OR(Podaci!I$3="<LOD", Podaci!I12="<LOD"), Podaci!I12,(Podaci!I12-Podaci!I$3)) -> <LOD | ... AV11: =IF(OR(Podaci!AV$3="<LOD", Podaci!AV12="<LOD"), Podaci!AV12,(Podaci!AV12-Podaci!AV$3)) -> 0
A12: J019_1_100x | B12: =IF(OR(Podaci!B$3="<LOD", Podaci!B13="<LOD"), Podaci!B13,(Podaci!B13-Podaci!B$3)) -> <LOD | C12: =IF(OR(Podaci!C$3="<LOD", Podaci!C13="<LOD"), Podaci!C13,(Podaci!C13-Podaci!C$3)) -> 0.001 | D12: =IF(OR(Podaci!D$3="<LOD", Podaci!D13="<LOD"), Podaci!D13,(Podaci!D13-Podaci!D$3)) -> 0.004 | E12: =IF(OR(Podaci!E$3="<LOD", Podaci!E13="<LOD"), Podaci!E13,(Podaci!E13-Podaci!E$3)) -> <LOD | F12: =IF(OR(Podaci!F$3="<LOD", Podaci!F13="<LOD"), Podaci!F13,(Podaci!F13-Podaci!F$3)) -> <LOD | G12: =IF(OR(Podaci!G$3="<LOD", Podaci!G13="<LOD"), Podaci!G13,(Podaci!G13-Podaci!G$3)) -> <LOD | H12: =IF(OR(Podaci!H$3="<LOD", Podaci!H13="<LOD"), Podaci!H13,(Podaci!H13-Podaci!H$3)) -> <LOD | I12: =IF(OR(Podaci!I$3="<LOD", Podaci!I13="<LOD"), Podaci!I13,(Podaci!I13-Podaci!I$3)) -> <LOD | ... AV12: =IF(OR(Podaci!AV$3="<LOD", Podaci!AV13="<LOD"), Podaci!AV13,(Podaci!AV13-Podaci!AV$3)) -> 0
A13: J024_1_100x | B13: =IF(OR(Podaci!B$3="<LOD", Podaci!B14="<LOD"), Podaci!B14,(Podaci!B14-Podaci!B$3)) -> -0.245 | C13: =IF(OR(Podaci!C$3="<LOD", Podaci!C14="<LOD"), Podaci!C14,(Podaci!C14-Podaci!C$3)) -> 0.077 | D13: =IF(OR(Podaci!D$3="<LOD", Podaci!D14="<LOD"), Podaci!D14,(Podaci!D14-Podaci!D$3)) -> 0.05 | E13: =IF(OR(Podaci!E$3="<LOD", Podaci!E14="<LOD"), Podaci!E14,(Podaci!E14-Podaci!E$3)) -> <LOD | F13: =IF(OR(Podaci!F$3="<LOD", Podaci!F14="<LOD"), Podaci!F14,(Podaci!F14-Podaci!F$3)) -> <LOD | G13: =IF(OR(Podaci!G$3="<LOD", Podaci!G14="<LOD"), Podaci!G14,(Podaci!G14-Podaci!G$3)) -> <LOD | H13: =IF(OR(Podaci!H$3="<LOD", Podaci!H14="<LOD"), Podaci!H14,(Podaci!H14-Podaci!H$3)) -> 0.002 | I13: =IF(OR(Podaci!I$3="<LOD", Podaci!I14="<LOD"), Podaci!I14,(Podaci!I14-Podaci!I$3)) -> <LOD | ... AV13: =IF(OR(Podaci!AV$3="<LOD", Podaci!AV14="<LOD"), Podaci!AV14,(Podaci!AV14-Podaci!AV$3)) -> 0
A14: J028_1_100x | B14: =IF(OR(Podaci!B$3="<LOD", Podaci!B15="<LOD"), Podaci!B15,(Podaci!B15-Podaci!B$3)) -> 0.31 | C14: =IF(OR(Podaci!C$3="<LOD", Podaci!C15="<LOD"), Podaci!C15,(Podaci!C15-Podaci!C$3)) -> 0.021 | D14: =IF(OR(Podaci!D$3="<LOD", Podaci!D15="<LOD"), Podaci!D15,(Podaci!D15-Podaci!D$3)) -> 0.098 | E14: =IF(OR(Podaci!E$3="<LOD", Podaci!E15="<LOD"), Podaci!E15,(Podaci!E15-Podaci!E$3)) -> <LOD | F14: =IF(OR(Podaci!F$3="<LOD", Podaci!F15="<LOD"), Podaci!F15,(Podaci!F15-Podaci!F$3)) -> <LOD | G14: =IF(OR(Podaci!G$3="<LOD", Podaci!G15="<LOD"), Podaci!G15,(Podaci!G15-Podaci!G$3)) -> <LOD | H14: =IF(OR(Podaci!H$3="<LOD", Podaci!H15="<LOD"), Podaci!H15,(Podaci!H15-Podaci!H$3)) -> <LOD | I14: =IF(OR(Podaci!I$3="<LOD", Podaci!I15="<LOD"), Podaci!I15,(Podaci!I15-Podaci!I$3)) -> 0.068 | ... AV14: =IF(OR(Podaci!AV$3="<LOD", Podaci!AV15="<LOD"), Podaci!AV15,(Podaci!AV15-Podaci!AV$3)) -> 0
... A18: J043_1_100x | B18: =IF(OR(Podaci!B$3="<LOD", Podaci!B19="<LOD"), Podaci!B19,(Podaci!B19-Podaci!B$3)) -> 1.223 | C18: =IF(OR(Podaci!C$3="<LOD", Podaci!C19="<LOD"), Podaci!C19,(Podaci!C19-Podaci!C$3)) -> 0.008 | D18: =IF(OR(Podaci!D$3="<LOD", Podaci!D19="<LOD"), Podaci!D19,(Podaci!D19-Podaci!D$3)) -> 0.039 | E18: =IF(OR(Podaci!E$3="<LOD", Podaci!E19="<LOD"), Podaci!E19,(Podaci!E19-Podaci!E$3)) -> <LOD | F18: =IF(OR(Podaci!F$3="<LOD", Podaci!F19="<LOD"), Podaci!F19,(Podaci!F19-Podaci!F$3)) -> <LOD | G18: =IF(OR(Podaci!G$3="<LOD", Podaci!G19="<LOD"), Podaci!G19,(Podaci!G19-Podaci!G$3)) -> <LOD | H18: =IF(OR(Podaci!H$3="<LOD", Podaci!H19="<LOD"), Podaci!H19,(Podaci!H19-Podaci!H$3)) -> <LOD | I18: =IF(OR(Podaci!I$3="<LOD", Podaci!I19="<LOD"), Podaci!I19,(Podaci!I19-Podaci!I$3)) -> 0.008 | ... AV18: =IF(OR(Podaci!AV$3="<LOD", Podaci!AV19="<LOD"), Podaci!AV19,(Podaci!AV19-Podaci!AV$3)) -> 0
